[2025-02-22T23:43:38.451-0500] {processor.py:186} INFO - Started process (PID=26668) to work on /home/rafaelrb/anaconda3/lib/python3.9/site-packages/airflow/example_dags/example_dataset_alias.py
[2025-02-22T23:43:38.453-0500] {processor.py:914} INFO - Processing file /home/rafaelrb/anaconda3/lib/python3.9/site-packages/airflow/example_dags/example_dataset_alias.py for tasks to queue
[2025-02-22T23:43:38.456-0500] {logging_mixin.py:190} INFO - [2025-02-22T23:43:38.456-0500] {dagbag.py:588} INFO - Filling up the DagBag from /home/rafaelrb/anaconda3/lib/python3.9/site-packages/airflow/example_dags/example_dataset_alias.py
[2025-02-22T23:43:38.471-0500] {logging_mixin.py:190} INFO - [2025-02-22T23:43:38.466-0500] {dagbag.py:387} ERROR - Failed to import: /home/rafaelrb/anaconda3/lib/python3.9/site-packages/airflow/example_dags/example_dataset_alias.py
Traceback (most recent call last):
  File "/home/rafaelrb/anaconda3/lib/python3.9/site-packages/airflow/models/dagbag.py", line 383, in parse
    loader.exec_module(new_module)
  File "<frozen importlib._bootstrap_external>", line 850, in exec_module
  File "<frozen importlib._bootstrap>", line 228, in _call_with_frames_removed
  File "/home/rafaelrb/anaconda3/lib/python3.9/site-packages/airflow/example_dags/example_dataset_alias.py", line 53, in <module>
    def produce_dataset_events():
  File "/home/rafaelrb/anaconda3/lib/python3.9/site-packages/airflow/decorators/base.py", line 691, in decorator_factory
    return _TaskDecorator(
TypeError: _TaskDecorator() takes no arguments
[2025-02-22T23:43:38.472-0500] {processor.py:927} WARNING - No viable dags retrieved from /home/rafaelrb/anaconda3/lib/python3.9/site-packages/airflow/example_dags/example_dataset_alias.py
[2025-02-22T23:43:38.514-0500] {processor.py:208} INFO - Processing /home/rafaelrb/anaconda3/lib/python3.9/site-packages/airflow/example_dags/example_dataset_alias.py took 0.073 seconds
[2025-02-22T23:44:47.602-0500] {processor.py:186} INFO - Started process (PID=27168) to work on /home/rafaelrb/anaconda3/lib/python3.9/site-packages/airflow/example_dags/example_dataset_alias.py
[2025-02-22T23:44:47.607-0500] {processor.py:914} INFO - Processing file /home/rafaelrb/anaconda3/lib/python3.9/site-packages/airflow/example_dags/example_dataset_alias.py for tasks to queue
[2025-02-22T23:44:47.610-0500] {logging_mixin.py:190} INFO - [2025-02-22T23:44:47.609-0500] {dagbag.py:588} INFO - Filling up the DagBag from /home/rafaelrb/anaconda3/lib/python3.9/site-packages/airflow/example_dags/example_dataset_alias.py
[2025-02-22T23:44:47.620-0500] {logging_mixin.py:190} INFO - [2025-02-22T23:44:47.617-0500] {dagbag.py:387} ERROR - Failed to import: /home/rafaelrb/anaconda3/lib/python3.9/site-packages/airflow/example_dags/example_dataset_alias.py
Traceback (most recent call last):
  File "/home/rafaelrb/anaconda3/lib/python3.9/site-packages/airflow/models/dagbag.py", line 383, in parse
    loader.exec_module(new_module)
  File "<frozen importlib._bootstrap_external>", line 850, in exec_module
  File "<frozen importlib._bootstrap>", line 228, in _call_with_frames_removed
  File "/home/rafaelrb/anaconda3/lib/python3.9/site-packages/airflow/example_dags/example_dataset_alias.py", line 53, in <module>
    def produce_dataset_events():
  File "/home/rafaelrb/anaconda3/lib/python3.9/site-packages/airflow/decorators/base.py", line 691, in decorator_factory
    return _TaskDecorator(
TypeError: _TaskDecorator() takes no arguments
[2025-02-22T23:44:47.621-0500] {processor.py:927} WARNING - No viable dags retrieved from /home/rafaelrb/anaconda3/lib/python3.9/site-packages/airflow/example_dags/example_dataset_alias.py
[2025-02-22T23:44:47.661-0500] {processor.py:208} INFO - Processing /home/rafaelrb/anaconda3/lib/python3.9/site-packages/airflow/example_dags/example_dataset_alias.py took 0.068 seconds
[2025-02-22T23:49:19.392-0500] {processor.py:186} INFO - Started process (PID=27774) to work on /home/rafaelrb/anaconda3/lib/python3.9/site-packages/airflow/example_dags/example_dataset_alias.py
[2025-02-22T23:49:19.397-0500] {processor.py:914} INFO - Processing file /home/rafaelrb/anaconda3/lib/python3.9/site-packages/airflow/example_dags/example_dataset_alias.py for tasks to queue
[2025-02-22T23:49:19.401-0500] {logging_mixin.py:190} INFO - [2025-02-22T23:49:19.400-0500] {dagbag.py:588} INFO - Filling up the DagBag from /home/rafaelrb/anaconda3/lib/python3.9/site-packages/airflow/example_dags/example_dataset_alias.py
[2025-02-22T23:49:19.412-0500] {logging_mixin.py:190} INFO - [2025-02-22T23:49:19.409-0500] {dagbag.py:387} ERROR - Failed to import: /home/rafaelrb/anaconda3/lib/python3.9/site-packages/airflow/example_dags/example_dataset_alias.py
Traceback (most recent call last):
  File "/home/rafaelrb/anaconda3/lib/python3.9/site-packages/airflow/models/dagbag.py", line 383, in parse
    loader.exec_module(new_module)
  File "<frozen importlib._bootstrap_external>", line 850, in exec_module
  File "<frozen importlib._bootstrap>", line 228, in _call_with_frames_removed
  File "/home/rafaelrb/anaconda3/lib/python3.9/site-packages/airflow/example_dags/example_dataset_alias.py", line 53, in <module>
    def produce_dataset_events():
  File "/home/rafaelrb/anaconda3/lib/python3.9/site-packages/airflow/decorators/base.py", line 691, in decorator_factory
    return _TaskDecorator(
TypeError: _TaskDecorator() takes no arguments
[2025-02-22T23:49:19.413-0500] {processor.py:927} WARNING - No viable dags retrieved from /home/rafaelrb/anaconda3/lib/python3.9/site-packages/airflow/example_dags/example_dataset_alias.py
[2025-02-22T23:49:19.448-0500] {processor.py:208} INFO - Processing /home/rafaelrb/anaconda3/lib/python3.9/site-packages/airflow/example_dags/example_dataset_alias.py took 0.065 seconds
[2025-02-22T23:50:22.063-0500] {processor.py:186} INFO - Started process (PID=28193) to work on /home/rafaelrb/anaconda3/lib/python3.9/site-packages/airflow/example_dags/example_dataset_alias.py
[2025-02-22T23:50:22.069-0500] {processor.py:914} INFO - Processing file /home/rafaelrb/anaconda3/lib/python3.9/site-packages/airflow/example_dags/example_dataset_alias.py for tasks to queue
[2025-02-22T23:50:22.072-0500] {logging_mixin.py:190} INFO - [2025-02-22T23:50:22.071-0500] {dagbag.py:588} INFO - Filling up the DagBag from /home/rafaelrb/anaconda3/lib/python3.9/site-packages/airflow/example_dags/example_dataset_alias.py
[2025-02-22T23:50:22.080-0500] {logging_mixin.py:190} INFO - [2025-02-22T23:50:22.079-0500] {dagbag.py:387} ERROR - Failed to import: /home/rafaelrb/anaconda3/lib/python3.9/site-packages/airflow/example_dags/example_dataset_alias.py
Traceback (most recent call last):
  File "/home/rafaelrb/anaconda3/lib/python3.9/site-packages/airflow/models/dagbag.py", line 383, in parse
    loader.exec_module(new_module)
  File "<frozen importlib._bootstrap_external>", line 850, in exec_module
  File "<frozen importlib._bootstrap>", line 228, in _call_with_frames_removed
  File "/home/rafaelrb/anaconda3/lib/python3.9/site-packages/airflow/example_dags/example_dataset_alias.py", line 53, in <module>
    def produce_dataset_events():
  File "/home/rafaelrb/anaconda3/lib/python3.9/site-packages/airflow/decorators/base.py", line 691, in decorator_factory
    return _TaskDecorator(
TypeError: _TaskDecorator() takes no arguments
[2025-02-22T23:50:22.080-0500] {processor.py:927} WARNING - No viable dags retrieved from /home/rafaelrb/anaconda3/lib/python3.9/site-packages/airflow/example_dags/example_dataset_alias.py
[2025-02-22T23:50:22.116-0500] {processor.py:208} INFO - Processing /home/rafaelrb/anaconda3/lib/python3.9/site-packages/airflow/example_dags/example_dataset_alias.py took 0.062 seconds
[2025-02-22T23:51:19.336-0500] {processor.py:186} INFO - Started process (PID=28628) to work on /home/rafaelrb/anaconda3/lib/python3.9/site-packages/airflow/example_dags/example_dataset_alias.py
[2025-02-22T23:51:19.337-0500] {processor.py:914} INFO - Processing file /home/rafaelrb/anaconda3/lib/python3.9/site-packages/airflow/example_dags/example_dataset_alias.py for tasks to queue
[2025-02-22T23:51:19.340-0500] {logging_mixin.py:190} INFO - [2025-02-22T23:51:19.340-0500] {dagbag.py:588} INFO - Filling up the DagBag from /home/rafaelrb/anaconda3/lib/python3.9/site-packages/airflow/example_dags/example_dataset_alias.py
[2025-02-22T23:51:19.360-0500] {logging_mixin.py:190} INFO - [2025-02-22T23:51:19.354-0500] {dagbag.py:387} ERROR - Failed to import: /home/rafaelrb/anaconda3/lib/python3.9/site-packages/airflow/example_dags/example_dataset_alias.py
Traceback (most recent call last):
  File "/home/rafaelrb/anaconda3/lib/python3.9/site-packages/airflow/models/dagbag.py", line 383, in parse
    loader.exec_module(new_module)
  File "<frozen importlib._bootstrap_external>", line 850, in exec_module
  File "<frozen importlib._bootstrap>", line 228, in _call_with_frames_removed
  File "/home/rafaelrb/anaconda3/lib/python3.9/site-packages/airflow/example_dags/example_dataset_alias.py", line 53, in <module>
    def produce_dataset_events():
  File "/home/rafaelrb/anaconda3/lib/python3.9/site-packages/airflow/decorators/base.py", line 691, in decorator_factory
    return _TaskDecorator(
TypeError: _TaskDecorator() takes no arguments
[2025-02-22T23:51:19.361-0500] {processor.py:927} WARNING - No viable dags retrieved from /home/rafaelrb/anaconda3/lib/python3.9/site-packages/airflow/example_dags/example_dataset_alias.py
[2025-02-22T23:51:19.391-0500] {processor.py:208} INFO - Processing /home/rafaelrb/anaconda3/lib/python3.9/site-packages/airflow/example_dags/example_dataset_alias.py took 0.067 seconds
[2025-02-22T23:52:17.843-0500] {processor.py:186} INFO - Started process (PID=29028) to work on /home/rafaelrb/anaconda3/lib/python3.9/site-packages/airflow/example_dags/example_dataset_alias.py
[2025-02-22T23:52:17.845-0500] {processor.py:914} INFO - Processing file /home/rafaelrb/anaconda3/lib/python3.9/site-packages/airflow/example_dags/example_dataset_alias.py for tasks to queue
[2025-02-22T23:52:17.848-0500] {logging_mixin.py:190} INFO - [2025-02-22T23:52:17.847-0500] {dagbag.py:588} INFO - Filling up the DagBag from /home/rafaelrb/anaconda3/lib/python3.9/site-packages/airflow/example_dags/example_dataset_alias.py
[2025-02-22T23:52:17.857-0500] {logging_mixin.py:190} INFO - [2025-02-22T23:52:17.856-0500] {dagbag.py:387} ERROR - Failed to import: /home/rafaelrb/anaconda3/lib/python3.9/site-packages/airflow/example_dags/example_dataset_alias.py
Traceback (most recent call last):
  File "/home/rafaelrb/anaconda3/lib/python3.9/site-packages/airflow/models/dagbag.py", line 383, in parse
    loader.exec_module(new_module)
  File "<frozen importlib._bootstrap_external>", line 850, in exec_module
  File "<frozen importlib._bootstrap>", line 228, in _call_with_frames_removed
  File "/home/rafaelrb/anaconda3/lib/python3.9/site-packages/airflow/example_dags/example_dataset_alias.py", line 53, in <module>
    def produce_dataset_events():
  File "/home/rafaelrb/anaconda3/lib/python3.9/site-packages/airflow/decorators/base.py", line 691, in decorator_factory
    return _TaskDecorator(
TypeError: _TaskDecorator() takes no arguments
[2025-02-22T23:52:17.857-0500] {processor.py:927} WARNING - No viable dags retrieved from /home/rafaelrb/anaconda3/lib/python3.9/site-packages/airflow/example_dags/example_dataset_alias.py
[2025-02-22T23:52:17.888-0500] {processor.py:208} INFO - Processing /home/rafaelrb/anaconda3/lib/python3.9/site-packages/airflow/example_dags/example_dataset_alias.py took 0.053 seconds
[2025-02-22T23:53:54.744-0500] {processor.py:186} INFO - Started process (PID=29711) to work on /home/rafaelrb/anaconda3/lib/python3.9/site-packages/airflow/example_dags/example_dataset_alias.py
[2025-02-22T23:53:54.745-0500] {processor.py:914} INFO - Processing file /home/rafaelrb/anaconda3/lib/python3.9/site-packages/airflow/example_dags/example_dataset_alias.py for tasks to queue
[2025-02-22T23:53:54.749-0500] {logging_mixin.py:190} INFO - [2025-02-22T23:53:54.748-0500] {dagbag.py:588} INFO - Filling up the DagBag from /home/rafaelrb/anaconda3/lib/python3.9/site-packages/airflow/example_dags/example_dataset_alias.py
[2025-02-22T23:53:54.759-0500] {logging_mixin.py:190} INFO - [2025-02-22T23:53:54.758-0500] {dagbag.py:387} ERROR - Failed to import: /home/rafaelrb/anaconda3/lib/python3.9/site-packages/airflow/example_dags/example_dataset_alias.py
Traceback (most recent call last):
  File "/home/rafaelrb/anaconda3/lib/python3.9/site-packages/airflow/models/dagbag.py", line 383, in parse
    loader.exec_module(new_module)
  File "<frozen importlib._bootstrap_external>", line 850, in exec_module
  File "<frozen importlib._bootstrap>", line 228, in _call_with_frames_removed
  File "/home/rafaelrb/anaconda3/lib/python3.9/site-packages/airflow/example_dags/example_dataset_alias.py", line 53, in <module>
    def produce_dataset_events():
  File "/home/rafaelrb/anaconda3/lib/python3.9/site-packages/airflow/decorators/base.py", line 691, in decorator_factory
    return _TaskDecorator(
TypeError: _TaskDecorator() takes no arguments
[2025-02-22T23:53:54.760-0500] {processor.py:927} WARNING - No viable dags retrieved from /home/rafaelrb/anaconda3/lib/python3.9/site-packages/airflow/example_dags/example_dataset_alias.py
[2025-02-22T23:53:54.795-0500] {processor.py:208} INFO - Processing /home/rafaelrb/anaconda3/lib/python3.9/site-packages/airflow/example_dags/example_dataset_alias.py took 0.060 seconds
[2025-02-22T23:54:57.053-0500] {processor.py:186} INFO - Started process (PID=30161) to work on /home/rafaelrb/anaconda3/lib/python3.9/site-packages/airflow/example_dags/example_dataset_alias.py
[2025-02-22T23:54:57.056-0500] {processor.py:914} INFO - Processing file /home/rafaelrb/anaconda3/lib/python3.9/site-packages/airflow/example_dags/example_dataset_alias.py for tasks to queue
[2025-02-22T23:54:57.060-0500] {logging_mixin.py:190} INFO - [2025-02-22T23:54:57.059-0500] {dagbag.py:588} INFO - Filling up the DagBag from /home/rafaelrb/anaconda3/lib/python3.9/site-packages/airflow/example_dags/example_dataset_alias.py
[2025-02-22T23:54:57.073-0500] {logging_mixin.py:190} INFO - [2025-02-22T23:54:57.069-0500] {dagbag.py:387} ERROR - Failed to import: /home/rafaelrb/anaconda3/lib/python3.9/site-packages/airflow/example_dags/example_dataset_alias.py
Traceback (most recent call last):
  File "/home/rafaelrb/anaconda3/lib/python3.9/site-packages/airflow/models/dagbag.py", line 383, in parse
    loader.exec_module(new_module)
  File "<frozen importlib._bootstrap_external>", line 850, in exec_module
  File "<frozen importlib._bootstrap>", line 228, in _call_with_frames_removed
  File "/home/rafaelrb/anaconda3/lib/python3.9/site-packages/airflow/example_dags/example_dataset_alias.py", line 53, in <module>
    def produce_dataset_events():
  File "/home/rafaelrb/anaconda3/lib/python3.9/site-packages/airflow/decorators/base.py", line 691, in decorator_factory
    return _TaskDecorator(
TypeError: _TaskDecorator() takes no arguments
[2025-02-22T23:54:57.074-0500] {processor.py:927} WARNING - No viable dags retrieved from /home/rafaelrb/anaconda3/lib/python3.9/site-packages/airflow/example_dags/example_dataset_alias.py
[2025-02-22T23:54:57.117-0500] {processor.py:208} INFO - Processing /home/rafaelrb/anaconda3/lib/python3.9/site-packages/airflow/example_dags/example_dataset_alias.py took 0.073 seconds
[2025-02-22T23:58:11.789-0500] {processor.py:186} INFO - Started process (PID=30699) to work on /home/rafaelrb/anaconda3/lib/python3.9/site-packages/airflow/example_dags/example_dataset_alias.py
[2025-02-22T23:58:11.791-0500] {processor.py:914} INFO - Processing file /home/rafaelrb/anaconda3/lib/python3.9/site-packages/airflow/example_dags/example_dataset_alias.py for tasks to queue
[2025-02-22T23:58:11.794-0500] {logging_mixin.py:190} INFO - [2025-02-22T23:58:11.793-0500] {dagbag.py:588} INFO - Filling up the DagBag from /home/rafaelrb/anaconda3/lib/python3.9/site-packages/airflow/example_dags/example_dataset_alias.py
[2025-02-22T23:58:11.806-0500] {logging_mixin.py:190} INFO - [2025-02-22T23:58:11.801-0500] {dagbag.py:387} ERROR - Failed to import: /home/rafaelrb/anaconda3/lib/python3.9/site-packages/airflow/example_dags/example_dataset_alias.py
Traceback (most recent call last):
  File "/home/rafaelrb/anaconda3/lib/python3.9/site-packages/airflow/models/dagbag.py", line 383, in parse
    loader.exec_module(new_module)
  File "<frozen importlib._bootstrap_external>", line 850, in exec_module
  File "<frozen importlib._bootstrap>", line 228, in _call_with_frames_removed
  File "/home/rafaelrb/anaconda3/lib/python3.9/site-packages/airflow/example_dags/example_dataset_alias.py", line 53, in <module>
    def produce_dataset_events():
  File "/home/rafaelrb/anaconda3/lib/python3.9/site-packages/airflow/decorators/base.py", line 691, in decorator_factory
    return _TaskDecorator(
TypeError: _TaskDecorator() takes no arguments
[2025-02-22T23:58:11.806-0500] {processor.py:927} WARNING - No viable dags retrieved from /home/rafaelrb/anaconda3/lib/python3.9/site-packages/airflow/example_dags/example_dataset_alias.py
[2025-02-22T23:58:11.840-0500] {processor.py:208} INFO - Processing /home/rafaelrb/anaconda3/lib/python3.9/site-packages/airflow/example_dags/example_dataset_alias.py took 0.060 seconds
[2025-02-22T23:59:16.583-0500] {processor.py:186} INFO - Started process (PID=31129) to work on /home/rafaelrb/anaconda3/lib/python3.9/site-packages/airflow/example_dags/example_dataset_alias.py
[2025-02-22T23:59:16.585-0500] {processor.py:914} INFO - Processing file /home/rafaelrb/anaconda3/lib/python3.9/site-packages/airflow/example_dags/example_dataset_alias.py for tasks to queue
[2025-02-22T23:59:16.588-0500] {logging_mixin.py:190} INFO - [2025-02-22T23:59:16.588-0500] {dagbag.py:588} INFO - Filling up the DagBag from /home/rafaelrb/anaconda3/lib/python3.9/site-packages/airflow/example_dags/example_dataset_alias.py
[2025-02-22T23:59:16.597-0500] {logging_mixin.py:190} INFO - [2025-02-22T23:59:16.596-0500] {dagbag.py:387} ERROR - Failed to import: /home/rafaelrb/anaconda3/lib/python3.9/site-packages/airflow/example_dags/example_dataset_alias.py
Traceback (most recent call last):
  File "/home/rafaelrb/anaconda3/lib/python3.9/site-packages/airflow/models/dagbag.py", line 383, in parse
    loader.exec_module(new_module)
  File "<frozen importlib._bootstrap_external>", line 850, in exec_module
  File "<frozen importlib._bootstrap>", line 228, in _call_with_frames_removed
  File "/home/rafaelrb/anaconda3/lib/python3.9/site-packages/airflow/example_dags/example_dataset_alias.py", line 53, in <module>
    def produce_dataset_events():
  File "/home/rafaelrb/anaconda3/lib/python3.9/site-packages/airflow/decorators/base.py", line 691, in decorator_factory
    return _TaskDecorator(
TypeError: _TaskDecorator() takes no arguments
[2025-02-22T23:59:16.598-0500] {processor.py:927} WARNING - No viable dags retrieved from /home/rafaelrb/anaconda3/lib/python3.9/site-packages/airflow/example_dags/example_dataset_alias.py
[2025-02-22T23:59:16.625-0500] {processor.py:208} INFO - Processing /home/rafaelrb/anaconda3/lib/python3.9/site-packages/airflow/example_dags/example_dataset_alias.py took 0.053 seconds
[2025-02-23T00:00:39.768-0500] {processor.py:186} INFO - Started process (PID=31691) to work on /home/rafaelrb/anaconda3/lib/python3.9/site-packages/airflow/example_dags/example_dataset_alias.py
[2025-02-23T00:00:39.771-0500] {processor.py:914} INFO - Processing file /home/rafaelrb/anaconda3/lib/python3.9/site-packages/airflow/example_dags/example_dataset_alias.py for tasks to queue
[2025-02-23T00:00:39.775-0500] {logging_mixin.py:190} INFO - [2025-02-23T00:00:39.774-0500] {dagbag.py:588} INFO - Filling up the DagBag from /home/rafaelrb/anaconda3/lib/python3.9/site-packages/airflow/example_dags/example_dataset_alias.py
[2025-02-23T00:00:39.786-0500] {logging_mixin.py:190} INFO - [2025-02-23T00:00:39.783-0500] {dagbag.py:387} ERROR - Failed to import: /home/rafaelrb/anaconda3/lib/python3.9/site-packages/airflow/example_dags/example_dataset_alias.py
Traceback (most recent call last):
  File "/home/rafaelrb/anaconda3/lib/python3.9/site-packages/airflow/models/dagbag.py", line 383, in parse
    loader.exec_module(new_module)
  File "<frozen importlib._bootstrap_external>", line 850, in exec_module
  File "<frozen importlib._bootstrap>", line 228, in _call_with_frames_removed
  File "/home/rafaelrb/anaconda3/lib/python3.9/site-packages/airflow/example_dags/example_dataset_alias.py", line 53, in <module>
    def produce_dataset_events():
  File "/home/rafaelrb/anaconda3/lib/python3.9/site-packages/airflow/decorators/base.py", line 691, in decorator_factory
    return _TaskDecorator(
TypeError: _TaskDecorator() takes no arguments
[2025-02-23T00:00:39.786-0500] {processor.py:927} WARNING - No viable dags retrieved from /home/rafaelrb/anaconda3/lib/python3.9/site-packages/airflow/example_dags/example_dataset_alias.py
[2025-02-23T00:00:39.822-0500] {processor.py:208} INFO - Processing /home/rafaelrb/anaconda3/lib/python3.9/site-packages/airflow/example_dags/example_dataset_alias.py took 0.068 seconds
[2025-02-23T00:01:41.555-0500] {processor.py:186} INFO - Started process (PID=32134) to work on /home/rafaelrb/anaconda3/lib/python3.9/site-packages/airflow/example_dags/example_dataset_alias.py
[2025-02-23T00:01:41.558-0500] {processor.py:914} INFO - Processing file /home/rafaelrb/anaconda3/lib/python3.9/site-packages/airflow/example_dags/example_dataset_alias.py for tasks to queue
[2025-02-23T00:01:41.561-0500] {logging_mixin.py:190} INFO - [2025-02-23T00:01:41.560-0500] {dagbag.py:588} INFO - Filling up the DagBag from /home/rafaelrb/anaconda3/lib/python3.9/site-packages/airflow/example_dags/example_dataset_alias.py
[2025-02-23T00:01:41.569-0500] {logging_mixin.py:190} INFO - [2025-02-23T00:01:41.567-0500] {dagbag.py:387} ERROR - Failed to import: /home/rafaelrb/anaconda3/lib/python3.9/site-packages/airflow/example_dags/example_dataset_alias.py
Traceback (most recent call last):
  File "/home/rafaelrb/anaconda3/lib/python3.9/site-packages/airflow/models/dagbag.py", line 383, in parse
    loader.exec_module(new_module)
  File "<frozen importlib._bootstrap_external>", line 850, in exec_module
  File "<frozen importlib._bootstrap>", line 228, in _call_with_frames_removed
  File "/home/rafaelrb/anaconda3/lib/python3.9/site-packages/airflow/example_dags/example_dataset_alias.py", line 53, in <module>
    def produce_dataset_events():
  File "/home/rafaelrb/anaconda3/lib/python3.9/site-packages/airflow/decorators/base.py", line 691, in decorator_factory
    return _TaskDecorator(
TypeError: _TaskDecorator() takes no arguments
[2025-02-23T00:01:41.569-0500] {processor.py:927} WARNING - No viable dags retrieved from /home/rafaelrb/anaconda3/lib/python3.9/site-packages/airflow/example_dags/example_dataset_alias.py
[2025-02-23T00:01:41.600-0500] {processor.py:208} INFO - Processing /home/rafaelrb/anaconda3/lib/python3.9/site-packages/airflow/example_dags/example_dataset_alias.py took 0.054 seconds
[2025-02-23T00:11:20.053-0500] {processor.py:186} INFO - Started process (PID=34423) to work on /home/rafaelrb/anaconda3/lib/python3.9/site-packages/airflow/example_dags/example_dataset_alias.py
[2025-02-23T00:11:20.060-0500] {processor.py:914} INFO - Processing file /home/rafaelrb/anaconda3/lib/python3.9/site-packages/airflow/example_dags/example_dataset_alias.py for tasks to queue
[2025-02-23T00:11:20.063-0500] {logging_mixin.py:190} INFO - [2025-02-23T00:11:20.063-0500] {dagbag.py:588} INFO - Filling up the DagBag from /home/rafaelrb/anaconda3/lib/python3.9/site-packages/airflow/example_dags/example_dataset_alias.py
[2025-02-23T00:11:20.071-0500] {logging_mixin.py:190} INFO - [2025-02-23T00:11:20.070-0500] {dagbag.py:387} ERROR - Failed to import: /home/rafaelrb/anaconda3/lib/python3.9/site-packages/airflow/example_dags/example_dataset_alias.py
Traceback (most recent call last):
  File "/home/rafaelrb/anaconda3/lib/python3.9/site-packages/airflow/models/dagbag.py", line 383, in parse
    loader.exec_module(new_module)
  File "<frozen importlib._bootstrap_external>", line 850, in exec_module
  File "<frozen importlib._bootstrap>", line 228, in _call_with_frames_removed
  File "/home/rafaelrb/anaconda3/lib/python3.9/site-packages/airflow/example_dags/example_dataset_alias.py", line 53, in <module>
    def produce_dataset_events():
  File "/home/rafaelrb/anaconda3/lib/python3.9/site-packages/airflow/decorators/base.py", line 691, in decorator_factory
    return _TaskDecorator(
TypeError: _TaskDecorator() takes no arguments
[2025-02-23T00:11:20.071-0500] {processor.py:927} WARNING - No viable dags retrieved from /home/rafaelrb/anaconda3/lib/python3.9/site-packages/airflow/example_dags/example_dataset_alias.py
[2025-02-23T00:11:20.100-0500] {processor.py:208} INFO - Processing /home/rafaelrb/anaconda3/lib/python3.9/site-packages/airflow/example_dags/example_dataset_alias.py took 0.055 seconds
[2025-02-23T00:12:20.918-0500] {processor.py:186} INFO - Started process (PID=34515) to work on /home/rafaelrb/anaconda3/lib/python3.9/site-packages/airflow/example_dags/example_dataset_alias.py
[2025-02-23T00:12:20.920-0500] {processor.py:914} INFO - Processing file /home/rafaelrb/anaconda3/lib/python3.9/site-packages/airflow/example_dags/example_dataset_alias.py for tasks to queue
[2025-02-23T00:12:20.923-0500] {logging_mixin.py:190} INFO - [2025-02-23T00:12:20.923-0500] {dagbag.py:588} INFO - Filling up the DagBag from /home/rafaelrb/anaconda3/lib/python3.9/site-packages/airflow/example_dags/example_dataset_alias.py
[2025-02-23T00:12:20.933-0500] {logging_mixin.py:190} INFO - [2025-02-23T00:12:20.931-0500] {dagbag.py:387} ERROR - Failed to import: /home/rafaelrb/anaconda3/lib/python3.9/site-packages/airflow/example_dags/example_dataset_alias.py
Traceback (most recent call last):
  File "/home/rafaelrb/anaconda3/lib/python3.9/site-packages/airflow/models/dagbag.py", line 383, in parse
    loader.exec_module(new_module)
  File "<frozen importlib._bootstrap_external>", line 850, in exec_module
  File "<frozen importlib._bootstrap>", line 228, in _call_with_frames_removed
  File "/home/rafaelrb/anaconda3/lib/python3.9/site-packages/airflow/example_dags/example_dataset_alias.py", line 53, in <module>
    def produce_dataset_events():
  File "/home/rafaelrb/anaconda3/lib/python3.9/site-packages/airflow/decorators/base.py", line 691, in decorator_factory
    return _TaskDecorator(
TypeError: _TaskDecorator() takes no arguments
[2025-02-23T00:12:20.934-0500] {processor.py:927} WARNING - No viable dags retrieved from /home/rafaelrb/anaconda3/lib/python3.9/site-packages/airflow/example_dags/example_dataset_alias.py
[2025-02-23T00:12:20.973-0500] {processor.py:208} INFO - Processing /home/rafaelrb/anaconda3/lib/python3.9/site-packages/airflow/example_dags/example_dataset_alias.py took 0.069 seconds
[2025-02-23T00:13:34.030-0500] {processor.py:186} INFO - Started process (PID=34620) to work on /home/rafaelrb/anaconda3/lib/python3.9/site-packages/airflow/example_dags/example_dataset_alias.py
[2025-02-23T00:13:34.037-0500] {processor.py:914} INFO - Processing file /home/rafaelrb/anaconda3/lib/python3.9/site-packages/airflow/example_dags/example_dataset_alias.py for tasks to queue
[2025-02-23T00:13:34.040-0500] {logging_mixin.py:190} INFO - [2025-02-23T00:13:34.039-0500] {dagbag.py:588} INFO - Filling up the DagBag from /home/rafaelrb/anaconda3/lib/python3.9/site-packages/airflow/example_dags/example_dataset_alias.py
[2025-02-23T00:13:34.049-0500] {logging_mixin.py:190} INFO - [2025-02-23T00:13:34.048-0500] {dagbag.py:387} ERROR - Failed to import: /home/rafaelrb/anaconda3/lib/python3.9/site-packages/airflow/example_dags/example_dataset_alias.py
Traceback (most recent call last):
  File "/home/rafaelrb/anaconda3/lib/python3.9/site-packages/airflow/models/dagbag.py", line 383, in parse
    loader.exec_module(new_module)
  File "<frozen importlib._bootstrap_external>", line 850, in exec_module
  File "<frozen importlib._bootstrap>", line 228, in _call_with_frames_removed
  File "/home/rafaelrb/anaconda3/lib/python3.9/site-packages/airflow/example_dags/example_dataset_alias.py", line 53, in <module>
    def produce_dataset_events():
  File "/home/rafaelrb/anaconda3/lib/python3.9/site-packages/airflow/decorators/base.py", line 691, in decorator_factory
    return _TaskDecorator(
TypeError: _TaskDecorator() takes no arguments
[2025-02-23T00:13:34.050-0500] {processor.py:927} WARNING - No viable dags retrieved from /home/rafaelrb/anaconda3/lib/python3.9/site-packages/airflow/example_dags/example_dataset_alias.py
[2025-02-23T00:13:34.099-0500] {processor.py:208} INFO - Processing /home/rafaelrb/anaconda3/lib/python3.9/site-packages/airflow/example_dags/example_dataset_alias.py took 0.079 seconds
[2025-02-23T00:14:31.785-0500] {processor.py:186} INFO - Started process (PID=34697) to work on /home/rafaelrb/anaconda3/lib/python3.9/site-packages/airflow/example_dags/example_dataset_alias.py
[2025-02-23T00:14:31.791-0500] {processor.py:914} INFO - Processing file /home/rafaelrb/anaconda3/lib/python3.9/site-packages/airflow/example_dags/example_dataset_alias.py for tasks to queue
[2025-02-23T00:14:31.803-0500] {logging_mixin.py:190} INFO - [2025-02-23T00:14:31.803-0500] {dagbag.py:588} INFO - Filling up the DagBag from /home/rafaelrb/anaconda3/lib/python3.9/site-packages/airflow/example_dags/example_dataset_alias.py
[2025-02-23T00:14:31.828-0500] {logging_mixin.py:190} INFO - [2025-02-23T00:14:31.826-0500] {dagbag.py:387} ERROR - Failed to import: /home/rafaelrb/anaconda3/lib/python3.9/site-packages/airflow/example_dags/example_dataset_alias.py
Traceback (most recent call last):
  File "/home/rafaelrb/anaconda3/lib/python3.9/site-packages/airflow/models/dagbag.py", line 383, in parse
    loader.exec_module(new_module)
  File "<frozen importlib._bootstrap_external>", line 850, in exec_module
  File "<frozen importlib._bootstrap>", line 228, in _call_with_frames_removed
  File "/home/rafaelrb/anaconda3/lib/python3.9/site-packages/airflow/example_dags/example_dataset_alias.py", line 53, in <module>
    def produce_dataset_events():
  File "/home/rafaelrb/anaconda3/lib/python3.9/site-packages/airflow/decorators/base.py", line 691, in decorator_factory
    return _TaskDecorator(
TypeError: _TaskDecorator() takes no arguments
[2025-02-23T00:14:31.829-0500] {processor.py:927} WARNING - No viable dags retrieved from /home/rafaelrb/anaconda3/lib/python3.9/site-packages/airflow/example_dags/example_dataset_alias.py
[2025-02-23T00:14:31.873-0500] {processor.py:208} INFO - Processing /home/rafaelrb/anaconda3/lib/python3.9/site-packages/airflow/example_dags/example_dataset_alias.py took 0.106 seconds
[2025-02-23T00:15:42.095-0500] {processor.py:186} INFO - Started process (PID=34793) to work on /home/rafaelrb/anaconda3/lib/python3.9/site-packages/airflow/example_dags/example_dataset_alias.py
[2025-02-23T00:15:42.097-0500] {processor.py:914} INFO - Processing file /home/rafaelrb/anaconda3/lib/python3.9/site-packages/airflow/example_dags/example_dataset_alias.py for tasks to queue
[2025-02-23T00:15:42.099-0500] {logging_mixin.py:190} INFO - [2025-02-23T00:15:42.099-0500] {dagbag.py:588} INFO - Filling up the DagBag from /home/rafaelrb/anaconda3/lib/python3.9/site-packages/airflow/example_dags/example_dataset_alias.py
[2025-02-23T00:15:42.111-0500] {logging_mixin.py:190} INFO - [2025-02-23T00:15:42.109-0500] {dagbag.py:387} ERROR - Failed to import: /home/rafaelrb/anaconda3/lib/python3.9/site-packages/airflow/example_dags/example_dataset_alias.py
Traceback (most recent call last):
  File "/home/rafaelrb/anaconda3/lib/python3.9/site-packages/airflow/models/dagbag.py", line 383, in parse
    loader.exec_module(new_module)
  File "<frozen importlib._bootstrap_external>", line 850, in exec_module
  File "<frozen importlib._bootstrap>", line 228, in _call_with_frames_removed
  File "/home/rafaelrb/anaconda3/lib/python3.9/site-packages/airflow/example_dags/example_dataset_alias.py", line 53, in <module>
    def produce_dataset_events():
  File "/home/rafaelrb/anaconda3/lib/python3.9/site-packages/airflow/decorators/base.py", line 691, in decorator_factory
    return _TaskDecorator(
TypeError: _TaskDecorator() takes no arguments
[2025-02-23T00:15:42.112-0500] {processor.py:927} WARNING - No viable dags retrieved from /home/rafaelrb/anaconda3/lib/python3.9/site-packages/airflow/example_dags/example_dataset_alias.py
[2025-02-23T00:15:42.147-0500] {processor.py:208} INFO - Processing /home/rafaelrb/anaconda3/lib/python3.9/site-packages/airflow/example_dags/example_dataset_alias.py took 0.063 seconds
[2025-02-23T00:16:43.535-0500] {processor.py:186} INFO - Started process (PID=34891) to work on /home/rafaelrb/anaconda3/lib/python3.9/site-packages/airflow/example_dags/example_dataset_alias.py
[2025-02-23T00:16:43.536-0500] {processor.py:914} INFO - Processing file /home/rafaelrb/anaconda3/lib/python3.9/site-packages/airflow/example_dags/example_dataset_alias.py for tasks to queue
[2025-02-23T00:16:43.539-0500] {logging_mixin.py:190} INFO - [2025-02-23T00:16:43.538-0500] {dagbag.py:588} INFO - Filling up the DagBag from /home/rafaelrb/anaconda3/lib/python3.9/site-packages/airflow/example_dags/example_dataset_alias.py
[2025-02-23T00:16:43.554-0500] {logging_mixin.py:190} INFO - [2025-02-23T00:16:43.553-0500] {dagbag.py:387} ERROR - Failed to import: /home/rafaelrb/anaconda3/lib/python3.9/site-packages/airflow/example_dags/example_dataset_alias.py
Traceback (most recent call last):
  File "/home/rafaelrb/anaconda3/lib/python3.9/site-packages/airflow/models/dagbag.py", line 383, in parse
    loader.exec_module(new_module)
  File "<frozen importlib._bootstrap_external>", line 850, in exec_module
  File "<frozen importlib._bootstrap>", line 228, in _call_with_frames_removed
  File "/home/rafaelrb/anaconda3/lib/python3.9/site-packages/airflow/example_dags/example_dataset_alias.py", line 53, in <module>
    def produce_dataset_events():
  File "/home/rafaelrb/anaconda3/lib/python3.9/site-packages/airflow/decorators/base.py", line 691, in decorator_factory
    return _TaskDecorator(
TypeError: _TaskDecorator() takes no arguments
[2025-02-23T00:16:43.555-0500] {processor.py:927} WARNING - No viable dags retrieved from /home/rafaelrb/anaconda3/lib/python3.9/site-packages/airflow/example_dags/example_dataset_alias.py
[2025-02-23T00:16:43.654-0500] {processor.py:208} INFO - Processing /home/rafaelrb/anaconda3/lib/python3.9/site-packages/airflow/example_dags/example_dataset_alias.py took 0.131 seconds
[2025-02-23T00:17:45.749-0500] {processor.py:186} INFO - Started process (PID=34972) to work on /home/rafaelrb/anaconda3/lib/python3.9/site-packages/airflow/example_dags/example_dataset_alias.py
[2025-02-23T00:17:45.751-0500] {processor.py:914} INFO - Processing file /home/rafaelrb/anaconda3/lib/python3.9/site-packages/airflow/example_dags/example_dataset_alias.py for tasks to queue
[2025-02-23T00:17:45.754-0500] {logging_mixin.py:190} INFO - [2025-02-23T00:17:45.753-0500] {dagbag.py:588} INFO - Filling up the DagBag from /home/rafaelrb/anaconda3/lib/python3.9/site-packages/airflow/example_dags/example_dataset_alias.py
[2025-02-23T00:17:45.763-0500] {logging_mixin.py:190} INFO - [2025-02-23T00:17:45.761-0500] {dagbag.py:387} ERROR - Failed to import: /home/rafaelrb/anaconda3/lib/python3.9/site-packages/airflow/example_dags/example_dataset_alias.py
Traceback (most recent call last):
  File "/home/rafaelrb/anaconda3/lib/python3.9/site-packages/airflow/models/dagbag.py", line 383, in parse
    loader.exec_module(new_module)
  File "<frozen importlib._bootstrap_external>", line 850, in exec_module
  File "<frozen importlib._bootstrap>", line 228, in _call_with_frames_removed
  File "/home/rafaelrb/anaconda3/lib/python3.9/site-packages/airflow/example_dags/example_dataset_alias.py", line 53, in <module>
    def produce_dataset_events():
  File "/home/rafaelrb/anaconda3/lib/python3.9/site-packages/airflow/decorators/base.py", line 691, in decorator_factory
    return _TaskDecorator(
TypeError: _TaskDecorator() takes no arguments
[2025-02-23T00:17:45.763-0500] {processor.py:927} WARNING - No viable dags retrieved from /home/rafaelrb/anaconda3/lib/python3.9/site-packages/airflow/example_dags/example_dataset_alias.py
[2025-02-23T00:17:45.794-0500] {processor.py:208} INFO - Processing /home/rafaelrb/anaconda3/lib/python3.9/site-packages/airflow/example_dags/example_dataset_alias.py took 0.055 seconds
[2025-02-23T00:18:46.423-0500] {processor.py:186} INFO - Started process (PID=35038) to work on /home/rafaelrb/anaconda3/lib/python3.9/site-packages/airflow/example_dags/example_dataset_alias.py
[2025-02-23T00:18:46.429-0500] {processor.py:914} INFO - Processing file /home/rafaelrb/anaconda3/lib/python3.9/site-packages/airflow/example_dags/example_dataset_alias.py for tasks to queue
[2025-02-23T00:18:46.432-0500] {logging_mixin.py:190} INFO - [2025-02-23T00:18:46.432-0500] {dagbag.py:588} INFO - Filling up the DagBag from /home/rafaelrb/anaconda3/lib/python3.9/site-packages/airflow/example_dags/example_dataset_alias.py
[2025-02-23T00:18:46.440-0500] {logging_mixin.py:190} INFO - [2025-02-23T00:18:46.439-0500] {dagbag.py:387} ERROR - Failed to import: /home/rafaelrb/anaconda3/lib/python3.9/site-packages/airflow/example_dags/example_dataset_alias.py
Traceback (most recent call last):
  File "/home/rafaelrb/anaconda3/lib/python3.9/site-packages/airflow/models/dagbag.py", line 383, in parse
    loader.exec_module(new_module)
  File "<frozen importlib._bootstrap_external>", line 850, in exec_module
  File "<frozen importlib._bootstrap>", line 228, in _call_with_frames_removed
  File "/home/rafaelrb/anaconda3/lib/python3.9/site-packages/airflow/example_dags/example_dataset_alias.py", line 53, in <module>
    def produce_dataset_events():
  File "/home/rafaelrb/anaconda3/lib/python3.9/site-packages/airflow/decorators/base.py", line 691, in decorator_factory
    return _TaskDecorator(
TypeError: _TaskDecorator() takes no arguments
[2025-02-23T00:18:46.441-0500] {processor.py:927} WARNING - No viable dags retrieved from /home/rafaelrb/anaconda3/lib/python3.9/site-packages/airflow/example_dags/example_dataset_alias.py
[2025-02-23T00:18:46.480-0500] {processor.py:208} INFO - Processing /home/rafaelrb/anaconda3/lib/python3.9/site-packages/airflow/example_dags/example_dataset_alias.py took 0.066 seconds
[2025-02-23T00:22:02.040-0500] {processor.py:186} INFO - Started process (PID=35184) to work on /home/rafaelrb/anaconda3/lib/python3.9/site-packages/airflow/example_dags/example_dataset_alias.py
[2025-02-23T00:22:02.045-0500] {processor.py:914} INFO - Processing file /home/rafaelrb/anaconda3/lib/python3.9/site-packages/airflow/example_dags/example_dataset_alias.py for tasks to queue
[2025-02-23T00:22:02.050-0500] {logging_mixin.py:190} INFO - [2025-02-23T00:22:02.050-0500] {dagbag.py:588} INFO - Filling up the DagBag from /home/rafaelrb/anaconda3/lib/python3.9/site-packages/airflow/example_dags/example_dataset_alias.py
[2025-02-23T00:22:02.058-0500] {logging_mixin.py:190} INFO - [2025-02-23T00:22:02.057-0500] {dagbag.py:387} ERROR - Failed to import: /home/rafaelrb/anaconda3/lib/python3.9/site-packages/airflow/example_dags/example_dataset_alias.py
Traceback (most recent call last):
  File "/home/rafaelrb/anaconda3/lib/python3.9/site-packages/airflow/models/dagbag.py", line 383, in parse
    loader.exec_module(new_module)
  File "<frozen importlib._bootstrap_external>", line 850, in exec_module
  File "<frozen importlib._bootstrap>", line 228, in _call_with_frames_removed
  File "/home/rafaelrb/anaconda3/lib/python3.9/site-packages/airflow/example_dags/example_dataset_alias.py", line 53, in <module>
    def produce_dataset_events():
  File "/home/rafaelrb/anaconda3/lib/python3.9/site-packages/airflow/decorators/base.py", line 691, in decorator_factory
    return _TaskDecorator(
TypeError: _TaskDecorator() takes no arguments
[2025-02-23T00:22:02.058-0500] {processor.py:927} WARNING - No viable dags retrieved from /home/rafaelrb/anaconda3/lib/python3.9/site-packages/airflow/example_dags/example_dataset_alias.py
[2025-02-23T00:22:02.100-0500] {processor.py:208} INFO - Processing /home/rafaelrb/anaconda3/lib/python3.9/site-packages/airflow/example_dags/example_dataset_alias.py took 0.071 seconds
[2025-02-23T00:23:02.390-0500] {processor.py:186} INFO - Started process (PID=35250) to work on /home/rafaelrb/anaconda3/lib/python3.9/site-packages/airflow/example_dags/example_dataset_alias.py
[2025-02-23T00:23:02.392-0500] {processor.py:914} INFO - Processing file /home/rafaelrb/anaconda3/lib/python3.9/site-packages/airflow/example_dags/example_dataset_alias.py for tasks to queue
[2025-02-23T00:23:02.395-0500] {logging_mixin.py:190} INFO - [2025-02-23T00:23:02.394-0500] {dagbag.py:588} INFO - Filling up the DagBag from /home/rafaelrb/anaconda3/lib/python3.9/site-packages/airflow/example_dags/example_dataset_alias.py
[2025-02-23T00:23:02.402-0500] {logging_mixin.py:190} INFO - [2025-02-23T00:23:02.401-0500] {dagbag.py:387} ERROR - Failed to import: /home/rafaelrb/anaconda3/lib/python3.9/site-packages/airflow/example_dags/example_dataset_alias.py
Traceback (most recent call last):
  File "/home/rafaelrb/anaconda3/lib/python3.9/site-packages/airflow/models/dagbag.py", line 383, in parse
    loader.exec_module(new_module)
  File "<frozen importlib._bootstrap_external>", line 850, in exec_module
  File "<frozen importlib._bootstrap>", line 228, in _call_with_frames_removed
  File "/home/rafaelrb/anaconda3/lib/python3.9/site-packages/airflow/example_dags/example_dataset_alias.py", line 53, in <module>
    def produce_dataset_events():
  File "/home/rafaelrb/anaconda3/lib/python3.9/site-packages/airflow/decorators/base.py", line 691, in decorator_factory
    return _TaskDecorator(
TypeError: _TaskDecorator() takes no arguments
[2025-02-23T00:23:02.403-0500] {processor.py:927} WARNING - No viable dags retrieved from /home/rafaelrb/anaconda3/lib/python3.9/site-packages/airflow/example_dags/example_dataset_alias.py
[2025-02-23T00:23:02.434-0500] {processor.py:208} INFO - Processing /home/rafaelrb/anaconda3/lib/python3.9/site-packages/airflow/example_dags/example_dataset_alias.py took 0.051 seconds
[2025-02-23T00:24:04.632-0500] {processor.py:186} INFO - Started process (PID=35324) to work on /home/rafaelrb/anaconda3/lib/python3.9/site-packages/airflow/example_dags/example_dataset_alias.py
[2025-02-23T00:24:04.633-0500] {processor.py:914} INFO - Processing file /home/rafaelrb/anaconda3/lib/python3.9/site-packages/airflow/example_dags/example_dataset_alias.py for tasks to queue
[2025-02-23T00:24:04.636-0500] {logging_mixin.py:190} INFO - [2025-02-23T00:24:04.636-0500] {dagbag.py:588} INFO - Filling up the DagBag from /home/rafaelrb/anaconda3/lib/python3.9/site-packages/airflow/example_dags/example_dataset_alias.py
[2025-02-23T00:24:04.644-0500] {logging_mixin.py:190} INFO - [2025-02-23T00:24:04.643-0500] {dagbag.py:387} ERROR - Failed to import: /home/rafaelrb/anaconda3/lib/python3.9/site-packages/airflow/example_dags/example_dataset_alias.py
Traceback (most recent call last):
  File "/home/rafaelrb/anaconda3/lib/python3.9/site-packages/airflow/models/dagbag.py", line 383, in parse
    loader.exec_module(new_module)
  File "<frozen importlib._bootstrap_external>", line 850, in exec_module
  File "<frozen importlib._bootstrap>", line 228, in _call_with_frames_removed
  File "/home/rafaelrb/anaconda3/lib/python3.9/site-packages/airflow/example_dags/example_dataset_alias.py", line 53, in <module>
    def produce_dataset_events():
  File "/home/rafaelrb/anaconda3/lib/python3.9/site-packages/airflow/decorators/base.py", line 691, in decorator_factory
    return _TaskDecorator(
TypeError: _TaskDecorator() takes no arguments
[2025-02-23T00:24:04.644-0500] {processor.py:927} WARNING - No viable dags retrieved from /home/rafaelrb/anaconda3/lib/python3.9/site-packages/airflow/example_dags/example_dataset_alias.py
[2025-02-23T00:24:04.679-0500] {processor.py:208} INFO - Processing /home/rafaelrb/anaconda3/lib/python3.9/site-packages/airflow/example_dags/example_dataset_alias.py took 0.056 seconds
[2025-02-23T00:25:06.606-0500] {processor.py:186} INFO - Started process (PID=35392) to work on /home/rafaelrb/anaconda3/lib/python3.9/site-packages/airflow/example_dags/example_dataset_alias.py
[2025-02-23T00:25:06.613-0500] {processor.py:914} INFO - Processing file /home/rafaelrb/anaconda3/lib/python3.9/site-packages/airflow/example_dags/example_dataset_alias.py for tasks to queue
[2025-02-23T00:25:06.616-0500] {logging_mixin.py:190} INFO - [2025-02-23T00:25:06.615-0500] {dagbag.py:588} INFO - Filling up the DagBag from /home/rafaelrb/anaconda3/lib/python3.9/site-packages/airflow/example_dags/example_dataset_alias.py
[2025-02-23T00:25:06.623-0500] {logging_mixin.py:190} INFO - [2025-02-23T00:25:06.622-0500] {dagbag.py:387} ERROR - Failed to import: /home/rafaelrb/anaconda3/lib/python3.9/site-packages/airflow/example_dags/example_dataset_alias.py
Traceback (most recent call last):
  File "/home/rafaelrb/anaconda3/lib/python3.9/site-packages/airflow/models/dagbag.py", line 383, in parse
    loader.exec_module(new_module)
  File "<frozen importlib._bootstrap_external>", line 850, in exec_module
  File "<frozen importlib._bootstrap>", line 228, in _call_with_frames_removed
  File "/home/rafaelrb/anaconda3/lib/python3.9/site-packages/airflow/example_dags/example_dataset_alias.py", line 53, in <module>
    def produce_dataset_events():
  File "/home/rafaelrb/anaconda3/lib/python3.9/site-packages/airflow/decorators/base.py", line 691, in decorator_factory
    return _TaskDecorator(
TypeError: _TaskDecorator() takes no arguments
[2025-02-23T00:25:06.623-0500] {processor.py:927} WARNING - No viable dags retrieved from /home/rafaelrb/anaconda3/lib/python3.9/site-packages/airflow/example_dags/example_dataset_alias.py
[2025-02-23T00:25:06.652-0500] {processor.py:208} INFO - Processing /home/rafaelrb/anaconda3/lib/python3.9/site-packages/airflow/example_dags/example_dataset_alias.py took 0.054 seconds
[2025-02-23T00:26:06.573-0500] {processor.py:186} INFO - Started process (PID=35464) to work on /home/rafaelrb/anaconda3/lib/python3.9/site-packages/airflow/example_dags/example_dataset_alias.py
[2025-02-23T00:26:06.580-0500] {processor.py:914} INFO - Processing file /home/rafaelrb/anaconda3/lib/python3.9/site-packages/airflow/example_dags/example_dataset_alias.py for tasks to queue
[2025-02-23T00:26:06.583-0500] {logging_mixin.py:190} INFO - [2025-02-23T00:26:06.583-0500] {dagbag.py:588} INFO - Filling up the DagBag from /home/rafaelrb/anaconda3/lib/python3.9/site-packages/airflow/example_dags/example_dataset_alias.py
[2025-02-23T00:26:06.593-0500] {logging_mixin.py:190} INFO - [2025-02-23T00:26:06.591-0500] {dagbag.py:387} ERROR - Failed to import: /home/rafaelrb/anaconda3/lib/python3.9/site-packages/airflow/example_dags/example_dataset_alias.py
Traceback (most recent call last):
  File "/home/rafaelrb/anaconda3/lib/python3.9/site-packages/airflow/models/dagbag.py", line 383, in parse
    loader.exec_module(new_module)
  File "<frozen importlib._bootstrap_external>", line 850, in exec_module
  File "<frozen importlib._bootstrap>", line 228, in _call_with_frames_removed
  File "/home/rafaelrb/anaconda3/lib/python3.9/site-packages/airflow/example_dags/example_dataset_alias.py", line 53, in <module>
    def produce_dataset_events():
  File "/home/rafaelrb/anaconda3/lib/python3.9/site-packages/airflow/decorators/base.py", line 691, in decorator_factory
    return _TaskDecorator(
TypeError: _TaskDecorator() takes no arguments
[2025-02-23T00:26:06.595-0500] {processor.py:927} WARNING - No viable dags retrieved from /home/rafaelrb/anaconda3/lib/python3.9/site-packages/airflow/example_dags/example_dataset_alias.py
[2025-02-23T00:26:06.638-0500] {processor.py:208} INFO - Processing /home/rafaelrb/anaconda3/lib/python3.9/site-packages/airflow/example_dags/example_dataset_alias.py took 0.078 seconds
[2025-02-23T02:32:11.829-0500] {processor.py:186} INFO - Started process (PID=76243) to work on /home/rafaelrb/anaconda3/lib/python3.9/site-packages/airflow/example_dags/example_dataset_alias.py
[2025-02-23T02:32:11.836-0500] {processor.py:914} INFO - Processing file /home/rafaelrb/anaconda3/lib/python3.9/site-packages/airflow/example_dags/example_dataset_alias.py for tasks to queue
[2025-02-23T02:32:11.840-0500] {logging_mixin.py:190} INFO - [2025-02-23T02:32:11.840-0500] {dagbag.py:588} INFO - Filling up the DagBag from /home/rafaelrb/anaconda3/lib/python3.9/site-packages/airflow/example_dags/example_dataset_alias.py
[2025-02-23T02:32:11.848-0500] {logging_mixin.py:190} INFO - [2025-02-23T02:32:11.847-0500] {dagbag.py:387} ERROR - Failed to import: /home/rafaelrb/anaconda3/lib/python3.9/site-packages/airflow/example_dags/example_dataset_alias.py
Traceback (most recent call last):
  File "/home/rafaelrb/anaconda3/lib/python3.9/site-packages/airflow/models/dagbag.py", line 383, in parse
    loader.exec_module(new_module)
  File "<frozen importlib._bootstrap_external>", line 850, in exec_module
  File "<frozen importlib._bootstrap>", line 228, in _call_with_frames_removed
  File "/home/rafaelrb/anaconda3/lib/python3.9/site-packages/airflow/example_dags/example_dataset_alias.py", line 53, in <module>
    def produce_dataset_events():
  File "/home/rafaelrb/anaconda3/lib/python3.9/site-packages/airflow/decorators/base.py", line 691, in decorator_factory
    return _TaskDecorator(
TypeError: _TaskDecorator() takes no arguments
[2025-02-23T02:32:11.849-0500] {processor.py:927} WARNING - No viable dags retrieved from /home/rafaelrb/anaconda3/lib/python3.9/site-packages/airflow/example_dags/example_dataset_alias.py
[2025-02-23T02:32:11.886-0500] {processor.py:208} INFO - Processing /home/rafaelrb/anaconda3/lib/python3.9/site-packages/airflow/example_dags/example_dataset_alias.py took 0.068 seconds
[2025-02-23T02:33:25.600-0500] {processor.py:186} INFO - Started process (PID=76696) to work on /home/rafaelrb/anaconda3/lib/python3.9/site-packages/airflow/example_dags/example_dataset_alias.py
[2025-02-23T02:33:25.867-0500] {processor.py:914} INFO - Processing file /home/rafaelrb/anaconda3/lib/python3.9/site-packages/airflow/example_dags/example_dataset_alias.py for tasks to queue
[2025-02-23T02:33:25.873-0500] {logging_mixin.py:190} INFO - [2025-02-23T02:33:25.872-0500] {dagbag.py:588} INFO - Filling up the DagBag from /home/rafaelrb/anaconda3/lib/python3.9/site-packages/airflow/example_dags/example_dataset_alias.py
[2025-02-23T02:33:25.896-0500] {logging_mixin.py:190} INFO - [2025-02-23T02:33:25.894-0500] {dagbag.py:387} ERROR - Failed to import: /home/rafaelrb/anaconda3/lib/python3.9/site-packages/airflow/example_dags/example_dataset_alias.py
Traceback (most recent call last):
  File "/home/rafaelrb/anaconda3/lib/python3.9/site-packages/airflow/models/dagbag.py", line 383, in parse
    loader.exec_module(new_module)
  File "<frozen importlib._bootstrap_external>", line 850, in exec_module
  File "<frozen importlib._bootstrap>", line 228, in _call_with_frames_removed
  File "/home/rafaelrb/anaconda3/lib/python3.9/site-packages/airflow/example_dags/example_dataset_alias.py", line 53, in <module>
    def produce_dataset_events():
  File "/home/rafaelrb/anaconda3/lib/python3.9/site-packages/airflow/decorators/base.py", line 691, in decorator_factory
    return _TaskDecorator(
TypeError: _TaskDecorator() takes no arguments
[2025-02-23T02:33:25.897-0500] {processor.py:927} WARNING - No viable dags retrieved from /home/rafaelrb/anaconda3/lib/python3.9/site-packages/airflow/example_dags/example_dataset_alias.py
[2025-02-23T02:33:25.960-0500] {processor.py:208} INFO - Processing /home/rafaelrb/anaconda3/lib/python3.9/site-packages/airflow/example_dags/example_dataset_alias.py took 0.406 seconds
[2025-02-23T02:34:48.366-0500] {processor.py:186} INFO - Started process (PID=77030) to work on /home/rafaelrb/anaconda3/lib/python3.9/site-packages/airflow/example_dags/example_dataset_alias.py
[2025-02-23T02:34:48.368-0500] {processor.py:914} INFO - Processing file /home/rafaelrb/anaconda3/lib/python3.9/site-packages/airflow/example_dags/example_dataset_alias.py for tasks to queue
[2025-02-23T02:34:48.371-0500] {logging_mixin.py:190} INFO - [2025-02-23T02:34:48.370-0500] {dagbag.py:588} INFO - Filling up the DagBag from /home/rafaelrb/anaconda3/lib/python3.9/site-packages/airflow/example_dags/example_dataset_alias.py
[2025-02-23T02:34:48.380-0500] {logging_mixin.py:190} INFO - [2025-02-23T02:34:48.377-0500] {dagbag.py:387} ERROR - Failed to import: /home/rafaelrb/anaconda3/lib/python3.9/site-packages/airflow/example_dags/example_dataset_alias.py
Traceback (most recent call last):
  File "/home/rafaelrb/anaconda3/lib/python3.9/site-packages/airflow/models/dagbag.py", line 383, in parse
    loader.exec_module(new_module)
  File "<frozen importlib._bootstrap_external>", line 850, in exec_module
  File "<frozen importlib._bootstrap>", line 228, in _call_with_frames_removed
  File "/home/rafaelrb/anaconda3/lib/python3.9/site-packages/airflow/example_dags/example_dataset_alias.py", line 53, in <module>
    def produce_dataset_events():
  File "/home/rafaelrb/anaconda3/lib/python3.9/site-packages/airflow/decorators/base.py", line 691, in decorator_factory
    return _TaskDecorator(
TypeError: _TaskDecorator() takes no arguments
[2025-02-23T02:34:48.381-0500] {processor.py:927} WARNING - No viable dags retrieved from /home/rafaelrb/anaconda3/lib/python3.9/site-packages/airflow/example_dags/example_dataset_alias.py
[2025-02-23T02:34:48.431-0500] {processor.py:208} INFO - Processing /home/rafaelrb/anaconda3/lib/python3.9/site-packages/airflow/example_dags/example_dataset_alias.py took 0.075 seconds
[2025-02-23T02:43:51.446-0500] {processor.py:186} INFO - Started process (PID=79182) to work on /home/rafaelrb/anaconda3/lib/python3.9/site-packages/airflow/example_dags/example_dataset_alias.py
[2025-02-23T02:43:51.447-0500] {processor.py:914} INFO - Processing file /home/rafaelrb/anaconda3/lib/python3.9/site-packages/airflow/example_dags/example_dataset_alias.py for tasks to queue
[2025-02-23T02:43:51.450-0500] {logging_mixin.py:190} INFO - [2025-02-23T02:43:51.449-0500] {dagbag.py:588} INFO - Filling up the DagBag from /home/rafaelrb/anaconda3/lib/python3.9/site-packages/airflow/example_dags/example_dataset_alias.py
[2025-02-23T02:43:51.457-0500] {logging_mixin.py:190} INFO - [2025-02-23T02:43:51.456-0500] {dagbag.py:387} ERROR - Failed to import: /home/rafaelrb/anaconda3/lib/python3.9/site-packages/airflow/example_dags/example_dataset_alias.py
Traceback (most recent call last):
  File "/home/rafaelrb/anaconda3/lib/python3.9/site-packages/airflow/models/dagbag.py", line 383, in parse
    loader.exec_module(new_module)
  File "<frozen importlib._bootstrap_external>", line 850, in exec_module
  File "<frozen importlib._bootstrap>", line 228, in _call_with_frames_removed
  File "/home/rafaelrb/anaconda3/lib/python3.9/site-packages/airflow/example_dags/example_dataset_alias.py", line 53, in <module>
    def produce_dataset_events():
  File "/home/rafaelrb/anaconda3/lib/python3.9/site-packages/airflow/decorators/base.py", line 691, in decorator_factory
    return _TaskDecorator(
TypeError: _TaskDecorator() takes no arguments
[2025-02-23T02:43:51.458-0500] {processor.py:927} WARNING - No viable dags retrieved from /home/rafaelrb/anaconda3/lib/python3.9/site-packages/airflow/example_dags/example_dataset_alias.py
[2025-02-23T02:43:51.486-0500] {processor.py:208} INFO - Processing /home/rafaelrb/anaconda3/lib/python3.9/site-packages/airflow/example_dags/example_dataset_alias.py took 0.051 seconds
