[2025-02-22T23:43:38.451-0500] {processor.py:186} INFO - Started process (PID=26668) to work on /home/rafaelrb/anaconda3/lib/python3.9/site-packages/airflow/example_dags/example_dataset_alias.py
[2025-02-22T23:43:38.453-0500] {processor.py:914} INFO - Processing file /home/rafaelrb/anaconda3/lib/python3.9/site-packages/airflow/example_dags/example_dataset_alias.py for tasks to queue
[2025-02-22T23:43:38.456-0500] {logging_mixin.py:190} INFO - [2025-02-22T23:43:38.456-0500] {dagbag.py:588} INFO - Filling up the DagBag from /home/rafaelrb/anaconda3/lib/python3.9/site-packages/airflow/example_dags/example_dataset_alias.py
[2025-02-22T23:43:38.471-0500] {logging_mixin.py:190} INFO - [2025-02-22T23:43:38.466-0500] {dagbag.py:387} ERROR - Failed to import: /home/rafaelrb/anaconda3/lib/python3.9/site-packages/airflow/example_dags/example_dataset_alias.py
Traceback (most recent call last):
  File "/home/rafaelrb/anaconda3/lib/python3.9/site-packages/airflow/models/dagbag.py", line 383, in parse
    loader.exec_module(new_module)
  File "<frozen importlib._bootstrap_external>", line 850, in exec_module
  File "<frozen importlib._bootstrap>", line 228, in _call_with_frames_removed
  File "/home/rafaelrb/anaconda3/lib/python3.9/site-packages/airflow/example_dags/example_dataset_alias.py", line 53, in <module>
    def produce_dataset_events():
  File "/home/rafaelrb/anaconda3/lib/python3.9/site-packages/airflow/decorators/base.py", line 691, in decorator_factory
    return _TaskDecorator(
TypeError: _TaskDecorator() takes no arguments
[2025-02-22T23:43:38.472-0500] {processor.py:927} WARNING - No viable dags retrieved from /home/rafaelrb/anaconda3/lib/python3.9/site-packages/airflow/example_dags/example_dataset_alias.py
[2025-02-22T23:43:38.514-0500] {processor.py:208} INFO - Processing /home/rafaelrb/anaconda3/lib/python3.9/site-packages/airflow/example_dags/example_dataset_alias.py took 0.073 seconds
[2025-02-22T23:44:47.602-0500] {processor.py:186} INFO - Started process (PID=27168) to work on /home/rafaelrb/anaconda3/lib/python3.9/site-packages/airflow/example_dags/example_dataset_alias.py
[2025-02-22T23:44:47.607-0500] {processor.py:914} INFO - Processing file /home/rafaelrb/anaconda3/lib/python3.9/site-packages/airflow/example_dags/example_dataset_alias.py for tasks to queue
[2025-02-22T23:44:47.610-0500] {logging_mixin.py:190} INFO - [2025-02-22T23:44:47.609-0500] {dagbag.py:588} INFO - Filling up the DagBag from /home/rafaelrb/anaconda3/lib/python3.9/site-packages/airflow/example_dags/example_dataset_alias.py
[2025-02-22T23:44:47.620-0500] {logging_mixin.py:190} INFO - [2025-02-22T23:44:47.617-0500] {dagbag.py:387} ERROR - Failed to import: /home/rafaelrb/anaconda3/lib/python3.9/site-packages/airflow/example_dags/example_dataset_alias.py
Traceback (most recent call last):
  File "/home/rafaelrb/anaconda3/lib/python3.9/site-packages/airflow/models/dagbag.py", line 383, in parse
    loader.exec_module(new_module)
  File "<frozen importlib._bootstrap_external>", line 850, in exec_module
  File "<frozen importlib._bootstrap>", line 228, in _call_with_frames_removed
  File "/home/rafaelrb/anaconda3/lib/python3.9/site-packages/airflow/example_dags/example_dataset_alias.py", line 53, in <module>
    def produce_dataset_events():
  File "/home/rafaelrb/anaconda3/lib/python3.9/site-packages/airflow/decorators/base.py", line 691, in decorator_factory
    return _TaskDecorator(
TypeError: _TaskDecorator() takes no arguments
[2025-02-22T23:44:47.621-0500] {processor.py:927} WARNING - No viable dags retrieved from /home/rafaelrb/anaconda3/lib/python3.9/site-packages/airflow/example_dags/example_dataset_alias.py
[2025-02-22T23:44:47.661-0500] {processor.py:208} INFO - Processing /home/rafaelrb/anaconda3/lib/python3.9/site-packages/airflow/example_dags/example_dataset_alias.py took 0.068 seconds
[2025-02-22T23:49:19.392-0500] {processor.py:186} INFO - Started process (PID=27774) to work on /home/rafaelrb/anaconda3/lib/python3.9/site-packages/airflow/example_dags/example_dataset_alias.py
[2025-02-22T23:49:19.397-0500] {processor.py:914} INFO - Processing file /home/rafaelrb/anaconda3/lib/python3.9/site-packages/airflow/example_dags/example_dataset_alias.py for tasks to queue
[2025-02-22T23:49:19.401-0500] {logging_mixin.py:190} INFO - [2025-02-22T23:49:19.400-0500] {dagbag.py:588} INFO - Filling up the DagBag from /home/rafaelrb/anaconda3/lib/python3.9/site-packages/airflow/example_dags/example_dataset_alias.py
[2025-02-22T23:49:19.412-0500] {logging_mixin.py:190} INFO - [2025-02-22T23:49:19.409-0500] {dagbag.py:387} ERROR - Failed to import: /home/rafaelrb/anaconda3/lib/python3.9/site-packages/airflow/example_dags/example_dataset_alias.py
Traceback (most recent call last):
  File "/home/rafaelrb/anaconda3/lib/python3.9/site-packages/airflow/models/dagbag.py", line 383, in parse
    loader.exec_module(new_module)
  File "<frozen importlib._bootstrap_external>", line 850, in exec_module
  File "<frozen importlib._bootstrap>", line 228, in _call_with_frames_removed
  File "/home/rafaelrb/anaconda3/lib/python3.9/site-packages/airflow/example_dags/example_dataset_alias.py", line 53, in <module>
    def produce_dataset_events():
  File "/home/rafaelrb/anaconda3/lib/python3.9/site-packages/airflow/decorators/base.py", line 691, in decorator_factory
    return _TaskDecorator(
TypeError: _TaskDecorator() takes no arguments
[2025-02-22T23:49:19.413-0500] {processor.py:927} WARNING - No viable dags retrieved from /home/rafaelrb/anaconda3/lib/python3.9/site-packages/airflow/example_dags/example_dataset_alias.py
[2025-02-22T23:49:19.448-0500] {processor.py:208} INFO - Processing /home/rafaelrb/anaconda3/lib/python3.9/site-packages/airflow/example_dags/example_dataset_alias.py took 0.065 seconds
[2025-02-22T23:50:22.063-0500] {processor.py:186} INFO - Started process (PID=28193) to work on /home/rafaelrb/anaconda3/lib/python3.9/site-packages/airflow/example_dags/example_dataset_alias.py
[2025-02-22T23:50:22.069-0500] {processor.py:914} INFO - Processing file /home/rafaelrb/anaconda3/lib/python3.9/site-packages/airflow/example_dags/example_dataset_alias.py for tasks to queue
[2025-02-22T23:50:22.072-0500] {logging_mixin.py:190} INFO - [2025-02-22T23:50:22.071-0500] {dagbag.py:588} INFO - Filling up the DagBag from /home/rafaelrb/anaconda3/lib/python3.9/site-packages/airflow/example_dags/example_dataset_alias.py
[2025-02-22T23:50:22.080-0500] {logging_mixin.py:190} INFO - [2025-02-22T23:50:22.079-0500] {dagbag.py:387} ERROR - Failed to import: /home/rafaelrb/anaconda3/lib/python3.9/site-packages/airflow/example_dags/example_dataset_alias.py
Traceback (most recent call last):
  File "/home/rafaelrb/anaconda3/lib/python3.9/site-packages/airflow/models/dagbag.py", line 383, in parse
    loader.exec_module(new_module)
  File "<frozen importlib._bootstrap_external>", line 850, in exec_module
  File "<frozen importlib._bootstrap>", line 228, in _call_with_frames_removed
  File "/home/rafaelrb/anaconda3/lib/python3.9/site-packages/airflow/example_dags/example_dataset_alias.py", line 53, in <module>
    def produce_dataset_events():
  File "/home/rafaelrb/anaconda3/lib/python3.9/site-packages/airflow/decorators/base.py", line 691, in decorator_factory
    return _TaskDecorator(
TypeError: _TaskDecorator() takes no arguments
[2025-02-22T23:50:22.080-0500] {processor.py:927} WARNING - No viable dags retrieved from /home/rafaelrb/anaconda3/lib/python3.9/site-packages/airflow/example_dags/example_dataset_alias.py
[2025-02-22T23:50:22.116-0500] {processor.py:208} INFO - Processing /home/rafaelrb/anaconda3/lib/python3.9/site-packages/airflow/example_dags/example_dataset_alias.py took 0.062 seconds
[2025-02-22T23:51:19.336-0500] {processor.py:186} INFO - Started process (PID=28628) to work on /home/rafaelrb/anaconda3/lib/python3.9/site-packages/airflow/example_dags/example_dataset_alias.py
[2025-02-22T23:51:19.337-0500] {processor.py:914} INFO - Processing file /home/rafaelrb/anaconda3/lib/python3.9/site-packages/airflow/example_dags/example_dataset_alias.py for tasks to queue
[2025-02-22T23:51:19.340-0500] {logging_mixin.py:190} INFO - [2025-02-22T23:51:19.340-0500] {dagbag.py:588} INFO - Filling up the DagBag from /home/rafaelrb/anaconda3/lib/python3.9/site-packages/airflow/example_dags/example_dataset_alias.py
[2025-02-22T23:51:19.360-0500] {logging_mixin.py:190} INFO - [2025-02-22T23:51:19.354-0500] {dagbag.py:387} ERROR - Failed to import: /home/rafaelrb/anaconda3/lib/python3.9/site-packages/airflow/example_dags/example_dataset_alias.py
Traceback (most recent call last):
  File "/home/rafaelrb/anaconda3/lib/python3.9/site-packages/airflow/models/dagbag.py", line 383, in parse
    loader.exec_module(new_module)
  File "<frozen importlib._bootstrap_external>", line 850, in exec_module
  File "<frozen importlib._bootstrap>", line 228, in _call_with_frames_removed
  File "/home/rafaelrb/anaconda3/lib/python3.9/site-packages/airflow/example_dags/example_dataset_alias.py", line 53, in <module>
    def produce_dataset_events():
  File "/home/rafaelrb/anaconda3/lib/python3.9/site-packages/airflow/decorators/base.py", line 691, in decorator_factory
    return _TaskDecorator(
TypeError: _TaskDecorator() takes no arguments
[2025-02-22T23:51:19.361-0500] {processor.py:927} WARNING - No viable dags retrieved from /home/rafaelrb/anaconda3/lib/python3.9/site-packages/airflow/example_dags/example_dataset_alias.py
[2025-02-22T23:51:19.391-0500] {processor.py:208} INFO - Processing /home/rafaelrb/anaconda3/lib/python3.9/site-packages/airflow/example_dags/example_dataset_alias.py took 0.067 seconds
[2025-02-22T23:52:17.843-0500] {processor.py:186} INFO - Started process (PID=29028) to work on /home/rafaelrb/anaconda3/lib/python3.9/site-packages/airflow/example_dags/example_dataset_alias.py
[2025-02-22T23:52:17.845-0500] {processor.py:914} INFO - Processing file /home/rafaelrb/anaconda3/lib/python3.9/site-packages/airflow/example_dags/example_dataset_alias.py for tasks to queue
[2025-02-22T23:52:17.848-0500] {logging_mixin.py:190} INFO - [2025-02-22T23:52:17.847-0500] {dagbag.py:588} INFO - Filling up the DagBag from /home/rafaelrb/anaconda3/lib/python3.9/site-packages/airflow/example_dags/example_dataset_alias.py
[2025-02-22T23:52:17.857-0500] {logging_mixin.py:190} INFO - [2025-02-22T23:52:17.856-0500] {dagbag.py:387} ERROR - Failed to import: /home/rafaelrb/anaconda3/lib/python3.9/site-packages/airflow/example_dags/example_dataset_alias.py
Traceback (most recent call last):
  File "/home/rafaelrb/anaconda3/lib/python3.9/site-packages/airflow/models/dagbag.py", line 383, in parse
    loader.exec_module(new_module)
  File "<frozen importlib._bootstrap_external>", line 850, in exec_module
  File "<frozen importlib._bootstrap>", line 228, in _call_with_frames_removed
  File "/home/rafaelrb/anaconda3/lib/python3.9/site-packages/airflow/example_dags/example_dataset_alias.py", line 53, in <module>
    def produce_dataset_events():
  File "/home/rafaelrb/anaconda3/lib/python3.9/site-packages/airflow/decorators/base.py", line 691, in decorator_factory
    return _TaskDecorator(
TypeError: _TaskDecorator() takes no arguments
[2025-02-22T23:52:17.857-0500] {processor.py:927} WARNING - No viable dags retrieved from /home/rafaelrb/anaconda3/lib/python3.9/site-packages/airflow/example_dags/example_dataset_alias.py
[2025-02-22T23:52:17.888-0500] {processor.py:208} INFO - Processing /home/rafaelrb/anaconda3/lib/python3.9/site-packages/airflow/example_dags/example_dataset_alias.py took 0.053 seconds
[2025-02-22T23:53:54.744-0500] {processor.py:186} INFO - Started process (PID=29711) to work on /home/rafaelrb/anaconda3/lib/python3.9/site-packages/airflow/example_dags/example_dataset_alias.py
[2025-02-22T23:53:54.745-0500] {processor.py:914} INFO - Processing file /home/rafaelrb/anaconda3/lib/python3.9/site-packages/airflow/example_dags/example_dataset_alias.py for tasks to queue
[2025-02-22T23:53:54.749-0500] {logging_mixin.py:190} INFO - [2025-02-22T23:53:54.748-0500] {dagbag.py:588} INFO - Filling up the DagBag from /home/rafaelrb/anaconda3/lib/python3.9/site-packages/airflow/example_dags/example_dataset_alias.py
[2025-02-22T23:53:54.759-0500] {logging_mixin.py:190} INFO - [2025-02-22T23:53:54.758-0500] {dagbag.py:387} ERROR - Failed to import: /home/rafaelrb/anaconda3/lib/python3.9/site-packages/airflow/example_dags/example_dataset_alias.py
Traceback (most recent call last):
  File "/home/rafaelrb/anaconda3/lib/python3.9/site-packages/airflow/models/dagbag.py", line 383, in parse
    loader.exec_module(new_module)
  File "<frozen importlib._bootstrap_external>", line 850, in exec_module
  File "<frozen importlib._bootstrap>", line 228, in _call_with_frames_removed
  File "/home/rafaelrb/anaconda3/lib/python3.9/site-packages/airflow/example_dags/example_dataset_alias.py", line 53, in <module>
    def produce_dataset_events():
  File "/home/rafaelrb/anaconda3/lib/python3.9/site-packages/airflow/decorators/base.py", line 691, in decorator_factory
    return _TaskDecorator(
TypeError: _TaskDecorator() takes no arguments
[2025-02-22T23:53:54.760-0500] {processor.py:927} WARNING - No viable dags retrieved from /home/rafaelrb/anaconda3/lib/python3.9/site-packages/airflow/example_dags/example_dataset_alias.py
[2025-02-22T23:53:54.795-0500] {processor.py:208} INFO - Processing /home/rafaelrb/anaconda3/lib/python3.9/site-packages/airflow/example_dags/example_dataset_alias.py took 0.060 seconds
[2025-02-22T23:54:57.053-0500] {processor.py:186} INFO - Started process (PID=30161) to work on /home/rafaelrb/anaconda3/lib/python3.9/site-packages/airflow/example_dags/example_dataset_alias.py
[2025-02-22T23:54:57.056-0500] {processor.py:914} INFO - Processing file /home/rafaelrb/anaconda3/lib/python3.9/site-packages/airflow/example_dags/example_dataset_alias.py for tasks to queue
[2025-02-22T23:54:57.060-0500] {logging_mixin.py:190} INFO - [2025-02-22T23:54:57.059-0500] {dagbag.py:588} INFO - Filling up the DagBag from /home/rafaelrb/anaconda3/lib/python3.9/site-packages/airflow/example_dags/example_dataset_alias.py
[2025-02-22T23:54:57.073-0500] {logging_mixin.py:190} INFO - [2025-02-22T23:54:57.069-0500] {dagbag.py:387} ERROR - Failed to import: /home/rafaelrb/anaconda3/lib/python3.9/site-packages/airflow/example_dags/example_dataset_alias.py
Traceback (most recent call last):
  File "/home/rafaelrb/anaconda3/lib/python3.9/site-packages/airflow/models/dagbag.py", line 383, in parse
    loader.exec_module(new_module)
  File "<frozen importlib._bootstrap_external>", line 850, in exec_module
  File "<frozen importlib._bootstrap>", line 228, in _call_with_frames_removed
  File "/home/rafaelrb/anaconda3/lib/python3.9/site-packages/airflow/example_dags/example_dataset_alias.py", line 53, in <module>
    def produce_dataset_events():
  File "/home/rafaelrb/anaconda3/lib/python3.9/site-packages/airflow/decorators/base.py", line 691, in decorator_factory
    return _TaskDecorator(
TypeError: _TaskDecorator() takes no arguments
[2025-02-22T23:54:57.074-0500] {processor.py:927} WARNING - No viable dags retrieved from /home/rafaelrb/anaconda3/lib/python3.9/site-packages/airflow/example_dags/example_dataset_alias.py
[2025-02-22T23:54:57.117-0500] {processor.py:208} INFO - Processing /home/rafaelrb/anaconda3/lib/python3.9/site-packages/airflow/example_dags/example_dataset_alias.py took 0.073 seconds
[2025-02-22T23:58:11.789-0500] {processor.py:186} INFO - Started process (PID=30699) to work on /home/rafaelrb/anaconda3/lib/python3.9/site-packages/airflow/example_dags/example_dataset_alias.py
[2025-02-22T23:58:11.791-0500] {processor.py:914} INFO - Processing file /home/rafaelrb/anaconda3/lib/python3.9/site-packages/airflow/example_dags/example_dataset_alias.py for tasks to queue
[2025-02-22T23:58:11.794-0500] {logging_mixin.py:190} INFO - [2025-02-22T23:58:11.793-0500] {dagbag.py:588} INFO - Filling up the DagBag from /home/rafaelrb/anaconda3/lib/python3.9/site-packages/airflow/example_dags/example_dataset_alias.py
[2025-02-22T23:58:11.806-0500] {logging_mixin.py:190} INFO - [2025-02-22T23:58:11.801-0500] {dagbag.py:387} ERROR - Failed to import: /home/rafaelrb/anaconda3/lib/python3.9/site-packages/airflow/example_dags/example_dataset_alias.py
Traceback (most recent call last):
  File "/home/rafaelrb/anaconda3/lib/python3.9/site-packages/airflow/models/dagbag.py", line 383, in parse
    loader.exec_module(new_module)
  File "<frozen importlib._bootstrap_external>", line 850, in exec_module
  File "<frozen importlib._bootstrap>", line 228, in _call_with_frames_removed
  File "/home/rafaelrb/anaconda3/lib/python3.9/site-packages/airflow/example_dags/example_dataset_alias.py", line 53, in <module>
    def produce_dataset_events():
  File "/home/rafaelrb/anaconda3/lib/python3.9/site-packages/airflow/decorators/base.py", line 691, in decorator_factory
    return _TaskDecorator(
TypeError: _TaskDecorator() takes no arguments
[2025-02-22T23:58:11.806-0500] {processor.py:927} WARNING - No viable dags retrieved from /home/rafaelrb/anaconda3/lib/python3.9/site-packages/airflow/example_dags/example_dataset_alias.py
[2025-02-22T23:58:11.840-0500] {processor.py:208} INFO - Processing /home/rafaelrb/anaconda3/lib/python3.9/site-packages/airflow/example_dags/example_dataset_alias.py took 0.060 seconds
[2025-02-22T23:59:16.583-0500] {processor.py:186} INFO - Started process (PID=31129) to work on /home/rafaelrb/anaconda3/lib/python3.9/site-packages/airflow/example_dags/example_dataset_alias.py
[2025-02-22T23:59:16.585-0500] {processor.py:914} INFO - Processing file /home/rafaelrb/anaconda3/lib/python3.9/site-packages/airflow/example_dags/example_dataset_alias.py for tasks to queue
[2025-02-22T23:59:16.588-0500] {logging_mixin.py:190} INFO - [2025-02-22T23:59:16.588-0500] {dagbag.py:588} INFO - Filling up the DagBag from /home/rafaelrb/anaconda3/lib/python3.9/site-packages/airflow/example_dags/example_dataset_alias.py
[2025-02-22T23:59:16.597-0500] {logging_mixin.py:190} INFO - [2025-02-22T23:59:16.596-0500] {dagbag.py:387} ERROR - Failed to import: /home/rafaelrb/anaconda3/lib/python3.9/site-packages/airflow/example_dags/example_dataset_alias.py
Traceback (most recent call last):
  File "/home/rafaelrb/anaconda3/lib/python3.9/site-packages/airflow/models/dagbag.py", line 383, in parse
    loader.exec_module(new_module)
  File "<frozen importlib._bootstrap_external>", line 850, in exec_module
  File "<frozen importlib._bootstrap>", line 228, in _call_with_frames_removed
  File "/home/rafaelrb/anaconda3/lib/python3.9/site-packages/airflow/example_dags/example_dataset_alias.py", line 53, in <module>
    def produce_dataset_events():
  File "/home/rafaelrb/anaconda3/lib/python3.9/site-packages/airflow/decorators/base.py", line 691, in decorator_factory
    return _TaskDecorator(
TypeError: _TaskDecorator() takes no arguments
[2025-02-22T23:59:16.598-0500] {processor.py:927} WARNING - No viable dags retrieved from /home/rafaelrb/anaconda3/lib/python3.9/site-packages/airflow/example_dags/example_dataset_alias.py
[2025-02-22T23:59:16.625-0500] {processor.py:208} INFO - Processing /home/rafaelrb/anaconda3/lib/python3.9/site-packages/airflow/example_dags/example_dataset_alias.py took 0.053 seconds
[2025-02-23T00:00:39.768-0500] {processor.py:186} INFO - Started process (PID=31691) to work on /home/rafaelrb/anaconda3/lib/python3.9/site-packages/airflow/example_dags/example_dataset_alias.py
[2025-02-23T00:00:39.771-0500] {processor.py:914} INFO - Processing file /home/rafaelrb/anaconda3/lib/python3.9/site-packages/airflow/example_dags/example_dataset_alias.py for tasks to queue
[2025-02-23T00:00:39.775-0500] {logging_mixin.py:190} INFO - [2025-02-23T00:00:39.774-0500] {dagbag.py:588} INFO - Filling up the DagBag from /home/rafaelrb/anaconda3/lib/python3.9/site-packages/airflow/example_dags/example_dataset_alias.py
[2025-02-23T00:00:39.786-0500] {logging_mixin.py:190} INFO - [2025-02-23T00:00:39.783-0500] {dagbag.py:387} ERROR - Failed to import: /home/rafaelrb/anaconda3/lib/python3.9/site-packages/airflow/example_dags/example_dataset_alias.py
Traceback (most recent call last):
  File "/home/rafaelrb/anaconda3/lib/python3.9/site-packages/airflow/models/dagbag.py", line 383, in parse
    loader.exec_module(new_module)
  File "<frozen importlib._bootstrap_external>", line 850, in exec_module
  File "<frozen importlib._bootstrap>", line 228, in _call_with_frames_removed
  File "/home/rafaelrb/anaconda3/lib/python3.9/site-packages/airflow/example_dags/example_dataset_alias.py", line 53, in <module>
    def produce_dataset_events():
  File "/home/rafaelrb/anaconda3/lib/python3.9/site-packages/airflow/decorators/base.py", line 691, in decorator_factory
    return _TaskDecorator(
TypeError: _TaskDecorator() takes no arguments
[2025-02-23T00:00:39.786-0500] {processor.py:927} WARNING - No viable dags retrieved from /home/rafaelrb/anaconda3/lib/python3.9/site-packages/airflow/example_dags/example_dataset_alias.py
[2025-02-23T00:00:39.822-0500] {processor.py:208} INFO - Processing /home/rafaelrb/anaconda3/lib/python3.9/site-packages/airflow/example_dags/example_dataset_alias.py took 0.068 seconds
[2025-02-23T00:01:41.555-0500] {processor.py:186} INFO - Started process (PID=32134) to work on /home/rafaelrb/anaconda3/lib/python3.9/site-packages/airflow/example_dags/example_dataset_alias.py
[2025-02-23T00:01:41.558-0500] {processor.py:914} INFO - Processing file /home/rafaelrb/anaconda3/lib/python3.9/site-packages/airflow/example_dags/example_dataset_alias.py for tasks to queue
[2025-02-23T00:01:41.561-0500] {logging_mixin.py:190} INFO - [2025-02-23T00:01:41.560-0500] {dagbag.py:588} INFO - Filling up the DagBag from /home/rafaelrb/anaconda3/lib/python3.9/site-packages/airflow/example_dags/example_dataset_alias.py
[2025-02-23T00:01:41.569-0500] {logging_mixin.py:190} INFO - [2025-02-23T00:01:41.567-0500] {dagbag.py:387} ERROR - Failed to import: /home/rafaelrb/anaconda3/lib/python3.9/site-packages/airflow/example_dags/example_dataset_alias.py
Traceback (most recent call last):
  File "/home/rafaelrb/anaconda3/lib/python3.9/site-packages/airflow/models/dagbag.py", line 383, in parse
    loader.exec_module(new_module)
  File "<frozen importlib._bootstrap_external>", line 850, in exec_module
  File "<frozen importlib._bootstrap>", line 228, in _call_with_frames_removed
  File "/home/rafaelrb/anaconda3/lib/python3.9/site-packages/airflow/example_dags/example_dataset_alias.py", line 53, in <module>
    def produce_dataset_events():
  File "/home/rafaelrb/anaconda3/lib/python3.9/site-packages/airflow/decorators/base.py", line 691, in decorator_factory
    return _TaskDecorator(
TypeError: _TaskDecorator() takes no arguments
[2025-02-23T00:01:41.569-0500] {processor.py:927} WARNING - No viable dags retrieved from /home/rafaelrb/anaconda3/lib/python3.9/site-packages/airflow/example_dags/example_dataset_alias.py
[2025-02-23T00:01:41.600-0500] {processor.py:208} INFO - Processing /home/rafaelrb/anaconda3/lib/python3.9/site-packages/airflow/example_dags/example_dataset_alias.py took 0.054 seconds
[2025-02-23T00:11:20.053-0500] {processor.py:186} INFO - Started process (PID=34423) to work on /home/rafaelrb/anaconda3/lib/python3.9/site-packages/airflow/example_dags/example_dataset_alias.py
[2025-02-23T00:11:20.060-0500] {processor.py:914} INFO - Processing file /home/rafaelrb/anaconda3/lib/python3.9/site-packages/airflow/example_dags/example_dataset_alias.py for tasks to queue
[2025-02-23T00:11:20.063-0500] {logging_mixin.py:190} INFO - [2025-02-23T00:11:20.063-0500] {dagbag.py:588} INFO - Filling up the DagBag from /home/rafaelrb/anaconda3/lib/python3.9/site-packages/airflow/example_dags/example_dataset_alias.py
[2025-02-23T00:11:20.071-0500] {logging_mixin.py:190} INFO - [2025-02-23T00:11:20.070-0500] {dagbag.py:387} ERROR - Failed to import: /home/rafaelrb/anaconda3/lib/python3.9/site-packages/airflow/example_dags/example_dataset_alias.py
Traceback (most recent call last):
  File "/home/rafaelrb/anaconda3/lib/python3.9/site-packages/airflow/models/dagbag.py", line 383, in parse
    loader.exec_module(new_module)
  File "<frozen importlib._bootstrap_external>", line 850, in exec_module
  File "<frozen importlib._bootstrap>", line 228, in _call_with_frames_removed
  File "/home/rafaelrb/anaconda3/lib/python3.9/site-packages/airflow/example_dags/example_dataset_alias.py", line 53, in <module>
    def produce_dataset_events():
  File "/home/rafaelrb/anaconda3/lib/python3.9/site-packages/airflow/decorators/base.py", line 691, in decorator_factory
    return _TaskDecorator(
TypeError: _TaskDecorator() takes no arguments
[2025-02-23T00:11:20.071-0500] {processor.py:927} WARNING - No viable dags retrieved from /home/rafaelrb/anaconda3/lib/python3.9/site-packages/airflow/example_dags/example_dataset_alias.py
[2025-02-23T00:11:20.100-0500] {processor.py:208} INFO - Processing /home/rafaelrb/anaconda3/lib/python3.9/site-packages/airflow/example_dags/example_dataset_alias.py took 0.055 seconds
[2025-02-23T00:12:20.918-0500] {processor.py:186} INFO - Started process (PID=34515) to work on /home/rafaelrb/anaconda3/lib/python3.9/site-packages/airflow/example_dags/example_dataset_alias.py
[2025-02-23T00:12:20.920-0500] {processor.py:914} INFO - Processing file /home/rafaelrb/anaconda3/lib/python3.9/site-packages/airflow/example_dags/example_dataset_alias.py for tasks to queue
[2025-02-23T00:12:20.923-0500] {logging_mixin.py:190} INFO - [2025-02-23T00:12:20.923-0500] {dagbag.py:588} INFO - Filling up the DagBag from /home/rafaelrb/anaconda3/lib/python3.9/site-packages/airflow/example_dags/example_dataset_alias.py
[2025-02-23T00:12:20.933-0500] {logging_mixin.py:190} INFO - [2025-02-23T00:12:20.931-0500] {dagbag.py:387} ERROR - Failed to import: /home/rafaelrb/anaconda3/lib/python3.9/site-packages/airflow/example_dags/example_dataset_alias.py
Traceback (most recent call last):
  File "/home/rafaelrb/anaconda3/lib/python3.9/site-packages/airflow/models/dagbag.py", line 383, in parse
    loader.exec_module(new_module)
  File "<frozen importlib._bootstrap_external>", line 850, in exec_module
  File "<frozen importlib._bootstrap>", line 228, in _call_with_frames_removed
  File "/home/rafaelrb/anaconda3/lib/python3.9/site-packages/airflow/example_dags/example_dataset_alias.py", line 53, in <module>
    def produce_dataset_events():
  File "/home/rafaelrb/anaconda3/lib/python3.9/site-packages/airflow/decorators/base.py", line 691, in decorator_factory
    return _TaskDecorator(
TypeError: _TaskDecorator() takes no arguments
[2025-02-23T00:12:20.934-0500] {processor.py:927} WARNING - No viable dags retrieved from /home/rafaelrb/anaconda3/lib/python3.9/site-packages/airflow/example_dags/example_dataset_alias.py
[2025-02-23T00:12:20.973-0500] {processor.py:208} INFO - Processing /home/rafaelrb/anaconda3/lib/python3.9/site-packages/airflow/example_dags/example_dataset_alias.py took 0.069 seconds
[2025-02-23T00:13:34.030-0500] {processor.py:186} INFO - Started process (PID=34620) to work on /home/rafaelrb/anaconda3/lib/python3.9/site-packages/airflow/example_dags/example_dataset_alias.py
[2025-02-23T00:13:34.037-0500] {processor.py:914} INFO - Processing file /home/rafaelrb/anaconda3/lib/python3.9/site-packages/airflow/example_dags/example_dataset_alias.py for tasks to queue
[2025-02-23T00:13:34.040-0500] {logging_mixin.py:190} INFO - [2025-02-23T00:13:34.039-0500] {dagbag.py:588} INFO - Filling up the DagBag from /home/rafaelrb/anaconda3/lib/python3.9/site-packages/airflow/example_dags/example_dataset_alias.py
[2025-02-23T00:13:34.049-0500] {logging_mixin.py:190} INFO - [2025-02-23T00:13:34.048-0500] {dagbag.py:387} ERROR - Failed to import: /home/rafaelrb/anaconda3/lib/python3.9/site-packages/airflow/example_dags/example_dataset_alias.py
Traceback (most recent call last):
  File "/home/rafaelrb/anaconda3/lib/python3.9/site-packages/airflow/models/dagbag.py", line 383, in parse
    loader.exec_module(new_module)
  File "<frozen importlib._bootstrap_external>", line 850, in exec_module
  File "<frozen importlib._bootstrap>", line 228, in _call_with_frames_removed
  File "/home/rafaelrb/anaconda3/lib/python3.9/site-packages/airflow/example_dags/example_dataset_alias.py", line 53, in <module>
    def produce_dataset_events():
  File "/home/rafaelrb/anaconda3/lib/python3.9/site-packages/airflow/decorators/base.py", line 691, in decorator_factory
    return _TaskDecorator(
TypeError: _TaskDecorator() takes no arguments
[2025-02-23T00:13:34.050-0500] {processor.py:927} WARNING - No viable dags retrieved from /home/rafaelrb/anaconda3/lib/python3.9/site-packages/airflow/example_dags/example_dataset_alias.py
[2025-02-23T00:13:34.099-0500] {processor.py:208} INFO - Processing /home/rafaelrb/anaconda3/lib/python3.9/site-packages/airflow/example_dags/example_dataset_alias.py took 0.079 seconds
[2025-02-23T00:14:31.785-0500] {processor.py:186} INFO - Started process (PID=34697) to work on /home/rafaelrb/anaconda3/lib/python3.9/site-packages/airflow/example_dags/example_dataset_alias.py
[2025-02-23T00:14:31.791-0500] {processor.py:914} INFO - Processing file /home/rafaelrb/anaconda3/lib/python3.9/site-packages/airflow/example_dags/example_dataset_alias.py for tasks to queue
[2025-02-23T00:14:31.803-0500] {logging_mixin.py:190} INFO - [2025-02-23T00:14:31.803-0500] {dagbag.py:588} INFO - Filling up the DagBag from /home/rafaelrb/anaconda3/lib/python3.9/site-packages/airflow/example_dags/example_dataset_alias.py
[2025-02-23T00:14:31.828-0500] {logging_mixin.py:190} INFO - [2025-02-23T00:14:31.826-0500] {dagbag.py:387} ERROR - Failed to import: /home/rafaelrb/anaconda3/lib/python3.9/site-packages/airflow/example_dags/example_dataset_alias.py
Traceback (most recent call last):
  File "/home/rafaelrb/anaconda3/lib/python3.9/site-packages/airflow/models/dagbag.py", line 383, in parse
    loader.exec_module(new_module)
  File "<frozen importlib._bootstrap_external>", line 850, in exec_module
  File "<frozen importlib._bootstrap>", line 228, in _call_with_frames_removed
  File "/home/rafaelrb/anaconda3/lib/python3.9/site-packages/airflow/example_dags/example_dataset_alias.py", line 53, in <module>
    def produce_dataset_events():
  File "/home/rafaelrb/anaconda3/lib/python3.9/site-packages/airflow/decorators/base.py", line 691, in decorator_factory
    return _TaskDecorator(
TypeError: _TaskDecorator() takes no arguments
[2025-02-23T00:14:31.829-0500] {processor.py:927} WARNING - No viable dags retrieved from /home/rafaelrb/anaconda3/lib/python3.9/site-packages/airflow/example_dags/example_dataset_alias.py
[2025-02-23T00:14:31.873-0500] {processor.py:208} INFO - Processing /home/rafaelrb/anaconda3/lib/python3.9/site-packages/airflow/example_dags/example_dataset_alias.py took 0.106 seconds
[2025-02-23T00:15:42.095-0500] {processor.py:186} INFO - Started process (PID=34793) to work on /home/rafaelrb/anaconda3/lib/python3.9/site-packages/airflow/example_dags/example_dataset_alias.py
[2025-02-23T00:15:42.097-0500] {processor.py:914} INFO - Processing file /home/rafaelrb/anaconda3/lib/python3.9/site-packages/airflow/example_dags/example_dataset_alias.py for tasks to queue
[2025-02-23T00:15:42.099-0500] {logging_mixin.py:190} INFO - [2025-02-23T00:15:42.099-0500] {dagbag.py:588} INFO - Filling up the DagBag from /home/rafaelrb/anaconda3/lib/python3.9/site-packages/airflow/example_dags/example_dataset_alias.py
[2025-02-23T00:15:42.111-0500] {logging_mixin.py:190} INFO - [2025-02-23T00:15:42.109-0500] {dagbag.py:387} ERROR - Failed to import: /home/rafaelrb/anaconda3/lib/python3.9/site-packages/airflow/example_dags/example_dataset_alias.py
Traceback (most recent call last):
  File "/home/rafaelrb/anaconda3/lib/python3.9/site-packages/airflow/models/dagbag.py", line 383, in parse
    loader.exec_module(new_module)
  File "<frozen importlib._bootstrap_external>", line 850, in exec_module
  File "<frozen importlib._bootstrap>", line 228, in _call_with_frames_removed
  File "/home/rafaelrb/anaconda3/lib/python3.9/site-packages/airflow/example_dags/example_dataset_alias.py", line 53, in <module>
    def produce_dataset_events():
  File "/home/rafaelrb/anaconda3/lib/python3.9/site-packages/airflow/decorators/base.py", line 691, in decorator_factory
    return _TaskDecorator(
TypeError: _TaskDecorator() takes no arguments
[2025-02-23T00:15:42.112-0500] {processor.py:927} WARNING - No viable dags retrieved from /home/rafaelrb/anaconda3/lib/python3.9/site-packages/airflow/example_dags/example_dataset_alias.py
[2025-02-23T00:15:42.147-0500] {processor.py:208} INFO - Processing /home/rafaelrb/anaconda3/lib/python3.9/site-packages/airflow/example_dags/example_dataset_alias.py took 0.063 seconds
[2025-02-23T00:16:43.535-0500] {processor.py:186} INFO - Started process (PID=34891) to work on /home/rafaelrb/anaconda3/lib/python3.9/site-packages/airflow/example_dags/example_dataset_alias.py
[2025-02-23T00:16:43.536-0500] {processor.py:914} INFO - Processing file /home/rafaelrb/anaconda3/lib/python3.9/site-packages/airflow/example_dags/example_dataset_alias.py for tasks to queue
[2025-02-23T00:16:43.539-0500] {logging_mixin.py:190} INFO - [2025-02-23T00:16:43.538-0500] {dagbag.py:588} INFO - Filling up the DagBag from /home/rafaelrb/anaconda3/lib/python3.9/site-packages/airflow/example_dags/example_dataset_alias.py
[2025-02-23T00:16:43.554-0500] {logging_mixin.py:190} INFO - [2025-02-23T00:16:43.553-0500] {dagbag.py:387} ERROR - Failed to import: /home/rafaelrb/anaconda3/lib/python3.9/site-packages/airflow/example_dags/example_dataset_alias.py
Traceback (most recent call last):
  File "/home/rafaelrb/anaconda3/lib/python3.9/site-packages/airflow/models/dagbag.py", line 383, in parse
    loader.exec_module(new_module)
  File "<frozen importlib._bootstrap_external>", line 850, in exec_module
  File "<frozen importlib._bootstrap>", line 228, in _call_with_frames_removed
  File "/home/rafaelrb/anaconda3/lib/python3.9/site-packages/airflow/example_dags/example_dataset_alias.py", line 53, in <module>
    def produce_dataset_events():
  File "/home/rafaelrb/anaconda3/lib/python3.9/site-packages/airflow/decorators/base.py", line 691, in decorator_factory
    return _TaskDecorator(
TypeError: _TaskDecorator() takes no arguments
[2025-02-23T00:16:43.555-0500] {processor.py:927} WARNING - No viable dags retrieved from /home/rafaelrb/anaconda3/lib/python3.9/site-packages/airflow/example_dags/example_dataset_alias.py
[2025-02-23T00:16:43.654-0500] {processor.py:208} INFO - Processing /home/rafaelrb/anaconda3/lib/python3.9/site-packages/airflow/example_dags/example_dataset_alias.py took 0.131 seconds
[2025-02-23T00:17:45.749-0500] {processor.py:186} INFO - Started process (PID=34972) to work on /home/rafaelrb/anaconda3/lib/python3.9/site-packages/airflow/example_dags/example_dataset_alias.py
[2025-02-23T00:17:45.751-0500] {processor.py:914} INFO - Processing file /home/rafaelrb/anaconda3/lib/python3.9/site-packages/airflow/example_dags/example_dataset_alias.py for tasks to queue
[2025-02-23T00:17:45.754-0500] {logging_mixin.py:190} INFO - [2025-02-23T00:17:45.753-0500] {dagbag.py:588} INFO - Filling up the DagBag from /home/rafaelrb/anaconda3/lib/python3.9/site-packages/airflow/example_dags/example_dataset_alias.py
[2025-02-23T00:17:45.763-0500] {logging_mixin.py:190} INFO - [2025-02-23T00:17:45.761-0500] {dagbag.py:387} ERROR - Failed to import: /home/rafaelrb/anaconda3/lib/python3.9/site-packages/airflow/example_dags/example_dataset_alias.py
Traceback (most recent call last):
  File "/home/rafaelrb/anaconda3/lib/python3.9/site-packages/airflow/models/dagbag.py", line 383, in parse
    loader.exec_module(new_module)
  File "<frozen importlib._bootstrap_external>", line 850, in exec_module
  File "<frozen importlib._bootstrap>", line 228, in _call_with_frames_removed
  File "/home/rafaelrb/anaconda3/lib/python3.9/site-packages/airflow/example_dags/example_dataset_alias.py", line 53, in <module>
    def produce_dataset_events():
  File "/home/rafaelrb/anaconda3/lib/python3.9/site-packages/airflow/decorators/base.py", line 691, in decorator_factory
    return _TaskDecorator(
TypeError: _TaskDecorator() takes no arguments
[2025-02-23T00:17:45.763-0500] {processor.py:927} WARNING - No viable dags retrieved from /home/rafaelrb/anaconda3/lib/python3.9/site-packages/airflow/example_dags/example_dataset_alias.py
[2025-02-23T00:17:45.794-0500] {processor.py:208} INFO - Processing /home/rafaelrb/anaconda3/lib/python3.9/site-packages/airflow/example_dags/example_dataset_alias.py took 0.055 seconds
[2025-02-23T00:18:46.423-0500] {processor.py:186} INFO - Started process (PID=35038) to work on /home/rafaelrb/anaconda3/lib/python3.9/site-packages/airflow/example_dags/example_dataset_alias.py
[2025-02-23T00:18:46.429-0500] {processor.py:914} INFO - Processing file /home/rafaelrb/anaconda3/lib/python3.9/site-packages/airflow/example_dags/example_dataset_alias.py for tasks to queue
[2025-02-23T00:18:46.432-0500] {logging_mixin.py:190} INFO - [2025-02-23T00:18:46.432-0500] {dagbag.py:588} INFO - Filling up the DagBag from /home/rafaelrb/anaconda3/lib/python3.9/site-packages/airflow/example_dags/example_dataset_alias.py
[2025-02-23T00:18:46.440-0500] {logging_mixin.py:190} INFO - [2025-02-23T00:18:46.439-0500] {dagbag.py:387} ERROR - Failed to import: /home/rafaelrb/anaconda3/lib/python3.9/site-packages/airflow/example_dags/example_dataset_alias.py
Traceback (most recent call last):
  File "/home/rafaelrb/anaconda3/lib/python3.9/site-packages/airflow/models/dagbag.py", line 383, in parse
    loader.exec_module(new_module)
  File "<frozen importlib._bootstrap_external>", line 850, in exec_module
  File "<frozen importlib._bootstrap>", line 228, in _call_with_frames_removed
  File "/home/rafaelrb/anaconda3/lib/python3.9/site-packages/airflow/example_dags/example_dataset_alias.py", line 53, in <module>
    def produce_dataset_events():
  File "/home/rafaelrb/anaconda3/lib/python3.9/site-packages/airflow/decorators/base.py", line 691, in decorator_factory
    return _TaskDecorator(
TypeError: _TaskDecorator() takes no arguments
[2025-02-23T00:18:46.441-0500] {processor.py:927} WARNING - No viable dags retrieved from /home/rafaelrb/anaconda3/lib/python3.9/site-packages/airflow/example_dags/example_dataset_alias.py
[2025-02-23T00:18:46.480-0500] {processor.py:208} INFO - Processing /home/rafaelrb/anaconda3/lib/python3.9/site-packages/airflow/example_dags/example_dataset_alias.py took 0.066 seconds
[2025-02-23T00:22:02.040-0500] {processor.py:186} INFO - Started process (PID=35184) to work on /home/rafaelrb/anaconda3/lib/python3.9/site-packages/airflow/example_dags/example_dataset_alias.py
[2025-02-23T00:22:02.045-0500] {processor.py:914} INFO - Processing file /home/rafaelrb/anaconda3/lib/python3.9/site-packages/airflow/example_dags/example_dataset_alias.py for tasks to queue
[2025-02-23T00:22:02.050-0500] {logging_mixin.py:190} INFO - [2025-02-23T00:22:02.050-0500] {dagbag.py:588} INFO - Filling up the DagBag from /home/rafaelrb/anaconda3/lib/python3.9/site-packages/airflow/example_dags/example_dataset_alias.py
[2025-02-23T00:22:02.058-0500] {logging_mixin.py:190} INFO - [2025-02-23T00:22:02.057-0500] {dagbag.py:387} ERROR - Failed to import: /home/rafaelrb/anaconda3/lib/python3.9/site-packages/airflow/example_dags/example_dataset_alias.py
Traceback (most recent call last):
  File "/home/rafaelrb/anaconda3/lib/python3.9/site-packages/airflow/models/dagbag.py", line 383, in parse
    loader.exec_module(new_module)
  File "<frozen importlib._bootstrap_external>", line 850, in exec_module
  File "<frozen importlib._bootstrap>", line 228, in _call_with_frames_removed
  File "/home/rafaelrb/anaconda3/lib/python3.9/site-packages/airflow/example_dags/example_dataset_alias.py", line 53, in <module>
    def produce_dataset_events():
  File "/home/rafaelrb/anaconda3/lib/python3.9/site-packages/airflow/decorators/base.py", line 691, in decorator_factory
    return _TaskDecorator(
TypeError: _TaskDecorator() takes no arguments
[2025-02-23T00:22:02.058-0500] {processor.py:927} WARNING - No viable dags retrieved from /home/rafaelrb/anaconda3/lib/python3.9/site-packages/airflow/example_dags/example_dataset_alias.py
[2025-02-23T00:22:02.100-0500] {processor.py:208} INFO - Processing /home/rafaelrb/anaconda3/lib/python3.9/site-packages/airflow/example_dags/example_dataset_alias.py took 0.071 seconds
[2025-02-23T00:23:02.390-0500] {processor.py:186} INFO - Started process (PID=35250) to work on /home/rafaelrb/anaconda3/lib/python3.9/site-packages/airflow/example_dags/example_dataset_alias.py
[2025-02-23T00:23:02.392-0500] {processor.py:914} INFO - Processing file /home/rafaelrb/anaconda3/lib/python3.9/site-packages/airflow/example_dags/example_dataset_alias.py for tasks to queue
[2025-02-23T00:23:02.395-0500] {logging_mixin.py:190} INFO - [2025-02-23T00:23:02.394-0500] {dagbag.py:588} INFO - Filling up the DagBag from /home/rafaelrb/anaconda3/lib/python3.9/site-packages/airflow/example_dags/example_dataset_alias.py
[2025-02-23T00:23:02.402-0500] {logging_mixin.py:190} INFO - [2025-02-23T00:23:02.401-0500] {dagbag.py:387} ERROR - Failed to import: /home/rafaelrb/anaconda3/lib/python3.9/site-packages/airflow/example_dags/example_dataset_alias.py
Traceback (most recent call last):
  File "/home/rafaelrb/anaconda3/lib/python3.9/site-packages/airflow/models/dagbag.py", line 383, in parse
    loader.exec_module(new_module)
  File "<frozen importlib._bootstrap_external>", line 850, in exec_module
  File "<frozen importlib._bootstrap>", line 228, in _call_with_frames_removed
  File "/home/rafaelrb/anaconda3/lib/python3.9/site-packages/airflow/example_dags/example_dataset_alias.py", line 53, in <module>
    def produce_dataset_events():
  File "/home/rafaelrb/anaconda3/lib/python3.9/site-packages/airflow/decorators/base.py", line 691, in decorator_factory
    return _TaskDecorator(
TypeError: _TaskDecorator() takes no arguments
[2025-02-23T00:23:02.403-0500] {processor.py:927} WARNING - No viable dags retrieved from /home/rafaelrb/anaconda3/lib/python3.9/site-packages/airflow/example_dags/example_dataset_alias.py
[2025-02-23T00:23:02.434-0500] {processor.py:208} INFO - Processing /home/rafaelrb/anaconda3/lib/python3.9/site-packages/airflow/example_dags/example_dataset_alias.py took 0.051 seconds
[2025-02-23T00:24:04.632-0500] {processor.py:186} INFO - Started process (PID=35324) to work on /home/rafaelrb/anaconda3/lib/python3.9/site-packages/airflow/example_dags/example_dataset_alias.py
[2025-02-23T00:24:04.633-0500] {processor.py:914} INFO - Processing file /home/rafaelrb/anaconda3/lib/python3.9/site-packages/airflow/example_dags/example_dataset_alias.py for tasks to queue
[2025-02-23T00:24:04.636-0500] {logging_mixin.py:190} INFO - [2025-02-23T00:24:04.636-0500] {dagbag.py:588} INFO - Filling up the DagBag from /home/rafaelrb/anaconda3/lib/python3.9/site-packages/airflow/example_dags/example_dataset_alias.py
[2025-02-23T00:24:04.644-0500] {logging_mixin.py:190} INFO - [2025-02-23T00:24:04.643-0500] {dagbag.py:387} ERROR - Failed to import: /home/rafaelrb/anaconda3/lib/python3.9/site-packages/airflow/example_dags/example_dataset_alias.py
Traceback (most recent call last):
  File "/home/rafaelrb/anaconda3/lib/python3.9/site-packages/airflow/models/dagbag.py", line 383, in parse
    loader.exec_module(new_module)
  File "<frozen importlib._bootstrap_external>", line 850, in exec_module
  File "<frozen importlib._bootstrap>", line 228, in _call_with_frames_removed
  File "/home/rafaelrb/anaconda3/lib/python3.9/site-packages/airflow/example_dags/example_dataset_alias.py", line 53, in <module>
    def produce_dataset_events():
  File "/home/rafaelrb/anaconda3/lib/python3.9/site-packages/airflow/decorators/base.py", line 691, in decorator_factory
    return _TaskDecorator(
TypeError: _TaskDecorator() takes no arguments
[2025-02-23T00:24:04.644-0500] {processor.py:927} WARNING - No viable dags retrieved from /home/rafaelrb/anaconda3/lib/python3.9/site-packages/airflow/example_dags/example_dataset_alias.py
[2025-02-23T00:24:04.679-0500] {processor.py:208} INFO - Processing /home/rafaelrb/anaconda3/lib/python3.9/site-packages/airflow/example_dags/example_dataset_alias.py took 0.056 seconds
[2025-02-23T00:25:06.606-0500] {processor.py:186} INFO - Started process (PID=35392) to work on /home/rafaelrb/anaconda3/lib/python3.9/site-packages/airflow/example_dags/example_dataset_alias.py
[2025-02-23T00:25:06.613-0500] {processor.py:914} INFO - Processing file /home/rafaelrb/anaconda3/lib/python3.9/site-packages/airflow/example_dags/example_dataset_alias.py for tasks to queue
[2025-02-23T00:25:06.616-0500] {logging_mixin.py:190} INFO - [2025-02-23T00:25:06.615-0500] {dagbag.py:588} INFO - Filling up the DagBag from /home/rafaelrb/anaconda3/lib/python3.9/site-packages/airflow/example_dags/example_dataset_alias.py
[2025-02-23T00:25:06.623-0500] {logging_mixin.py:190} INFO - [2025-02-23T00:25:06.622-0500] {dagbag.py:387} ERROR - Failed to import: /home/rafaelrb/anaconda3/lib/python3.9/site-packages/airflow/example_dags/example_dataset_alias.py
Traceback (most recent call last):
  File "/home/rafaelrb/anaconda3/lib/python3.9/site-packages/airflow/models/dagbag.py", line 383, in parse
    loader.exec_module(new_module)
  File "<frozen importlib._bootstrap_external>", line 850, in exec_module
  File "<frozen importlib._bootstrap>", line 228, in _call_with_frames_removed
  File "/home/rafaelrb/anaconda3/lib/python3.9/site-packages/airflow/example_dags/example_dataset_alias.py", line 53, in <module>
    def produce_dataset_events():
  File "/home/rafaelrb/anaconda3/lib/python3.9/site-packages/airflow/decorators/base.py", line 691, in decorator_factory
    return _TaskDecorator(
TypeError: _TaskDecorator() takes no arguments
[2025-02-23T00:25:06.623-0500] {processor.py:927} WARNING - No viable dags retrieved from /home/rafaelrb/anaconda3/lib/python3.9/site-packages/airflow/example_dags/example_dataset_alias.py
[2025-02-23T00:25:06.652-0500] {processor.py:208} INFO - Processing /home/rafaelrb/anaconda3/lib/python3.9/site-packages/airflow/example_dags/example_dataset_alias.py took 0.054 seconds
[2025-02-23T00:26:06.573-0500] {processor.py:186} INFO - Started process (PID=35464) to work on /home/rafaelrb/anaconda3/lib/python3.9/site-packages/airflow/example_dags/example_dataset_alias.py
[2025-02-23T00:26:06.580-0500] {processor.py:914} INFO - Processing file /home/rafaelrb/anaconda3/lib/python3.9/site-packages/airflow/example_dags/example_dataset_alias.py for tasks to queue
[2025-02-23T00:26:06.583-0500] {logging_mixin.py:190} INFO - [2025-02-23T00:26:06.583-0500] {dagbag.py:588} INFO - Filling up the DagBag from /home/rafaelrb/anaconda3/lib/python3.9/site-packages/airflow/example_dags/example_dataset_alias.py
[2025-02-23T00:26:06.593-0500] {logging_mixin.py:190} INFO - [2025-02-23T00:26:06.591-0500] {dagbag.py:387} ERROR - Failed to import: /home/rafaelrb/anaconda3/lib/python3.9/site-packages/airflow/example_dags/example_dataset_alias.py
Traceback (most recent call last):
  File "/home/rafaelrb/anaconda3/lib/python3.9/site-packages/airflow/models/dagbag.py", line 383, in parse
    loader.exec_module(new_module)
  File "<frozen importlib._bootstrap_external>", line 850, in exec_module
  File "<frozen importlib._bootstrap>", line 228, in _call_with_frames_removed
  File "/home/rafaelrb/anaconda3/lib/python3.9/site-packages/airflow/example_dags/example_dataset_alias.py", line 53, in <module>
    def produce_dataset_events():
  File "/home/rafaelrb/anaconda3/lib/python3.9/site-packages/airflow/decorators/base.py", line 691, in decorator_factory
    return _TaskDecorator(
TypeError: _TaskDecorator() takes no arguments
[2025-02-23T00:26:06.595-0500] {processor.py:927} WARNING - No viable dags retrieved from /home/rafaelrb/anaconda3/lib/python3.9/site-packages/airflow/example_dags/example_dataset_alias.py
[2025-02-23T00:26:06.638-0500] {processor.py:208} INFO - Processing /home/rafaelrb/anaconda3/lib/python3.9/site-packages/airflow/example_dags/example_dataset_alias.py took 0.078 seconds
[2025-02-23T02:32:11.829-0500] {processor.py:186} INFO - Started process (PID=76243) to work on /home/rafaelrb/anaconda3/lib/python3.9/site-packages/airflow/example_dags/example_dataset_alias.py
[2025-02-23T02:32:11.836-0500] {processor.py:914} INFO - Processing file /home/rafaelrb/anaconda3/lib/python3.9/site-packages/airflow/example_dags/example_dataset_alias.py for tasks to queue
[2025-02-23T02:32:11.840-0500] {logging_mixin.py:190} INFO - [2025-02-23T02:32:11.840-0500] {dagbag.py:588} INFO - Filling up the DagBag from /home/rafaelrb/anaconda3/lib/python3.9/site-packages/airflow/example_dags/example_dataset_alias.py
[2025-02-23T02:32:11.848-0500] {logging_mixin.py:190} INFO - [2025-02-23T02:32:11.847-0500] {dagbag.py:387} ERROR - Failed to import: /home/rafaelrb/anaconda3/lib/python3.9/site-packages/airflow/example_dags/example_dataset_alias.py
Traceback (most recent call last):
  File "/home/rafaelrb/anaconda3/lib/python3.9/site-packages/airflow/models/dagbag.py", line 383, in parse
    loader.exec_module(new_module)
  File "<frozen importlib._bootstrap_external>", line 850, in exec_module
  File "<frozen importlib._bootstrap>", line 228, in _call_with_frames_removed
  File "/home/rafaelrb/anaconda3/lib/python3.9/site-packages/airflow/example_dags/example_dataset_alias.py", line 53, in <module>
    def produce_dataset_events():
  File "/home/rafaelrb/anaconda3/lib/python3.9/site-packages/airflow/decorators/base.py", line 691, in decorator_factory
    return _TaskDecorator(
TypeError: _TaskDecorator() takes no arguments
[2025-02-23T02:32:11.849-0500] {processor.py:927} WARNING - No viable dags retrieved from /home/rafaelrb/anaconda3/lib/python3.9/site-packages/airflow/example_dags/example_dataset_alias.py
[2025-02-23T02:32:11.886-0500] {processor.py:208} INFO - Processing /home/rafaelrb/anaconda3/lib/python3.9/site-packages/airflow/example_dags/example_dataset_alias.py took 0.068 seconds
[2025-02-23T02:33:25.600-0500] {processor.py:186} INFO - Started process (PID=76696) to work on /home/rafaelrb/anaconda3/lib/python3.9/site-packages/airflow/example_dags/example_dataset_alias.py
[2025-02-23T02:33:25.867-0500] {processor.py:914} INFO - Processing file /home/rafaelrb/anaconda3/lib/python3.9/site-packages/airflow/example_dags/example_dataset_alias.py for tasks to queue
[2025-02-23T02:33:25.873-0500] {logging_mixin.py:190} INFO - [2025-02-23T02:33:25.872-0500] {dagbag.py:588} INFO - Filling up the DagBag from /home/rafaelrb/anaconda3/lib/python3.9/site-packages/airflow/example_dags/example_dataset_alias.py
[2025-02-23T02:33:25.896-0500] {logging_mixin.py:190} INFO - [2025-02-23T02:33:25.894-0500] {dagbag.py:387} ERROR - Failed to import: /home/rafaelrb/anaconda3/lib/python3.9/site-packages/airflow/example_dags/example_dataset_alias.py
Traceback (most recent call last):
  File "/home/rafaelrb/anaconda3/lib/python3.9/site-packages/airflow/models/dagbag.py", line 383, in parse
    loader.exec_module(new_module)
  File "<frozen importlib._bootstrap_external>", line 850, in exec_module
  File "<frozen importlib._bootstrap>", line 228, in _call_with_frames_removed
  File "/home/rafaelrb/anaconda3/lib/python3.9/site-packages/airflow/example_dags/example_dataset_alias.py", line 53, in <module>
    def produce_dataset_events():
  File "/home/rafaelrb/anaconda3/lib/python3.9/site-packages/airflow/decorators/base.py", line 691, in decorator_factory
    return _TaskDecorator(
TypeError: _TaskDecorator() takes no arguments
[2025-02-23T02:33:25.897-0500] {processor.py:927} WARNING - No viable dags retrieved from /home/rafaelrb/anaconda3/lib/python3.9/site-packages/airflow/example_dags/example_dataset_alias.py
[2025-02-23T02:33:25.960-0500] {processor.py:208} INFO - Processing /home/rafaelrb/anaconda3/lib/python3.9/site-packages/airflow/example_dags/example_dataset_alias.py took 0.406 seconds
[2025-02-23T02:34:48.366-0500] {processor.py:186} INFO - Started process (PID=77030) to work on /home/rafaelrb/anaconda3/lib/python3.9/site-packages/airflow/example_dags/example_dataset_alias.py
[2025-02-23T02:34:48.368-0500] {processor.py:914} INFO - Processing file /home/rafaelrb/anaconda3/lib/python3.9/site-packages/airflow/example_dags/example_dataset_alias.py for tasks to queue
[2025-02-23T02:34:48.371-0500] {logging_mixin.py:190} INFO - [2025-02-23T02:34:48.370-0500] {dagbag.py:588} INFO - Filling up the DagBag from /home/rafaelrb/anaconda3/lib/python3.9/site-packages/airflow/example_dags/example_dataset_alias.py
[2025-02-23T02:34:48.380-0500] {logging_mixin.py:190} INFO - [2025-02-23T02:34:48.377-0500] {dagbag.py:387} ERROR - Failed to import: /home/rafaelrb/anaconda3/lib/python3.9/site-packages/airflow/example_dags/example_dataset_alias.py
Traceback (most recent call last):
  File "/home/rafaelrb/anaconda3/lib/python3.9/site-packages/airflow/models/dagbag.py", line 383, in parse
    loader.exec_module(new_module)
  File "<frozen importlib._bootstrap_external>", line 850, in exec_module
  File "<frozen importlib._bootstrap>", line 228, in _call_with_frames_removed
  File "/home/rafaelrb/anaconda3/lib/python3.9/site-packages/airflow/example_dags/example_dataset_alias.py", line 53, in <module>
    def produce_dataset_events():
  File "/home/rafaelrb/anaconda3/lib/python3.9/site-packages/airflow/decorators/base.py", line 691, in decorator_factory
    return _TaskDecorator(
TypeError: _TaskDecorator() takes no arguments
[2025-02-23T02:34:48.381-0500] {processor.py:927} WARNING - No viable dags retrieved from /home/rafaelrb/anaconda3/lib/python3.9/site-packages/airflow/example_dags/example_dataset_alias.py
[2025-02-23T02:34:48.431-0500] {processor.py:208} INFO - Processing /home/rafaelrb/anaconda3/lib/python3.9/site-packages/airflow/example_dags/example_dataset_alias.py took 0.075 seconds
[2025-02-23T02:43:51.446-0500] {processor.py:186} INFO - Started process (PID=79182) to work on /home/rafaelrb/anaconda3/lib/python3.9/site-packages/airflow/example_dags/example_dataset_alias.py
[2025-02-23T02:43:51.447-0500] {processor.py:914} INFO - Processing file /home/rafaelrb/anaconda3/lib/python3.9/site-packages/airflow/example_dags/example_dataset_alias.py for tasks to queue
[2025-02-23T02:43:51.450-0500] {logging_mixin.py:190} INFO - [2025-02-23T02:43:51.449-0500] {dagbag.py:588} INFO - Filling up the DagBag from /home/rafaelrb/anaconda3/lib/python3.9/site-packages/airflow/example_dags/example_dataset_alias.py
[2025-02-23T02:43:51.457-0500] {logging_mixin.py:190} INFO - [2025-02-23T02:43:51.456-0500] {dagbag.py:387} ERROR - Failed to import: /home/rafaelrb/anaconda3/lib/python3.9/site-packages/airflow/example_dags/example_dataset_alias.py
Traceback (most recent call last):
  File "/home/rafaelrb/anaconda3/lib/python3.9/site-packages/airflow/models/dagbag.py", line 383, in parse
    loader.exec_module(new_module)
  File "<frozen importlib._bootstrap_external>", line 850, in exec_module
  File "<frozen importlib._bootstrap>", line 228, in _call_with_frames_removed
  File "/home/rafaelrb/anaconda3/lib/python3.9/site-packages/airflow/example_dags/example_dataset_alias.py", line 53, in <module>
    def produce_dataset_events():
  File "/home/rafaelrb/anaconda3/lib/python3.9/site-packages/airflow/decorators/base.py", line 691, in decorator_factory
    return _TaskDecorator(
TypeError: _TaskDecorator() takes no arguments
[2025-02-23T02:43:51.458-0500] {processor.py:927} WARNING - No viable dags retrieved from /home/rafaelrb/anaconda3/lib/python3.9/site-packages/airflow/example_dags/example_dataset_alias.py
[2025-02-23T02:43:51.486-0500] {processor.py:208} INFO - Processing /home/rafaelrb/anaconda3/lib/python3.9/site-packages/airflow/example_dags/example_dataset_alias.py took 0.051 seconds
[2025-02-23T02:44:54.378-0500] {processor.py:186} INFO - Started process (PID=79375) to work on /home/rafaelrb/anaconda3/lib/python3.9/site-packages/airflow/example_dags/example_dataset_alias.py
[2025-02-23T02:44:54.380-0500] {processor.py:914} INFO - Processing file /home/rafaelrb/anaconda3/lib/python3.9/site-packages/airflow/example_dags/example_dataset_alias.py for tasks to queue
[2025-02-23T02:44:54.385-0500] {logging_mixin.py:190} INFO - [2025-02-23T02:44:54.383-0500] {dagbag.py:588} INFO - Filling up the DagBag from /home/rafaelrb/anaconda3/lib/python3.9/site-packages/airflow/example_dags/example_dataset_alias.py
[2025-02-23T02:44:54.393-0500] {logging_mixin.py:190} INFO - [2025-02-23T02:44:54.391-0500] {dagbag.py:387} ERROR - Failed to import: /home/rafaelrb/anaconda3/lib/python3.9/site-packages/airflow/example_dags/example_dataset_alias.py
Traceback (most recent call last):
  File "/home/rafaelrb/anaconda3/lib/python3.9/site-packages/airflow/models/dagbag.py", line 383, in parse
    loader.exec_module(new_module)
  File "<frozen importlib._bootstrap_external>", line 850, in exec_module
  File "<frozen importlib._bootstrap>", line 228, in _call_with_frames_removed
  File "/home/rafaelrb/anaconda3/lib/python3.9/site-packages/airflow/example_dags/example_dataset_alias.py", line 53, in <module>
    def produce_dataset_events():
  File "/home/rafaelrb/anaconda3/lib/python3.9/site-packages/airflow/decorators/base.py", line 691, in decorator_factory
    return _TaskDecorator(
TypeError: _TaskDecorator() takes no arguments
[2025-02-23T02:44:54.393-0500] {processor.py:927} WARNING - No viable dags retrieved from /home/rafaelrb/anaconda3/lib/python3.9/site-packages/airflow/example_dags/example_dataset_alias.py
[2025-02-23T02:44:54.427-0500] {processor.py:208} INFO - Processing /home/rafaelrb/anaconda3/lib/python3.9/site-packages/airflow/example_dags/example_dataset_alias.py took 0.058 seconds
[2025-02-23T02:45:57.067-0500] {processor.py:186} INFO - Started process (PID=79575) to work on /home/rafaelrb/anaconda3/lib/python3.9/site-packages/airflow/example_dags/example_dataset_alias.py
[2025-02-23T02:45:57.069-0500] {processor.py:914} INFO - Processing file /home/rafaelrb/anaconda3/lib/python3.9/site-packages/airflow/example_dags/example_dataset_alias.py for tasks to queue
[2025-02-23T02:45:57.072-0500] {logging_mixin.py:190} INFO - [2025-02-23T02:45:57.071-0500] {dagbag.py:588} INFO - Filling up the DagBag from /home/rafaelrb/anaconda3/lib/python3.9/site-packages/airflow/example_dags/example_dataset_alias.py
[2025-02-23T02:45:57.081-0500] {logging_mixin.py:190} INFO - [2025-02-23T02:45:57.079-0500] {dagbag.py:387} ERROR - Failed to import: /home/rafaelrb/anaconda3/lib/python3.9/site-packages/airflow/example_dags/example_dataset_alias.py
Traceback (most recent call last):
  File "/home/rafaelrb/anaconda3/lib/python3.9/site-packages/airflow/models/dagbag.py", line 383, in parse
    loader.exec_module(new_module)
  File "<frozen importlib._bootstrap_external>", line 850, in exec_module
  File "<frozen importlib._bootstrap>", line 228, in _call_with_frames_removed
  File "/home/rafaelrb/anaconda3/lib/python3.9/site-packages/airflow/example_dags/example_dataset_alias.py", line 53, in <module>
    def produce_dataset_events():
  File "/home/rafaelrb/anaconda3/lib/python3.9/site-packages/airflow/decorators/base.py", line 691, in decorator_factory
    return _TaskDecorator(
TypeError: _TaskDecorator() takes no arguments
[2025-02-23T02:45:57.082-0500] {processor.py:927} WARNING - No viable dags retrieved from /home/rafaelrb/anaconda3/lib/python3.9/site-packages/airflow/example_dags/example_dataset_alias.py
[2025-02-23T02:45:57.122-0500] {processor.py:208} INFO - Processing /home/rafaelrb/anaconda3/lib/python3.9/site-packages/airflow/example_dags/example_dataset_alias.py took 0.064 seconds
[2025-02-23T02:47:01.381-0500] {processor.py:186} INFO - Started process (PID=79803) to work on /home/rafaelrb/anaconda3/lib/python3.9/site-packages/airflow/example_dags/example_dataset_alias.py
[2025-02-23T02:47:01.383-0500] {processor.py:914} INFO - Processing file /home/rafaelrb/anaconda3/lib/python3.9/site-packages/airflow/example_dags/example_dataset_alias.py for tasks to queue
[2025-02-23T02:47:01.387-0500] {logging_mixin.py:190} INFO - [2025-02-23T02:47:01.386-0500] {dagbag.py:588} INFO - Filling up the DagBag from /home/rafaelrb/anaconda3/lib/python3.9/site-packages/airflow/example_dags/example_dataset_alias.py
[2025-02-23T02:47:01.397-0500] {logging_mixin.py:190} INFO - [2025-02-23T02:47:01.396-0500] {dagbag.py:387} ERROR - Failed to import: /home/rafaelrb/anaconda3/lib/python3.9/site-packages/airflow/example_dags/example_dataset_alias.py
Traceback (most recent call last):
  File "/home/rafaelrb/anaconda3/lib/python3.9/site-packages/airflow/models/dagbag.py", line 383, in parse
    loader.exec_module(new_module)
  File "<frozen importlib._bootstrap_external>", line 850, in exec_module
  File "<frozen importlib._bootstrap>", line 228, in _call_with_frames_removed
  File "/home/rafaelrb/anaconda3/lib/python3.9/site-packages/airflow/example_dags/example_dataset_alias.py", line 53, in <module>
    def produce_dataset_events():
  File "/home/rafaelrb/anaconda3/lib/python3.9/site-packages/airflow/decorators/base.py", line 691, in decorator_factory
    return _TaskDecorator(
TypeError: _TaskDecorator() takes no arguments
[2025-02-23T02:47:01.398-0500] {processor.py:927} WARNING - No viable dags retrieved from /home/rafaelrb/anaconda3/lib/python3.9/site-packages/airflow/example_dags/example_dataset_alias.py
[2025-02-23T02:47:01.458-0500] {processor.py:208} INFO - Processing /home/rafaelrb/anaconda3/lib/python3.9/site-packages/airflow/example_dags/example_dataset_alias.py took 0.089 seconds
[2025-02-23T02:48:08.432-0500] {processor.py:186} INFO - Started process (PID=80014) to work on /home/rafaelrb/anaconda3/lib/python3.9/site-packages/airflow/example_dags/example_dataset_alias.py
[2025-02-23T02:48:08.439-0500] {processor.py:914} INFO - Processing file /home/rafaelrb/anaconda3/lib/python3.9/site-packages/airflow/example_dags/example_dataset_alias.py for tasks to queue
[2025-02-23T02:48:08.442-0500] {logging_mixin.py:190} INFO - [2025-02-23T02:48:08.441-0500] {dagbag.py:588} INFO - Filling up the DagBag from /home/rafaelrb/anaconda3/lib/python3.9/site-packages/airflow/example_dags/example_dataset_alias.py
[2025-02-23T02:48:08.449-0500] {logging_mixin.py:190} INFO - [2025-02-23T02:48:08.448-0500] {dagbag.py:387} ERROR - Failed to import: /home/rafaelrb/anaconda3/lib/python3.9/site-packages/airflow/example_dags/example_dataset_alias.py
Traceback (most recent call last):
  File "/home/rafaelrb/anaconda3/lib/python3.9/site-packages/airflow/models/dagbag.py", line 383, in parse
    loader.exec_module(new_module)
  File "<frozen importlib._bootstrap_external>", line 850, in exec_module
  File "<frozen importlib._bootstrap>", line 228, in _call_with_frames_removed
  File "/home/rafaelrb/anaconda3/lib/python3.9/site-packages/airflow/example_dags/example_dataset_alias.py", line 53, in <module>
    def produce_dataset_events():
  File "/home/rafaelrb/anaconda3/lib/python3.9/site-packages/airflow/decorators/base.py", line 691, in decorator_factory
    return _TaskDecorator(
TypeError: _TaskDecorator() takes no arguments
[2025-02-23T02:48:08.449-0500] {processor.py:927} WARNING - No viable dags retrieved from /home/rafaelrb/anaconda3/lib/python3.9/site-packages/airflow/example_dags/example_dataset_alias.py
[2025-02-23T02:48:08.477-0500] {processor.py:208} INFO - Processing /home/rafaelrb/anaconda3/lib/python3.9/site-packages/airflow/example_dags/example_dataset_alias.py took 0.055 seconds
[2025-02-23T02:49:11.387-0500] {processor.py:186} INFO - Started process (PID=80208) to work on /home/rafaelrb/anaconda3/lib/python3.9/site-packages/airflow/example_dags/example_dataset_alias.py
[2025-02-23T02:49:11.394-0500] {processor.py:914} INFO - Processing file /home/rafaelrb/anaconda3/lib/python3.9/site-packages/airflow/example_dags/example_dataset_alias.py for tasks to queue
[2025-02-23T02:49:11.396-0500] {logging_mixin.py:190} INFO - [2025-02-23T02:49:11.396-0500] {dagbag.py:588} INFO - Filling up the DagBag from /home/rafaelrb/anaconda3/lib/python3.9/site-packages/airflow/example_dags/example_dataset_alias.py
[2025-02-23T02:49:11.404-0500] {logging_mixin.py:190} INFO - [2025-02-23T02:49:11.403-0500] {dagbag.py:387} ERROR - Failed to import: /home/rafaelrb/anaconda3/lib/python3.9/site-packages/airflow/example_dags/example_dataset_alias.py
Traceback (most recent call last):
  File "/home/rafaelrb/anaconda3/lib/python3.9/site-packages/airflow/models/dagbag.py", line 383, in parse
    loader.exec_module(new_module)
  File "<frozen importlib._bootstrap_external>", line 850, in exec_module
  File "<frozen importlib._bootstrap>", line 228, in _call_with_frames_removed
  File "/home/rafaelrb/anaconda3/lib/python3.9/site-packages/airflow/example_dags/example_dataset_alias.py", line 53, in <module>
    def produce_dataset_events():
  File "/home/rafaelrb/anaconda3/lib/python3.9/site-packages/airflow/decorators/base.py", line 691, in decorator_factory
    return _TaskDecorator(
TypeError: _TaskDecorator() takes no arguments
[2025-02-23T02:49:11.404-0500] {processor.py:927} WARNING - No viable dags retrieved from /home/rafaelrb/anaconda3/lib/python3.9/site-packages/airflow/example_dags/example_dataset_alias.py
[2025-02-23T02:49:11.435-0500] {processor.py:208} INFO - Processing /home/rafaelrb/anaconda3/lib/python3.9/site-packages/airflow/example_dags/example_dataset_alias.py took 0.057 seconds
[2025-02-23T02:50:40.273-0500] {processor.py:186} INFO - Started process (PID=80457) to work on /home/rafaelrb/anaconda3/lib/python3.9/site-packages/airflow/example_dags/example_dataset_alias.py
[2025-02-23T02:50:40.275-0500] {processor.py:914} INFO - Processing file /home/rafaelrb/anaconda3/lib/python3.9/site-packages/airflow/example_dags/example_dataset_alias.py for tasks to queue
[2025-02-23T02:50:40.279-0500] {logging_mixin.py:190} INFO - [2025-02-23T02:50:40.278-0500] {dagbag.py:588} INFO - Filling up the DagBag from /home/rafaelrb/anaconda3/lib/python3.9/site-packages/airflow/example_dags/example_dataset_alias.py
[2025-02-23T02:50:40.299-0500] {logging_mixin.py:190} INFO - [2025-02-23T02:50:40.296-0500] {dagbag.py:387} ERROR - Failed to import: /home/rafaelrb/anaconda3/lib/python3.9/site-packages/airflow/example_dags/example_dataset_alias.py
Traceback (most recent call last):
  File "/home/rafaelrb/anaconda3/lib/python3.9/site-packages/airflow/models/dagbag.py", line 383, in parse
    loader.exec_module(new_module)
  File "<frozen importlib._bootstrap_external>", line 850, in exec_module
  File "<frozen importlib._bootstrap>", line 228, in _call_with_frames_removed
  File "/home/rafaelrb/anaconda3/lib/python3.9/site-packages/airflow/example_dags/example_dataset_alias.py", line 53, in <module>
    def produce_dataset_events():
  File "/home/rafaelrb/anaconda3/lib/python3.9/site-packages/airflow/decorators/base.py", line 691, in decorator_factory
    return _TaskDecorator(
TypeError: _TaskDecorator() takes no arguments
[2025-02-23T02:50:40.300-0500] {processor.py:927} WARNING - No viable dags retrieved from /home/rafaelrb/anaconda3/lib/python3.9/site-packages/airflow/example_dags/example_dataset_alias.py
[2025-02-23T02:50:40.373-0500] {processor.py:208} INFO - Processing /home/rafaelrb/anaconda3/lib/python3.9/site-packages/airflow/example_dags/example_dataset_alias.py took 0.113 seconds
[2025-02-23T02:51:57.092-0500] {processor.py:186} INFO - Started process (PID=80709) to work on /home/rafaelrb/anaconda3/lib/python3.9/site-packages/airflow/example_dags/example_dataset_alias.py
[2025-02-23T02:51:57.094-0500] {processor.py:914} INFO - Processing file /home/rafaelrb/anaconda3/lib/python3.9/site-packages/airflow/example_dags/example_dataset_alias.py for tasks to queue
[2025-02-23T02:51:57.098-0500] {logging_mixin.py:190} INFO - [2025-02-23T02:51:57.097-0500] {dagbag.py:588} INFO - Filling up the DagBag from /home/rafaelrb/anaconda3/lib/python3.9/site-packages/airflow/example_dags/example_dataset_alias.py
[2025-02-23T02:51:57.107-0500] {logging_mixin.py:190} INFO - [2025-02-23T02:51:57.104-0500] {dagbag.py:387} ERROR - Failed to import: /home/rafaelrb/anaconda3/lib/python3.9/site-packages/airflow/example_dags/example_dataset_alias.py
Traceback (most recent call last):
  File "/home/rafaelrb/anaconda3/lib/python3.9/site-packages/airflow/models/dagbag.py", line 383, in parse
    loader.exec_module(new_module)
  File "<frozen importlib._bootstrap_external>", line 850, in exec_module
  File "<frozen importlib._bootstrap>", line 228, in _call_with_frames_removed
  File "/home/rafaelrb/anaconda3/lib/python3.9/site-packages/airflow/example_dags/example_dataset_alias.py", line 53, in <module>
    def produce_dataset_events():
  File "/home/rafaelrb/anaconda3/lib/python3.9/site-packages/airflow/decorators/base.py", line 691, in decorator_factory
    return _TaskDecorator(
TypeError: _TaskDecorator() takes no arguments
[2025-02-23T02:51:57.108-0500] {processor.py:927} WARNING - No viable dags retrieved from /home/rafaelrb/anaconda3/lib/python3.9/site-packages/airflow/example_dags/example_dataset_alias.py
[2025-02-23T02:51:57.175-0500] {processor.py:208} INFO - Processing /home/rafaelrb/anaconda3/lib/python3.9/site-packages/airflow/example_dags/example_dataset_alias.py took 0.096 seconds
[2025-02-23T02:53:05.094-0500] {processor.py:186} INFO - Started process (PID=80915) to work on /home/rafaelrb/anaconda3/lib/python3.9/site-packages/airflow/example_dags/example_dataset_alias.py
[2025-02-23T02:53:05.096-0500] {processor.py:914} INFO - Processing file /home/rafaelrb/anaconda3/lib/python3.9/site-packages/airflow/example_dags/example_dataset_alias.py for tasks to queue
[2025-02-23T02:53:05.100-0500] {logging_mixin.py:190} INFO - [2025-02-23T02:53:05.099-0500] {dagbag.py:588} INFO - Filling up the DagBag from /home/rafaelrb/anaconda3/lib/python3.9/site-packages/airflow/example_dags/example_dataset_alias.py
[2025-02-23T02:53:05.109-0500] {logging_mixin.py:190} INFO - [2025-02-23T02:53:05.107-0500] {dagbag.py:387} ERROR - Failed to import: /home/rafaelrb/anaconda3/lib/python3.9/site-packages/airflow/example_dags/example_dataset_alias.py
Traceback (most recent call last):
  File "/home/rafaelrb/anaconda3/lib/python3.9/site-packages/airflow/models/dagbag.py", line 383, in parse
    loader.exec_module(new_module)
  File "<frozen importlib._bootstrap_external>", line 850, in exec_module
  File "<frozen importlib._bootstrap>", line 228, in _call_with_frames_removed
  File "/home/rafaelrb/anaconda3/lib/python3.9/site-packages/airflow/example_dags/example_dataset_alias.py", line 53, in <module>
    def produce_dataset_events():
  File "/home/rafaelrb/anaconda3/lib/python3.9/site-packages/airflow/decorators/base.py", line 691, in decorator_factory
    return _TaskDecorator(
TypeError: _TaskDecorator() takes no arguments
[2025-02-23T02:53:05.110-0500] {processor.py:927} WARNING - No viable dags retrieved from /home/rafaelrb/anaconda3/lib/python3.9/site-packages/airflow/example_dags/example_dataset_alias.py
[2025-02-23T02:53:05.151-0500] {processor.py:208} INFO - Processing /home/rafaelrb/anaconda3/lib/python3.9/site-packages/airflow/example_dags/example_dataset_alias.py took 0.068 seconds
[2025-02-23T02:54:06.810-0500] {processor.py:186} INFO - Started process (PID=81104) to work on /home/rafaelrb/anaconda3/lib/python3.9/site-packages/airflow/example_dags/example_dataset_alias.py
[2025-02-23T02:54:06.812-0500] {processor.py:914} INFO - Processing file /home/rafaelrb/anaconda3/lib/python3.9/site-packages/airflow/example_dags/example_dataset_alias.py for tasks to queue
[2025-02-23T02:54:06.817-0500] {logging_mixin.py:190} INFO - [2025-02-23T02:54:06.816-0500] {dagbag.py:588} INFO - Filling up the DagBag from /home/rafaelrb/anaconda3/lib/python3.9/site-packages/airflow/example_dags/example_dataset_alias.py
[2025-02-23T02:54:06.834-0500] {logging_mixin.py:190} INFO - [2025-02-23T02:54:06.832-0500] {dagbag.py:387} ERROR - Failed to import: /home/rafaelrb/anaconda3/lib/python3.9/site-packages/airflow/example_dags/example_dataset_alias.py
Traceback (most recent call last):
  File "/home/rafaelrb/anaconda3/lib/python3.9/site-packages/airflow/models/dagbag.py", line 383, in parse
    loader.exec_module(new_module)
  File "<frozen importlib._bootstrap_external>", line 850, in exec_module
  File "<frozen importlib._bootstrap>", line 228, in _call_with_frames_removed
  File "/home/rafaelrb/anaconda3/lib/python3.9/site-packages/airflow/example_dags/example_dataset_alias.py", line 53, in <module>
    def produce_dataset_events():
  File "/home/rafaelrb/anaconda3/lib/python3.9/site-packages/airflow/decorators/base.py", line 691, in decorator_factory
    return _TaskDecorator(
TypeError: _TaskDecorator() takes no arguments
[2025-02-23T02:54:06.835-0500] {processor.py:927} WARNING - No viable dags retrieved from /home/rafaelrb/anaconda3/lib/python3.9/site-packages/airflow/example_dags/example_dataset_alias.py
[2025-02-23T02:54:06.880-0500] {processor.py:208} INFO - Processing /home/rafaelrb/anaconda3/lib/python3.9/site-packages/airflow/example_dags/example_dataset_alias.py took 0.084 seconds
[2025-02-23T02:55:11.259-0500] {processor.py:186} INFO - Started process (PID=81307) to work on /home/rafaelrb/anaconda3/lib/python3.9/site-packages/airflow/example_dags/example_dataset_alias.py
[2025-02-23T02:55:11.261-0500] {processor.py:914} INFO - Processing file /home/rafaelrb/anaconda3/lib/python3.9/site-packages/airflow/example_dags/example_dataset_alias.py for tasks to queue
[2025-02-23T02:55:11.264-0500] {logging_mixin.py:190} INFO - [2025-02-23T02:55:11.263-0500] {dagbag.py:588} INFO - Filling up the DagBag from /home/rafaelrb/anaconda3/lib/python3.9/site-packages/airflow/example_dags/example_dataset_alias.py
[2025-02-23T02:55:11.271-0500] {logging_mixin.py:190} INFO - [2025-02-23T02:55:11.270-0500] {dagbag.py:387} ERROR - Failed to import: /home/rafaelrb/anaconda3/lib/python3.9/site-packages/airflow/example_dags/example_dataset_alias.py
Traceback (most recent call last):
  File "/home/rafaelrb/anaconda3/lib/python3.9/site-packages/airflow/models/dagbag.py", line 383, in parse
    loader.exec_module(new_module)
  File "<frozen importlib._bootstrap_external>", line 850, in exec_module
  File "<frozen importlib._bootstrap>", line 228, in _call_with_frames_removed
  File "/home/rafaelrb/anaconda3/lib/python3.9/site-packages/airflow/example_dags/example_dataset_alias.py", line 53, in <module>
    def produce_dataset_events():
  File "/home/rafaelrb/anaconda3/lib/python3.9/site-packages/airflow/decorators/base.py", line 691, in decorator_factory
    return _TaskDecorator(
TypeError: _TaskDecorator() takes no arguments
[2025-02-23T02:55:11.272-0500] {processor.py:927} WARNING - No viable dags retrieved from /home/rafaelrb/anaconda3/lib/python3.9/site-packages/airflow/example_dags/example_dataset_alias.py
[2025-02-23T02:55:11.305-0500] {processor.py:208} INFO - Processing /home/rafaelrb/anaconda3/lib/python3.9/site-packages/airflow/example_dags/example_dataset_alias.py took 0.054 seconds
[2025-02-23T02:56:12.918-0500] {processor.py:186} INFO - Started process (PID=81493) to work on /home/rafaelrb/anaconda3/lib/python3.9/site-packages/airflow/example_dags/example_dataset_alias.py
[2025-02-23T02:56:12.920-0500] {processor.py:914} INFO - Processing file /home/rafaelrb/anaconda3/lib/python3.9/site-packages/airflow/example_dags/example_dataset_alias.py for tasks to queue
[2025-02-23T02:56:12.923-0500] {logging_mixin.py:190} INFO - [2025-02-23T02:56:12.922-0500] {dagbag.py:588} INFO - Filling up the DagBag from /home/rafaelrb/anaconda3/lib/python3.9/site-packages/airflow/example_dags/example_dataset_alias.py
[2025-02-23T02:56:12.933-0500] {logging_mixin.py:190} INFO - [2025-02-23T02:56:12.931-0500] {dagbag.py:387} ERROR - Failed to import: /home/rafaelrb/anaconda3/lib/python3.9/site-packages/airflow/example_dags/example_dataset_alias.py
Traceback (most recent call last):
  File "/home/rafaelrb/anaconda3/lib/python3.9/site-packages/airflow/models/dagbag.py", line 383, in parse
    loader.exec_module(new_module)
  File "<frozen importlib._bootstrap_external>", line 850, in exec_module
  File "<frozen importlib._bootstrap>", line 228, in _call_with_frames_removed
  File "/home/rafaelrb/anaconda3/lib/python3.9/site-packages/airflow/example_dags/example_dataset_alias.py", line 53, in <module>
    def produce_dataset_events():
  File "/home/rafaelrb/anaconda3/lib/python3.9/site-packages/airflow/decorators/base.py", line 691, in decorator_factory
    return _TaskDecorator(
TypeError: _TaskDecorator() takes no arguments
[2025-02-23T02:56:12.934-0500] {processor.py:927} WARNING - No viable dags retrieved from /home/rafaelrb/anaconda3/lib/python3.9/site-packages/airflow/example_dags/example_dataset_alias.py
[2025-02-23T02:56:12.967-0500] {processor.py:208} INFO - Processing /home/rafaelrb/anaconda3/lib/python3.9/site-packages/airflow/example_dags/example_dataset_alias.py took 0.060 seconds
[2025-02-23T02:57:13.479-0500] {processor.py:186} INFO - Started process (PID=81718) to work on /home/rafaelrb/anaconda3/lib/python3.9/site-packages/airflow/example_dags/example_dataset_alias.py
[2025-02-23T02:57:13.481-0500] {processor.py:914} INFO - Processing file /home/rafaelrb/anaconda3/lib/python3.9/site-packages/airflow/example_dags/example_dataset_alias.py for tasks to queue
[2025-02-23T02:57:13.484-0500] {logging_mixin.py:190} INFO - [2025-02-23T02:57:13.483-0500] {dagbag.py:588} INFO - Filling up the DagBag from /home/rafaelrb/anaconda3/lib/python3.9/site-packages/airflow/example_dags/example_dataset_alias.py
[2025-02-23T02:57:13.492-0500] {logging_mixin.py:190} INFO - [2025-02-23T02:57:13.491-0500] {dagbag.py:387} ERROR - Failed to import: /home/rafaelrb/anaconda3/lib/python3.9/site-packages/airflow/example_dags/example_dataset_alias.py
Traceback (most recent call last):
  File "/home/rafaelrb/anaconda3/lib/python3.9/site-packages/airflow/models/dagbag.py", line 383, in parse
    loader.exec_module(new_module)
  File "<frozen importlib._bootstrap_external>", line 850, in exec_module
  File "<frozen importlib._bootstrap>", line 228, in _call_with_frames_removed
  File "/home/rafaelrb/anaconda3/lib/python3.9/site-packages/airflow/example_dags/example_dataset_alias.py", line 53, in <module>
    def produce_dataset_events():
  File "/home/rafaelrb/anaconda3/lib/python3.9/site-packages/airflow/decorators/base.py", line 691, in decorator_factory
    return _TaskDecorator(
TypeError: _TaskDecorator() takes no arguments
[2025-02-23T02:57:13.492-0500] {processor.py:927} WARNING - No viable dags retrieved from /home/rafaelrb/anaconda3/lib/python3.9/site-packages/airflow/example_dags/example_dataset_alias.py
[2025-02-23T02:57:13.524-0500] {processor.py:208} INFO - Processing /home/rafaelrb/anaconda3/lib/python3.9/site-packages/airflow/example_dags/example_dataset_alias.py took 0.054 seconds
[2025-02-23T02:58:21.045-0500] {processor.py:186} INFO - Started process (PID=81935) to work on /home/rafaelrb/anaconda3/lib/python3.9/site-packages/airflow/example_dags/example_dataset_alias.py
[2025-02-23T02:58:21.083-0500] {processor.py:914} INFO - Processing file /home/rafaelrb/anaconda3/lib/python3.9/site-packages/airflow/example_dags/example_dataset_alias.py for tasks to queue
[2025-02-23T02:58:21.087-0500] {logging_mixin.py:190} INFO - [2025-02-23T02:58:21.086-0500] {dagbag.py:588} INFO - Filling up the DagBag from /home/rafaelrb/anaconda3/lib/python3.9/site-packages/airflow/example_dags/example_dataset_alias.py
[2025-02-23T02:58:21.108-0500] {logging_mixin.py:190} INFO - [2025-02-23T02:58:21.097-0500] {dagbag.py:387} ERROR - Failed to import: /home/rafaelrb/anaconda3/lib/python3.9/site-packages/airflow/example_dags/example_dataset_alias.py
Traceback (most recent call last):
  File "/home/rafaelrb/anaconda3/lib/python3.9/site-packages/airflow/models/dagbag.py", line 383, in parse
    loader.exec_module(new_module)
  File "<frozen importlib._bootstrap_external>", line 850, in exec_module
  File "<frozen importlib._bootstrap>", line 228, in _call_with_frames_removed
  File "/home/rafaelrb/anaconda3/lib/python3.9/site-packages/airflow/example_dags/example_dataset_alias.py", line 53, in <module>
    def produce_dataset_events():
  File "/home/rafaelrb/anaconda3/lib/python3.9/site-packages/airflow/decorators/base.py", line 691, in decorator_factory
    return _TaskDecorator(
TypeError: _TaskDecorator() takes no arguments
[2025-02-23T02:58:21.110-0500] {processor.py:927} WARNING - No viable dags retrieved from /home/rafaelrb/anaconda3/lib/python3.9/site-packages/airflow/example_dags/example_dataset_alias.py
[2025-02-23T02:58:21.147-0500] {processor.py:208} INFO - Processing /home/rafaelrb/anaconda3/lib/python3.9/site-packages/airflow/example_dags/example_dataset_alias.py took 0.112 seconds
[2025-02-23T02:59:20.397-0500] {processor.py:186} INFO - Started process (PID=82122) to work on /home/rafaelrb/anaconda3/lib/python3.9/site-packages/airflow/example_dags/example_dataset_alias.py
[2025-02-23T02:59:20.400-0500] {processor.py:914} INFO - Processing file /home/rafaelrb/anaconda3/lib/python3.9/site-packages/airflow/example_dags/example_dataset_alias.py for tasks to queue
[2025-02-23T02:59:20.403-0500] {logging_mixin.py:190} INFO - [2025-02-23T02:59:20.403-0500] {dagbag.py:588} INFO - Filling up the DagBag from /home/rafaelrb/anaconda3/lib/python3.9/site-packages/airflow/example_dags/example_dataset_alias.py
[2025-02-23T02:59:20.411-0500] {logging_mixin.py:190} INFO - [2025-02-23T02:59:20.410-0500] {dagbag.py:387} ERROR - Failed to import: /home/rafaelrb/anaconda3/lib/python3.9/site-packages/airflow/example_dags/example_dataset_alias.py
Traceback (most recent call last):
  File "/home/rafaelrb/anaconda3/lib/python3.9/site-packages/airflow/models/dagbag.py", line 383, in parse
    loader.exec_module(new_module)
  File "<frozen importlib._bootstrap_external>", line 850, in exec_module
  File "<frozen importlib._bootstrap>", line 228, in _call_with_frames_removed
  File "/home/rafaelrb/anaconda3/lib/python3.9/site-packages/airflow/example_dags/example_dataset_alias.py", line 53, in <module>
    def produce_dataset_events():
  File "/home/rafaelrb/anaconda3/lib/python3.9/site-packages/airflow/decorators/base.py", line 691, in decorator_factory
    return _TaskDecorator(
TypeError: _TaskDecorator() takes no arguments
[2025-02-23T02:59:20.412-0500] {processor.py:927} WARNING - No viable dags retrieved from /home/rafaelrb/anaconda3/lib/python3.9/site-packages/airflow/example_dags/example_dataset_alias.py
[2025-02-23T02:59:20.447-0500] {processor.py:208} INFO - Processing /home/rafaelrb/anaconda3/lib/python3.9/site-packages/airflow/example_dags/example_dataset_alias.py took 0.059 seconds
[2025-02-23T03:00:25.335-0500] {processor.py:186} INFO - Started process (PID=82314) to work on /home/rafaelrb/anaconda3/lib/python3.9/site-packages/airflow/example_dags/example_dataset_alias.py
[2025-02-23T03:00:25.337-0500] {processor.py:914} INFO - Processing file /home/rafaelrb/anaconda3/lib/python3.9/site-packages/airflow/example_dags/example_dataset_alias.py for tasks to queue
[2025-02-23T03:00:25.340-0500] {logging_mixin.py:190} INFO - [2025-02-23T03:00:25.339-0500] {dagbag.py:588} INFO - Filling up the DagBag from /home/rafaelrb/anaconda3/lib/python3.9/site-packages/airflow/example_dags/example_dataset_alias.py
[2025-02-23T03:00:25.348-0500] {logging_mixin.py:190} INFO - [2025-02-23T03:00:25.347-0500] {dagbag.py:387} ERROR - Failed to import: /home/rafaelrb/anaconda3/lib/python3.9/site-packages/airflow/example_dags/example_dataset_alias.py
Traceback (most recent call last):
  File "/home/rafaelrb/anaconda3/lib/python3.9/site-packages/airflow/models/dagbag.py", line 383, in parse
    loader.exec_module(new_module)
  File "<frozen importlib._bootstrap_external>", line 850, in exec_module
  File "<frozen importlib._bootstrap>", line 228, in _call_with_frames_removed
  File "/home/rafaelrb/anaconda3/lib/python3.9/site-packages/airflow/example_dags/example_dataset_alias.py", line 53, in <module>
    def produce_dataset_events():
  File "/home/rafaelrb/anaconda3/lib/python3.9/site-packages/airflow/decorators/base.py", line 691, in decorator_factory
    return _TaskDecorator(
TypeError: _TaskDecorator() takes no arguments
[2025-02-23T03:00:25.349-0500] {processor.py:927} WARNING - No viable dags retrieved from /home/rafaelrb/anaconda3/lib/python3.9/site-packages/airflow/example_dags/example_dataset_alias.py
[2025-02-23T03:00:25.381-0500] {processor.py:208} INFO - Processing /home/rafaelrb/anaconda3/lib/python3.9/site-packages/airflow/example_dags/example_dataset_alias.py took 0.057 seconds
[2025-02-23T03:01:31.363-0500] {processor.py:186} INFO - Started process (PID=82563) to work on /home/rafaelrb/anaconda3/lib/python3.9/site-packages/airflow/example_dags/example_dataset_alias.py
[2025-02-23T03:01:31.364-0500] {processor.py:914} INFO - Processing file /home/rafaelrb/anaconda3/lib/python3.9/site-packages/airflow/example_dags/example_dataset_alias.py for tasks to queue
[2025-02-23T03:01:31.368-0500] {logging_mixin.py:190} INFO - [2025-02-23T03:01:31.367-0500] {dagbag.py:588} INFO - Filling up the DagBag from /home/rafaelrb/anaconda3/lib/python3.9/site-packages/airflow/example_dags/example_dataset_alias.py
[2025-02-23T03:01:31.374-0500] {logging_mixin.py:190} INFO - [2025-02-23T03:01:31.374-0500] {dagbag.py:387} ERROR - Failed to import: /home/rafaelrb/anaconda3/lib/python3.9/site-packages/airflow/example_dags/example_dataset_alias.py
Traceback (most recent call last):
  File "/home/rafaelrb/anaconda3/lib/python3.9/site-packages/airflow/models/dagbag.py", line 383, in parse
    loader.exec_module(new_module)
  File "<frozen importlib._bootstrap_external>", line 850, in exec_module
  File "<frozen importlib._bootstrap>", line 228, in _call_with_frames_removed
  File "/home/rafaelrb/anaconda3/lib/python3.9/site-packages/airflow/example_dags/example_dataset_alias.py", line 53, in <module>
    def produce_dataset_events():
  File "/home/rafaelrb/anaconda3/lib/python3.9/site-packages/airflow/decorators/base.py", line 691, in decorator_factory
    return _TaskDecorator(
TypeError: _TaskDecorator() takes no arguments
[2025-02-23T03:01:31.375-0500] {processor.py:927} WARNING - No viable dags retrieved from /home/rafaelrb/anaconda3/lib/python3.9/site-packages/airflow/example_dags/example_dataset_alias.py
[2025-02-23T03:01:31.408-0500] {processor.py:208} INFO - Processing /home/rafaelrb/anaconda3/lib/python3.9/site-packages/airflow/example_dags/example_dataset_alias.py took 0.054 seconds
[2025-02-23T03:02:45.831-0500] {processor.py:186} INFO - Started process (PID=82802) to work on /home/rafaelrb/anaconda3/lib/python3.9/site-packages/airflow/example_dags/example_dataset_alias.py
[2025-02-23T03:02:45.833-0500] {processor.py:914} INFO - Processing file /home/rafaelrb/anaconda3/lib/python3.9/site-packages/airflow/example_dags/example_dataset_alias.py for tasks to queue
[2025-02-23T03:02:45.838-0500] {logging_mixin.py:190} INFO - [2025-02-23T03:02:45.837-0500] {dagbag.py:588} INFO - Filling up the DagBag from /home/rafaelrb/anaconda3/lib/python3.9/site-packages/airflow/example_dags/example_dataset_alias.py
[2025-02-23T03:02:45.848-0500] {logging_mixin.py:190} INFO - [2025-02-23T03:02:45.847-0500] {dagbag.py:387} ERROR - Failed to import: /home/rafaelrb/anaconda3/lib/python3.9/site-packages/airflow/example_dags/example_dataset_alias.py
Traceback (most recent call last):
  File "/home/rafaelrb/anaconda3/lib/python3.9/site-packages/airflow/models/dagbag.py", line 383, in parse
    loader.exec_module(new_module)
  File "<frozen importlib._bootstrap_external>", line 850, in exec_module
  File "<frozen importlib._bootstrap>", line 228, in _call_with_frames_removed
  File "/home/rafaelrb/anaconda3/lib/python3.9/site-packages/airflow/example_dags/example_dataset_alias.py", line 53, in <module>
    def produce_dataset_events():
  File "/home/rafaelrb/anaconda3/lib/python3.9/site-packages/airflow/decorators/base.py", line 691, in decorator_factory
    return _TaskDecorator(
TypeError: _TaskDecorator() takes no arguments
[2025-02-23T03:02:45.849-0500] {processor.py:927} WARNING - No viable dags retrieved from /home/rafaelrb/anaconda3/lib/python3.9/site-packages/airflow/example_dags/example_dataset_alias.py
[2025-02-23T03:02:45.898-0500] {processor.py:208} INFO - Processing /home/rafaelrb/anaconda3/lib/python3.9/site-packages/airflow/example_dags/example_dataset_alias.py took 0.079 seconds
[2025-02-23T03:04:03.835-0500] {processor.py:186} INFO - Started process (PID=83640) to work on /home/rafaelrb/anaconda3/lib/python3.9/site-packages/airflow/example_dags/example_dataset_alias.py
[2025-02-23T03:04:03.837-0500] {processor.py:914} INFO - Processing file /home/rafaelrb/anaconda3/lib/python3.9/site-packages/airflow/example_dags/example_dataset_alias.py for tasks to queue
[2025-02-23T03:04:03.840-0500] {logging_mixin.py:190} INFO - [2025-02-23T03:04:03.840-0500] {dagbag.py:588} INFO - Filling up the DagBag from /home/rafaelrb/anaconda3/lib/python3.9/site-packages/airflow/example_dags/example_dataset_alias.py
[2025-02-23T03:04:03.849-0500] {logging_mixin.py:190} INFO - [2025-02-23T03:04:03.847-0500] {dagbag.py:387} ERROR - Failed to import: /home/rafaelrb/anaconda3/lib/python3.9/site-packages/airflow/example_dags/example_dataset_alias.py
Traceback (most recent call last):
  File "/home/rafaelrb/anaconda3/lib/python3.9/site-packages/airflow/models/dagbag.py", line 383, in parse
    loader.exec_module(new_module)
  File "<frozen importlib._bootstrap_external>", line 850, in exec_module
  File "<frozen importlib._bootstrap>", line 228, in _call_with_frames_removed
  File "/home/rafaelrb/anaconda3/lib/python3.9/site-packages/airflow/example_dags/example_dataset_alias.py", line 53, in <module>
    def produce_dataset_events():
  File "/home/rafaelrb/anaconda3/lib/python3.9/site-packages/airflow/decorators/base.py", line 691, in decorator_factory
    return _TaskDecorator(
TypeError: _TaskDecorator() takes no arguments
[2025-02-23T03:04:03.850-0500] {processor.py:927} WARNING - No viable dags retrieved from /home/rafaelrb/anaconda3/lib/python3.9/site-packages/airflow/example_dags/example_dataset_alias.py
[2025-02-23T03:04:03.884-0500] {processor.py:208} INFO - Processing /home/rafaelrb/anaconda3/lib/python3.9/site-packages/airflow/example_dags/example_dataset_alias.py took 0.060 seconds
[2025-02-23T03:05:09.898-0500] {processor.py:186} INFO - Started process (PID=83842) to work on /home/rafaelrb/anaconda3/lib/python3.9/site-packages/airflow/example_dags/example_dataset_alias.py
[2025-02-23T03:05:09.905-0500] {processor.py:914} INFO - Processing file /home/rafaelrb/anaconda3/lib/python3.9/site-packages/airflow/example_dags/example_dataset_alias.py for tasks to queue
[2025-02-23T03:05:09.908-0500] {logging_mixin.py:190} INFO - [2025-02-23T03:05:09.908-0500] {dagbag.py:588} INFO - Filling up the DagBag from /home/rafaelrb/anaconda3/lib/python3.9/site-packages/airflow/example_dags/example_dataset_alias.py
[2025-02-23T03:05:09.916-0500] {logging_mixin.py:190} INFO - [2025-02-23T03:05:09.915-0500] {dagbag.py:387} ERROR - Failed to import: /home/rafaelrb/anaconda3/lib/python3.9/site-packages/airflow/example_dags/example_dataset_alias.py
Traceback (most recent call last):
  File "/home/rafaelrb/anaconda3/lib/python3.9/site-packages/airflow/models/dagbag.py", line 383, in parse
    loader.exec_module(new_module)
  File "<frozen importlib._bootstrap_external>", line 850, in exec_module
  File "<frozen importlib._bootstrap>", line 228, in _call_with_frames_removed
  File "/home/rafaelrb/anaconda3/lib/python3.9/site-packages/airflow/example_dags/example_dataset_alias.py", line 53, in <module>
    def produce_dataset_events():
  File "/home/rafaelrb/anaconda3/lib/python3.9/site-packages/airflow/decorators/base.py", line 691, in decorator_factory
    return _TaskDecorator(
TypeError: _TaskDecorator() takes no arguments
[2025-02-23T03:05:09.917-0500] {processor.py:927} WARNING - No viable dags retrieved from /home/rafaelrb/anaconda3/lib/python3.9/site-packages/airflow/example_dags/example_dataset_alias.py
[2025-02-23T03:05:09.945-0500] {processor.py:208} INFO - Processing /home/rafaelrb/anaconda3/lib/python3.9/site-packages/airflow/example_dags/example_dataset_alias.py took 0.058 seconds
[2025-02-23T03:06:12.897-0500] {processor.py:186} INFO - Started process (PID=84040) to work on /home/rafaelrb/anaconda3/lib/python3.9/site-packages/airflow/example_dags/example_dataset_alias.py
[2025-02-23T03:06:12.899-0500] {processor.py:914} INFO - Processing file /home/rafaelrb/anaconda3/lib/python3.9/site-packages/airflow/example_dags/example_dataset_alias.py for tasks to queue
[2025-02-23T03:06:12.902-0500] {logging_mixin.py:190} INFO - [2025-02-23T03:06:12.901-0500] {dagbag.py:588} INFO - Filling up the DagBag from /home/rafaelrb/anaconda3/lib/python3.9/site-packages/airflow/example_dags/example_dataset_alias.py
[2025-02-23T03:06:12.909-0500] {logging_mixin.py:190} INFO - [2025-02-23T03:06:12.908-0500] {dagbag.py:387} ERROR - Failed to import: /home/rafaelrb/anaconda3/lib/python3.9/site-packages/airflow/example_dags/example_dataset_alias.py
Traceback (most recent call last):
  File "/home/rafaelrb/anaconda3/lib/python3.9/site-packages/airflow/models/dagbag.py", line 383, in parse
    loader.exec_module(new_module)
  File "<frozen importlib._bootstrap_external>", line 850, in exec_module
  File "<frozen importlib._bootstrap>", line 228, in _call_with_frames_removed
  File "/home/rafaelrb/anaconda3/lib/python3.9/site-packages/airflow/example_dags/example_dataset_alias.py", line 53, in <module>
    def produce_dataset_events():
  File "/home/rafaelrb/anaconda3/lib/python3.9/site-packages/airflow/decorators/base.py", line 691, in decorator_factory
    return _TaskDecorator(
TypeError: _TaskDecorator() takes no arguments
[2025-02-23T03:06:12.909-0500] {processor.py:927} WARNING - No viable dags retrieved from /home/rafaelrb/anaconda3/lib/python3.9/site-packages/airflow/example_dags/example_dataset_alias.py
[2025-02-23T03:06:12.940-0500] {processor.py:208} INFO - Processing /home/rafaelrb/anaconda3/lib/python3.9/site-packages/airflow/example_dags/example_dataset_alias.py took 0.053 seconds
[2025-02-23T03:07:12.697-0500] {processor.py:186} INFO - Started process (PID=84246) to work on /home/rafaelrb/anaconda3/lib/python3.9/site-packages/airflow/example_dags/example_dataset_alias.py
[2025-02-23T03:07:12.699-0500] {processor.py:914} INFO - Processing file /home/rafaelrb/anaconda3/lib/python3.9/site-packages/airflow/example_dags/example_dataset_alias.py for tasks to queue
[2025-02-23T03:07:12.704-0500] {logging_mixin.py:190} INFO - [2025-02-23T03:07:12.703-0500] {dagbag.py:588} INFO - Filling up the DagBag from /home/rafaelrb/anaconda3/lib/python3.9/site-packages/airflow/example_dags/example_dataset_alias.py
[2025-02-23T03:07:12.712-0500] {logging_mixin.py:190} INFO - [2025-02-23T03:07:12.711-0500] {dagbag.py:387} ERROR - Failed to import: /home/rafaelrb/anaconda3/lib/python3.9/site-packages/airflow/example_dags/example_dataset_alias.py
Traceback (most recent call last):
  File "/home/rafaelrb/anaconda3/lib/python3.9/site-packages/airflow/models/dagbag.py", line 383, in parse
    loader.exec_module(new_module)
  File "<frozen importlib._bootstrap_external>", line 850, in exec_module
  File "<frozen importlib._bootstrap>", line 228, in _call_with_frames_removed
  File "/home/rafaelrb/anaconda3/lib/python3.9/site-packages/airflow/example_dags/example_dataset_alias.py", line 53, in <module>
    def produce_dataset_events():
  File "/home/rafaelrb/anaconda3/lib/python3.9/site-packages/airflow/decorators/base.py", line 691, in decorator_factory
    return _TaskDecorator(
TypeError: _TaskDecorator() takes no arguments
[2025-02-23T03:07:12.713-0500] {processor.py:927} WARNING - No viable dags retrieved from /home/rafaelrb/anaconda3/lib/python3.9/site-packages/airflow/example_dags/example_dataset_alias.py
[2025-02-23T03:07:12.751-0500] {processor.py:208} INFO - Processing /home/rafaelrb/anaconda3/lib/python3.9/site-packages/airflow/example_dags/example_dataset_alias.py took 0.073 seconds
[2025-02-23T03:08:14.842-0500] {processor.py:186} INFO - Started process (PID=84436) to work on /home/rafaelrb/anaconda3/lib/python3.9/site-packages/airflow/example_dags/example_dataset_alias.py
[2025-02-23T03:08:14.844-0500] {processor.py:914} INFO - Processing file /home/rafaelrb/anaconda3/lib/python3.9/site-packages/airflow/example_dags/example_dataset_alias.py for tasks to queue
[2025-02-23T03:08:14.847-0500] {logging_mixin.py:190} INFO - [2025-02-23T03:08:14.846-0500] {dagbag.py:588} INFO - Filling up the DagBag from /home/rafaelrb/anaconda3/lib/python3.9/site-packages/airflow/example_dags/example_dataset_alias.py
[2025-02-23T03:08:14.856-0500] {logging_mixin.py:190} INFO - [2025-02-23T03:08:14.854-0500] {dagbag.py:387} ERROR - Failed to import: /home/rafaelrb/anaconda3/lib/python3.9/site-packages/airflow/example_dags/example_dataset_alias.py
Traceback (most recent call last):
  File "/home/rafaelrb/anaconda3/lib/python3.9/site-packages/airflow/models/dagbag.py", line 383, in parse
    loader.exec_module(new_module)
  File "<frozen importlib._bootstrap_external>", line 850, in exec_module
  File "<frozen importlib._bootstrap>", line 228, in _call_with_frames_removed
  File "/home/rafaelrb/anaconda3/lib/python3.9/site-packages/airflow/example_dags/example_dataset_alias.py", line 53, in <module>
    def produce_dataset_events():
  File "/home/rafaelrb/anaconda3/lib/python3.9/site-packages/airflow/decorators/base.py", line 691, in decorator_factory
    return _TaskDecorator(
TypeError: _TaskDecorator() takes no arguments
[2025-02-23T03:08:14.856-0500] {processor.py:927} WARNING - No viable dags retrieved from /home/rafaelrb/anaconda3/lib/python3.9/site-packages/airflow/example_dags/example_dataset_alias.py
[2025-02-23T03:08:14.901-0500] {processor.py:208} INFO - Processing /home/rafaelrb/anaconda3/lib/python3.9/site-packages/airflow/example_dags/example_dataset_alias.py took 0.070 seconds
[2025-02-23T03:09:18.350-0500] {processor.py:186} INFO - Started process (PID=84663) to work on /home/rafaelrb/anaconda3/lib/python3.9/site-packages/airflow/example_dags/example_dataset_alias.py
[2025-02-23T03:09:18.352-0500] {processor.py:914} INFO - Processing file /home/rafaelrb/anaconda3/lib/python3.9/site-packages/airflow/example_dags/example_dataset_alias.py for tasks to queue
[2025-02-23T03:09:18.354-0500] {logging_mixin.py:190} INFO - [2025-02-23T03:09:18.354-0500] {dagbag.py:588} INFO - Filling up the DagBag from /home/rafaelrb/anaconda3/lib/python3.9/site-packages/airflow/example_dags/example_dataset_alias.py
[2025-02-23T03:09:18.362-0500] {logging_mixin.py:190} INFO - [2025-02-23T03:09:18.361-0500] {dagbag.py:387} ERROR - Failed to import: /home/rafaelrb/anaconda3/lib/python3.9/site-packages/airflow/example_dags/example_dataset_alias.py
Traceback (most recent call last):
  File "/home/rafaelrb/anaconda3/lib/python3.9/site-packages/airflow/models/dagbag.py", line 383, in parse
    loader.exec_module(new_module)
  File "<frozen importlib._bootstrap_external>", line 850, in exec_module
  File "<frozen importlib._bootstrap>", line 228, in _call_with_frames_removed
  File "/home/rafaelrb/anaconda3/lib/python3.9/site-packages/airflow/example_dags/example_dataset_alias.py", line 53, in <module>
    def produce_dataset_events():
  File "/home/rafaelrb/anaconda3/lib/python3.9/site-packages/airflow/decorators/base.py", line 691, in decorator_factory
    return _TaskDecorator(
TypeError: _TaskDecorator() takes no arguments
[2025-02-23T03:09:18.363-0500] {processor.py:927} WARNING - No viable dags retrieved from /home/rafaelrb/anaconda3/lib/python3.9/site-packages/airflow/example_dags/example_dataset_alias.py
[2025-02-23T03:09:18.406-0500] {processor.py:208} INFO - Processing /home/rafaelrb/anaconda3/lib/python3.9/site-packages/airflow/example_dags/example_dataset_alias.py took 0.065 seconds
[2025-02-23T03:10:26.672-0500] {processor.py:186} INFO - Started process (PID=84866) to work on /home/rafaelrb/anaconda3/lib/python3.9/site-packages/airflow/example_dags/example_dataset_alias.py
[2025-02-23T03:10:26.679-0500] {processor.py:914} INFO - Processing file /home/rafaelrb/anaconda3/lib/python3.9/site-packages/airflow/example_dags/example_dataset_alias.py for tasks to queue
[2025-02-23T03:10:26.682-0500] {logging_mixin.py:190} INFO - [2025-02-23T03:10:26.682-0500] {dagbag.py:588} INFO - Filling up the DagBag from /home/rafaelrb/anaconda3/lib/python3.9/site-packages/airflow/example_dags/example_dataset_alias.py
[2025-02-23T03:10:26.690-0500] {logging_mixin.py:190} INFO - [2025-02-23T03:10:26.689-0500] {dagbag.py:387} ERROR - Failed to import: /home/rafaelrb/anaconda3/lib/python3.9/site-packages/airflow/example_dags/example_dataset_alias.py
Traceback (most recent call last):
  File "/home/rafaelrb/anaconda3/lib/python3.9/site-packages/airflow/models/dagbag.py", line 383, in parse
    loader.exec_module(new_module)
  File "<frozen importlib._bootstrap_external>", line 850, in exec_module
  File "<frozen importlib._bootstrap>", line 228, in _call_with_frames_removed
  File "/home/rafaelrb/anaconda3/lib/python3.9/site-packages/airflow/example_dags/example_dataset_alias.py", line 53, in <module>
    def produce_dataset_events():
  File "/home/rafaelrb/anaconda3/lib/python3.9/site-packages/airflow/decorators/base.py", line 691, in decorator_factory
    return _TaskDecorator(
TypeError: _TaskDecorator() takes no arguments
[2025-02-23T03:10:26.690-0500] {processor.py:927} WARNING - No viable dags retrieved from /home/rafaelrb/anaconda3/lib/python3.9/site-packages/airflow/example_dags/example_dataset_alias.py
[2025-02-23T03:10:26.723-0500] {processor.py:208} INFO - Processing /home/rafaelrb/anaconda3/lib/python3.9/site-packages/airflow/example_dags/example_dataset_alias.py took 0.060 seconds
[2025-02-23T03:11:26.382-0500] {processor.py:186} INFO - Started process (PID=85083) to work on /home/rafaelrb/anaconda3/lib/python3.9/site-packages/airflow/example_dags/example_dataset_alias.py
[2025-02-23T03:11:26.385-0500] {processor.py:914} INFO - Processing file /home/rafaelrb/anaconda3/lib/python3.9/site-packages/airflow/example_dags/example_dataset_alias.py for tasks to queue
[2025-02-23T03:11:26.388-0500] {logging_mixin.py:190} INFO - [2025-02-23T03:11:26.388-0500] {dagbag.py:588} INFO - Filling up the DagBag from /home/rafaelrb/anaconda3/lib/python3.9/site-packages/airflow/example_dags/example_dataset_alias.py
[2025-02-23T03:11:26.399-0500] {logging_mixin.py:190} INFO - [2025-02-23T03:11:26.398-0500] {dagbag.py:387} ERROR - Failed to import: /home/rafaelrb/anaconda3/lib/python3.9/site-packages/airflow/example_dags/example_dataset_alias.py
Traceback (most recent call last):
  File "/home/rafaelrb/anaconda3/lib/python3.9/site-packages/airflow/models/dagbag.py", line 383, in parse
    loader.exec_module(new_module)
  File "<frozen importlib._bootstrap_external>", line 850, in exec_module
  File "<frozen importlib._bootstrap>", line 228, in _call_with_frames_removed
  File "/home/rafaelrb/anaconda3/lib/python3.9/site-packages/airflow/example_dags/example_dataset_alias.py", line 53, in <module>
    def produce_dataset_events():
  File "/home/rafaelrb/anaconda3/lib/python3.9/site-packages/airflow/decorators/base.py", line 691, in decorator_factory
    return _TaskDecorator(
TypeError: _TaskDecorator() takes no arguments
[2025-02-23T03:11:26.400-0500] {processor.py:927} WARNING - No viable dags retrieved from /home/rafaelrb/anaconda3/lib/python3.9/site-packages/airflow/example_dags/example_dataset_alias.py
[2025-02-23T03:11:26.445-0500] {processor.py:208} INFO - Processing /home/rafaelrb/anaconda3/lib/python3.9/site-packages/airflow/example_dags/example_dataset_alias.py took 0.074 seconds
[2025-02-23T03:12:32.791-0500] {processor.py:186} INFO - Started process (PID=85286) to work on /home/rafaelrb/anaconda3/lib/python3.9/site-packages/airflow/example_dags/example_dataset_alias.py
[2025-02-23T03:12:32.798-0500] {processor.py:914} INFO - Processing file /home/rafaelrb/anaconda3/lib/python3.9/site-packages/airflow/example_dags/example_dataset_alias.py for tasks to queue
[2025-02-23T03:12:32.801-0500] {logging_mixin.py:190} INFO - [2025-02-23T03:12:32.801-0500] {dagbag.py:588} INFO - Filling up the DagBag from /home/rafaelrb/anaconda3/lib/python3.9/site-packages/airflow/example_dags/example_dataset_alias.py
[2025-02-23T03:12:32.809-0500] {logging_mixin.py:190} INFO - [2025-02-23T03:12:32.808-0500] {dagbag.py:387} ERROR - Failed to import: /home/rafaelrb/anaconda3/lib/python3.9/site-packages/airflow/example_dags/example_dataset_alias.py
Traceback (most recent call last):
  File "/home/rafaelrb/anaconda3/lib/python3.9/site-packages/airflow/models/dagbag.py", line 383, in parse
    loader.exec_module(new_module)
  File "<frozen importlib._bootstrap_external>", line 850, in exec_module
  File "<frozen importlib._bootstrap>", line 228, in _call_with_frames_removed
  File "/home/rafaelrb/anaconda3/lib/python3.9/site-packages/airflow/example_dags/example_dataset_alias.py", line 53, in <module>
    def produce_dataset_events():
  File "/home/rafaelrb/anaconda3/lib/python3.9/site-packages/airflow/decorators/base.py", line 691, in decorator_factory
    return _TaskDecorator(
TypeError: _TaskDecorator() takes no arguments
[2025-02-23T03:12:32.810-0500] {processor.py:927} WARNING - No viable dags retrieved from /home/rafaelrb/anaconda3/lib/python3.9/site-packages/airflow/example_dags/example_dataset_alias.py
[2025-02-23T03:12:32.840-0500] {processor.py:208} INFO - Processing /home/rafaelrb/anaconda3/lib/python3.9/site-packages/airflow/example_dags/example_dataset_alias.py took 0.057 seconds
[2025-02-23T03:13:36.278-0500] {processor.py:186} INFO - Started process (PID=85477) to work on /home/rafaelrb/anaconda3/lib/python3.9/site-packages/airflow/example_dags/example_dataset_alias.py
[2025-02-23T03:13:36.280-0500] {processor.py:914} INFO - Processing file /home/rafaelrb/anaconda3/lib/python3.9/site-packages/airflow/example_dags/example_dataset_alias.py for tasks to queue
[2025-02-23T03:13:36.285-0500] {logging_mixin.py:190} INFO - [2025-02-23T03:13:36.284-0500] {dagbag.py:588} INFO - Filling up the DagBag from /home/rafaelrb/anaconda3/lib/python3.9/site-packages/airflow/example_dags/example_dataset_alias.py
[2025-02-23T03:13:36.297-0500] {logging_mixin.py:190} INFO - [2025-02-23T03:13:36.296-0500] {dagbag.py:387} ERROR - Failed to import: /home/rafaelrb/anaconda3/lib/python3.9/site-packages/airflow/example_dags/example_dataset_alias.py
Traceback (most recent call last):
  File "/home/rafaelrb/anaconda3/lib/python3.9/site-packages/airflow/models/dagbag.py", line 383, in parse
    loader.exec_module(new_module)
  File "<frozen importlib._bootstrap_external>", line 850, in exec_module
  File "<frozen importlib._bootstrap>", line 228, in _call_with_frames_removed
  File "/home/rafaelrb/anaconda3/lib/python3.9/site-packages/airflow/example_dags/example_dataset_alias.py", line 53, in <module>
    def produce_dataset_events():
  File "/home/rafaelrb/anaconda3/lib/python3.9/site-packages/airflow/decorators/base.py", line 691, in decorator_factory
    return _TaskDecorator(
TypeError: _TaskDecorator() takes no arguments
[2025-02-23T03:13:36.298-0500] {processor.py:927} WARNING - No viable dags retrieved from /home/rafaelrb/anaconda3/lib/python3.9/site-packages/airflow/example_dags/example_dataset_alias.py
[2025-02-23T03:13:36.337-0500] {processor.py:208} INFO - Processing /home/rafaelrb/anaconda3/lib/python3.9/site-packages/airflow/example_dags/example_dataset_alias.py took 0.073 seconds
[2025-02-23T03:14:43.785-0500] {processor.py:186} INFO - Started process (PID=85743) to work on /home/rafaelrb/anaconda3/lib/python3.9/site-packages/airflow/example_dags/example_dataset_alias.py
[2025-02-23T03:14:43.787-0500] {processor.py:914} INFO - Processing file /home/rafaelrb/anaconda3/lib/python3.9/site-packages/airflow/example_dags/example_dataset_alias.py for tasks to queue
[2025-02-23T03:14:43.790-0500] {logging_mixin.py:190} INFO - [2025-02-23T03:14:43.789-0500] {dagbag.py:588} INFO - Filling up the DagBag from /home/rafaelrb/anaconda3/lib/python3.9/site-packages/airflow/example_dags/example_dataset_alias.py
[2025-02-23T03:14:43.797-0500] {logging_mixin.py:190} INFO - [2025-02-23T03:14:43.796-0500] {dagbag.py:387} ERROR - Failed to import: /home/rafaelrb/anaconda3/lib/python3.9/site-packages/airflow/example_dags/example_dataset_alias.py
Traceback (most recent call last):
  File "/home/rafaelrb/anaconda3/lib/python3.9/site-packages/airflow/models/dagbag.py", line 383, in parse
    loader.exec_module(new_module)
  File "<frozen importlib._bootstrap_external>", line 850, in exec_module
  File "<frozen importlib._bootstrap>", line 228, in _call_with_frames_removed
  File "/home/rafaelrb/anaconda3/lib/python3.9/site-packages/airflow/example_dags/example_dataset_alias.py", line 53, in <module>
    def produce_dataset_events():
  File "/home/rafaelrb/anaconda3/lib/python3.9/site-packages/airflow/decorators/base.py", line 691, in decorator_factory
    return _TaskDecorator(
TypeError: _TaskDecorator() takes no arguments
[2025-02-23T03:14:43.797-0500] {processor.py:927} WARNING - No viable dags retrieved from /home/rafaelrb/anaconda3/lib/python3.9/site-packages/airflow/example_dags/example_dataset_alias.py
[2025-02-23T03:14:43.829-0500] {processor.py:208} INFO - Processing /home/rafaelrb/anaconda3/lib/python3.9/site-packages/airflow/example_dags/example_dataset_alias.py took 0.052 seconds
[2025-02-23T03:15:51.349-0500] {processor.py:186} INFO - Started process (PID=85946) to work on /home/rafaelrb/anaconda3/lib/python3.9/site-packages/airflow/example_dags/example_dataset_alias.py
[2025-02-23T03:15:51.357-0500] {processor.py:914} INFO - Processing file /home/rafaelrb/anaconda3/lib/python3.9/site-packages/airflow/example_dags/example_dataset_alias.py for tasks to queue
[2025-02-23T03:15:51.359-0500] {logging_mixin.py:190} INFO - [2025-02-23T03:15:51.359-0500] {dagbag.py:588} INFO - Filling up the DagBag from /home/rafaelrb/anaconda3/lib/python3.9/site-packages/airflow/example_dags/example_dataset_alias.py
[2025-02-23T03:15:51.367-0500] {logging_mixin.py:190} INFO - [2025-02-23T03:15:51.366-0500] {dagbag.py:387} ERROR - Failed to import: /home/rafaelrb/anaconda3/lib/python3.9/site-packages/airflow/example_dags/example_dataset_alias.py
Traceback (most recent call last):
  File "/home/rafaelrb/anaconda3/lib/python3.9/site-packages/airflow/models/dagbag.py", line 383, in parse
    loader.exec_module(new_module)
  File "<frozen importlib._bootstrap_external>", line 850, in exec_module
  File "<frozen importlib._bootstrap>", line 228, in _call_with_frames_removed
  File "/home/rafaelrb/anaconda3/lib/python3.9/site-packages/airflow/example_dags/example_dataset_alias.py", line 53, in <module>
    def produce_dataset_events():
  File "/home/rafaelrb/anaconda3/lib/python3.9/site-packages/airflow/decorators/base.py", line 691, in decorator_factory
    return _TaskDecorator(
TypeError: _TaskDecorator() takes no arguments
[2025-02-23T03:15:51.367-0500] {processor.py:927} WARNING - No viable dags retrieved from /home/rafaelrb/anaconda3/lib/python3.9/site-packages/airflow/example_dags/example_dataset_alias.py
[2025-02-23T03:15:51.398-0500] {processor.py:208} INFO - Processing /home/rafaelrb/anaconda3/lib/python3.9/site-packages/airflow/example_dags/example_dataset_alias.py took 0.057 seconds
[2025-02-23T03:16:49.814-0500] {processor.py:186} INFO - Started process (PID=86168) to work on /home/rafaelrb/anaconda3/lib/python3.9/site-packages/airflow/example_dags/example_dataset_alias.py
[2025-02-23T03:16:49.834-0500] {processor.py:914} INFO - Processing file /home/rafaelrb/anaconda3/lib/python3.9/site-packages/airflow/example_dags/example_dataset_alias.py for tasks to queue
[2025-02-23T03:16:49.837-0500] {logging_mixin.py:190} INFO - [2025-02-23T03:16:49.837-0500] {dagbag.py:588} INFO - Filling up the DagBag from /home/rafaelrb/anaconda3/lib/python3.9/site-packages/airflow/example_dags/example_dataset_alias.py
[2025-02-23T03:16:49.845-0500] {logging_mixin.py:190} INFO - [2025-02-23T03:16:49.844-0500] {dagbag.py:387} ERROR - Failed to import: /home/rafaelrb/anaconda3/lib/python3.9/site-packages/airflow/example_dags/example_dataset_alias.py
Traceback (most recent call last):
  File "/home/rafaelrb/anaconda3/lib/python3.9/site-packages/airflow/models/dagbag.py", line 383, in parse
    loader.exec_module(new_module)
  File "<frozen importlib._bootstrap_external>", line 850, in exec_module
  File "<frozen importlib._bootstrap>", line 228, in _call_with_frames_removed
  File "/home/rafaelrb/anaconda3/lib/python3.9/site-packages/airflow/example_dags/example_dataset_alias.py", line 53, in <module>
    def produce_dataset_events():
  File "/home/rafaelrb/anaconda3/lib/python3.9/site-packages/airflow/decorators/base.py", line 691, in decorator_factory
    return _TaskDecorator(
TypeError: _TaskDecorator() takes no arguments
[2025-02-23T03:16:49.846-0500] {processor.py:927} WARNING - No viable dags retrieved from /home/rafaelrb/anaconda3/lib/python3.9/site-packages/airflow/example_dags/example_dataset_alias.py
[2025-02-23T03:16:49.871-0500] {processor.py:208} INFO - Processing /home/rafaelrb/anaconda3/lib/python3.9/site-packages/airflow/example_dags/example_dataset_alias.py took 0.076 seconds
[2025-02-23T03:17:52.215-0500] {processor.py:186} INFO - Started process (PID=86365) to work on /home/rafaelrb/anaconda3/lib/python3.9/site-packages/airflow/example_dags/example_dataset_alias.py
[2025-02-23T03:17:52.217-0500] {processor.py:914} INFO - Processing file /home/rafaelrb/anaconda3/lib/python3.9/site-packages/airflow/example_dags/example_dataset_alias.py for tasks to queue
[2025-02-23T03:17:52.220-0500] {logging_mixin.py:190} INFO - [2025-02-23T03:17:52.219-0500] {dagbag.py:588} INFO - Filling up the DagBag from /home/rafaelrb/anaconda3/lib/python3.9/site-packages/airflow/example_dags/example_dataset_alias.py
[2025-02-23T03:17:52.227-0500] {logging_mixin.py:190} INFO - [2025-02-23T03:17:52.226-0500] {dagbag.py:387} ERROR - Failed to import: /home/rafaelrb/anaconda3/lib/python3.9/site-packages/airflow/example_dags/example_dataset_alias.py
Traceback (most recent call last):
  File "/home/rafaelrb/anaconda3/lib/python3.9/site-packages/airflow/models/dagbag.py", line 383, in parse
    loader.exec_module(new_module)
  File "<frozen importlib._bootstrap_external>", line 850, in exec_module
  File "<frozen importlib._bootstrap>", line 228, in _call_with_frames_removed
  File "/home/rafaelrb/anaconda3/lib/python3.9/site-packages/airflow/example_dags/example_dataset_alias.py", line 53, in <module>
    def produce_dataset_events():
  File "/home/rafaelrb/anaconda3/lib/python3.9/site-packages/airflow/decorators/base.py", line 691, in decorator_factory
    return _TaskDecorator(
TypeError: _TaskDecorator() takes no arguments
[2025-02-23T03:17:52.228-0500] {processor.py:927} WARNING - No viable dags retrieved from /home/rafaelrb/anaconda3/lib/python3.9/site-packages/airflow/example_dags/example_dataset_alias.py
[2025-02-23T03:17:52.260-0500] {processor.py:208} INFO - Processing /home/rafaelrb/anaconda3/lib/python3.9/site-packages/airflow/example_dags/example_dataset_alias.py took 0.053 seconds
[2025-02-23T03:18:54.451-0500] {processor.py:186} INFO - Started process (PID=86686) to work on /home/rafaelrb/anaconda3/lib/python3.9/site-packages/airflow/example_dags/example_dataset_alias.py
[2025-02-23T03:18:54.454-0500] {processor.py:914} INFO - Processing file /home/rafaelrb/anaconda3/lib/python3.9/site-packages/airflow/example_dags/example_dataset_alias.py for tasks to queue
[2025-02-23T03:18:54.457-0500] {logging_mixin.py:190} INFO - [2025-02-23T03:18:54.457-0500] {dagbag.py:588} INFO - Filling up the DagBag from /home/rafaelrb/anaconda3/lib/python3.9/site-packages/airflow/example_dags/example_dataset_alias.py
[2025-02-23T03:18:54.466-0500] {logging_mixin.py:190} INFO - [2025-02-23T03:18:54.464-0500] {dagbag.py:387} ERROR - Failed to import: /home/rafaelrb/anaconda3/lib/python3.9/site-packages/airflow/example_dags/example_dataset_alias.py
Traceback (most recent call last):
  File "/home/rafaelrb/anaconda3/lib/python3.9/site-packages/airflow/models/dagbag.py", line 383, in parse
    loader.exec_module(new_module)
  File "<frozen importlib._bootstrap_external>", line 850, in exec_module
  File "<frozen importlib._bootstrap>", line 228, in _call_with_frames_removed
  File "/home/rafaelrb/anaconda3/lib/python3.9/site-packages/airflow/example_dags/example_dataset_alias.py", line 53, in <module>
    def produce_dataset_events():
  File "/home/rafaelrb/anaconda3/lib/python3.9/site-packages/airflow/decorators/base.py", line 691, in decorator_factory
    return _TaskDecorator(
TypeError: _TaskDecorator() takes no arguments
[2025-02-23T03:18:54.467-0500] {processor.py:927} WARNING - No viable dags retrieved from /home/rafaelrb/anaconda3/lib/python3.9/site-packages/airflow/example_dags/example_dataset_alias.py
[2025-02-23T03:18:54.501-0500] {processor.py:208} INFO - Processing /home/rafaelrb/anaconda3/lib/python3.9/site-packages/airflow/example_dags/example_dataset_alias.py took 0.082 seconds
[2025-02-23T03:19:58.808-0500] {processor.py:186} INFO - Started process (PID=86881) to work on /home/rafaelrb/anaconda3/lib/python3.9/site-packages/airflow/example_dags/example_dataset_alias.py
[2025-02-23T03:19:58.814-0500] {processor.py:914} INFO - Processing file /home/rafaelrb/anaconda3/lib/python3.9/site-packages/airflow/example_dags/example_dataset_alias.py for tasks to queue
[2025-02-23T03:19:58.817-0500] {logging_mixin.py:190} INFO - [2025-02-23T03:19:58.817-0500] {dagbag.py:588} INFO - Filling up the DagBag from /home/rafaelrb/anaconda3/lib/python3.9/site-packages/airflow/example_dags/example_dataset_alias.py
[2025-02-23T03:19:58.824-0500] {logging_mixin.py:190} INFO - [2025-02-23T03:19:58.824-0500] {dagbag.py:387} ERROR - Failed to import: /home/rafaelrb/anaconda3/lib/python3.9/site-packages/airflow/example_dags/example_dataset_alias.py
Traceback (most recent call last):
  File "/home/rafaelrb/anaconda3/lib/python3.9/site-packages/airflow/models/dagbag.py", line 383, in parse
    loader.exec_module(new_module)
  File "<frozen importlib._bootstrap_external>", line 850, in exec_module
  File "<frozen importlib._bootstrap>", line 228, in _call_with_frames_removed
  File "/home/rafaelrb/anaconda3/lib/python3.9/site-packages/airflow/example_dags/example_dataset_alias.py", line 53, in <module>
    def produce_dataset_events():
  File "/home/rafaelrb/anaconda3/lib/python3.9/site-packages/airflow/decorators/base.py", line 691, in decorator_factory
    return _TaskDecorator(
TypeError: _TaskDecorator() takes no arguments
[2025-02-23T03:19:58.825-0500] {processor.py:927} WARNING - No viable dags retrieved from /home/rafaelrb/anaconda3/lib/python3.9/site-packages/airflow/example_dags/example_dataset_alias.py
[2025-02-23T03:19:58.868-0500] {processor.py:208} INFO - Processing /home/rafaelrb/anaconda3/lib/python3.9/site-packages/airflow/example_dags/example_dataset_alias.py took 0.069 seconds
[2025-02-23T03:21:01.305-0500] {processor.py:186} INFO - Started process (PID=87082) to work on /home/rafaelrb/anaconda3/lib/python3.9/site-packages/airflow/example_dags/example_dataset_alias.py
[2025-02-23T03:21:01.307-0500] {processor.py:914} INFO - Processing file /home/rafaelrb/anaconda3/lib/python3.9/site-packages/airflow/example_dags/example_dataset_alias.py for tasks to queue
[2025-02-23T03:21:01.310-0500] {logging_mixin.py:190} INFO - [2025-02-23T03:21:01.310-0500] {dagbag.py:588} INFO - Filling up the DagBag from /home/rafaelrb/anaconda3/lib/python3.9/site-packages/airflow/example_dags/example_dataset_alias.py
[2025-02-23T03:21:01.319-0500] {logging_mixin.py:190} INFO - [2025-02-23T03:21:01.318-0500] {dagbag.py:387} ERROR - Failed to import: /home/rafaelrb/anaconda3/lib/python3.9/site-packages/airflow/example_dags/example_dataset_alias.py
Traceback (most recent call last):
  File "/home/rafaelrb/anaconda3/lib/python3.9/site-packages/airflow/models/dagbag.py", line 383, in parse
    loader.exec_module(new_module)
  File "<frozen importlib._bootstrap_external>", line 850, in exec_module
  File "<frozen importlib._bootstrap>", line 228, in _call_with_frames_removed
  File "/home/rafaelrb/anaconda3/lib/python3.9/site-packages/airflow/example_dags/example_dataset_alias.py", line 53, in <module>
    def produce_dataset_events():
  File "/home/rafaelrb/anaconda3/lib/python3.9/site-packages/airflow/decorators/base.py", line 691, in decorator_factory
    return _TaskDecorator(
TypeError: _TaskDecorator() takes no arguments
[2025-02-23T03:21:01.320-0500] {processor.py:927} WARNING - No viable dags retrieved from /home/rafaelrb/anaconda3/lib/python3.9/site-packages/airflow/example_dags/example_dataset_alias.py
[2025-02-23T03:21:01.352-0500] {processor.py:208} INFO - Processing /home/rafaelrb/anaconda3/lib/python3.9/site-packages/airflow/example_dags/example_dataset_alias.py took 0.060 seconds
[2025-02-23T03:21:58.893-0500] {processor.py:186} INFO - Started process (PID=87299) to work on /home/rafaelrb/anaconda3/lib/python3.9/site-packages/airflow/example_dags/example_dataset_alias.py
[2025-02-23T03:21:58.895-0500] {processor.py:914} INFO - Processing file /home/rafaelrb/anaconda3/lib/python3.9/site-packages/airflow/example_dags/example_dataset_alias.py for tasks to queue
[2025-02-23T03:21:58.900-0500] {logging_mixin.py:190} INFO - [2025-02-23T03:21:58.899-0500] {dagbag.py:588} INFO - Filling up the DagBag from /home/rafaelrb/anaconda3/lib/python3.9/site-packages/airflow/example_dags/example_dataset_alias.py
[2025-02-23T03:21:58.911-0500] {logging_mixin.py:190} INFO - [2025-02-23T03:21:58.909-0500] {dagbag.py:387} ERROR - Failed to import: /home/rafaelrb/anaconda3/lib/python3.9/site-packages/airflow/example_dags/example_dataset_alias.py
Traceback (most recent call last):
  File "/home/rafaelrb/anaconda3/lib/python3.9/site-packages/airflow/models/dagbag.py", line 383, in parse
    loader.exec_module(new_module)
  File "<frozen importlib._bootstrap_external>", line 850, in exec_module
  File "<frozen importlib._bootstrap>", line 228, in _call_with_frames_removed
  File "/home/rafaelrb/anaconda3/lib/python3.9/site-packages/airflow/example_dags/example_dataset_alias.py", line 53, in <module>
    def produce_dataset_events():
  File "/home/rafaelrb/anaconda3/lib/python3.9/site-packages/airflow/decorators/base.py", line 691, in decorator_factory
    return _TaskDecorator(
TypeError: _TaskDecorator() takes no arguments
[2025-02-23T03:21:58.911-0500] {processor.py:927} WARNING - No viable dags retrieved from /home/rafaelrb/anaconda3/lib/python3.9/site-packages/airflow/example_dags/example_dataset_alias.py
[2025-02-23T03:21:58.941-0500] {processor.py:208} INFO - Processing /home/rafaelrb/anaconda3/lib/python3.9/site-packages/airflow/example_dags/example_dataset_alias.py took 0.058 seconds
[2025-02-23T03:23:04.049-0500] {processor.py:186} INFO - Started process (PID=87526) to work on /home/rafaelrb/anaconda3/lib/python3.9/site-packages/airflow/example_dags/example_dataset_alias.py
[2025-02-23T03:23:04.051-0500] {processor.py:914} INFO - Processing file /home/rafaelrb/anaconda3/lib/python3.9/site-packages/airflow/example_dags/example_dataset_alias.py for tasks to queue
[2025-02-23T03:23:04.055-0500] {logging_mixin.py:190} INFO - [2025-02-23T03:23:04.054-0500] {dagbag.py:588} INFO - Filling up the DagBag from /home/rafaelrb/anaconda3/lib/python3.9/site-packages/airflow/example_dags/example_dataset_alias.py
[2025-02-23T03:23:04.064-0500] {logging_mixin.py:190} INFO - [2025-02-23T03:23:04.063-0500] {dagbag.py:387} ERROR - Failed to import: /home/rafaelrb/anaconda3/lib/python3.9/site-packages/airflow/example_dags/example_dataset_alias.py
Traceback (most recent call last):
  File "/home/rafaelrb/anaconda3/lib/python3.9/site-packages/airflow/models/dagbag.py", line 383, in parse
    loader.exec_module(new_module)
  File "<frozen importlib._bootstrap_external>", line 850, in exec_module
  File "<frozen importlib._bootstrap>", line 228, in _call_with_frames_removed
  File "/home/rafaelrb/anaconda3/lib/python3.9/site-packages/airflow/example_dags/example_dataset_alias.py", line 53, in <module>
    def produce_dataset_events():
  File "/home/rafaelrb/anaconda3/lib/python3.9/site-packages/airflow/decorators/base.py", line 691, in decorator_factory
    return _TaskDecorator(
TypeError: _TaskDecorator() takes no arguments
[2025-02-23T03:23:04.065-0500] {processor.py:927} WARNING - No viable dags retrieved from /home/rafaelrb/anaconda3/lib/python3.9/site-packages/airflow/example_dags/example_dataset_alias.py
[2025-02-23T03:23:04.096-0500] {processor.py:208} INFO - Processing /home/rafaelrb/anaconda3/lib/python3.9/site-packages/airflow/example_dags/example_dataset_alias.py took 0.059 seconds
[2025-02-23T03:24:06.270-0500] {processor.py:186} INFO - Started process (PID=87720) to work on /home/rafaelrb/anaconda3/lib/python3.9/site-packages/airflow/example_dags/example_dataset_alias.py
[2025-02-23T03:24:06.272-0500] {processor.py:914} INFO - Processing file /home/rafaelrb/anaconda3/lib/python3.9/site-packages/airflow/example_dags/example_dataset_alias.py for tasks to queue
[2025-02-23T03:24:06.276-0500] {logging_mixin.py:190} INFO - [2025-02-23T03:24:06.275-0500] {dagbag.py:588} INFO - Filling up the DagBag from /home/rafaelrb/anaconda3/lib/python3.9/site-packages/airflow/example_dags/example_dataset_alias.py
[2025-02-23T03:24:06.292-0500] {logging_mixin.py:190} INFO - [2025-02-23T03:24:06.287-0500] {dagbag.py:387} ERROR - Failed to import: /home/rafaelrb/anaconda3/lib/python3.9/site-packages/airflow/example_dags/example_dataset_alias.py
Traceback (most recent call last):
  File "/home/rafaelrb/anaconda3/lib/python3.9/site-packages/airflow/models/dagbag.py", line 383, in parse
    loader.exec_module(new_module)
  File "<frozen importlib._bootstrap_external>", line 850, in exec_module
  File "<frozen importlib._bootstrap>", line 228, in _call_with_frames_removed
  File "/home/rafaelrb/anaconda3/lib/python3.9/site-packages/airflow/example_dags/example_dataset_alias.py", line 53, in <module>
    def produce_dataset_events():
  File "/home/rafaelrb/anaconda3/lib/python3.9/site-packages/airflow/decorators/base.py", line 691, in decorator_factory
    return _TaskDecorator(
TypeError: _TaskDecorator() takes no arguments
[2025-02-23T03:24:06.292-0500] {processor.py:927} WARNING - No viable dags retrieved from /home/rafaelrb/anaconda3/lib/python3.9/site-packages/airflow/example_dags/example_dataset_alias.py
[2025-02-23T03:24:06.372-0500] {processor.py:208} INFO - Processing /home/rafaelrb/anaconda3/lib/python3.9/site-packages/airflow/example_dags/example_dataset_alias.py took 0.118 seconds
[2025-02-23T03:25:13.663-0500] {processor.py:186} INFO - Started process (PID=87932) to work on /home/rafaelrb/anaconda3/lib/python3.9/site-packages/airflow/example_dags/example_dataset_alias.py
[2025-02-23T03:25:13.670-0500] {processor.py:914} INFO - Processing file /home/rafaelrb/anaconda3/lib/python3.9/site-packages/airflow/example_dags/example_dataset_alias.py for tasks to queue
[2025-02-23T03:25:13.673-0500] {logging_mixin.py:190} INFO - [2025-02-23T03:25:13.673-0500] {dagbag.py:588} INFO - Filling up the DagBag from /home/rafaelrb/anaconda3/lib/python3.9/site-packages/airflow/example_dags/example_dataset_alias.py
[2025-02-23T03:25:13.680-0500] {logging_mixin.py:190} INFO - [2025-02-23T03:25:13.679-0500] {dagbag.py:387} ERROR - Failed to import: /home/rafaelrb/anaconda3/lib/python3.9/site-packages/airflow/example_dags/example_dataset_alias.py
Traceback (most recent call last):
  File "/home/rafaelrb/anaconda3/lib/python3.9/site-packages/airflow/models/dagbag.py", line 383, in parse
    loader.exec_module(new_module)
  File "<frozen importlib._bootstrap_external>", line 850, in exec_module
  File "<frozen importlib._bootstrap>", line 228, in _call_with_frames_removed
  File "/home/rafaelrb/anaconda3/lib/python3.9/site-packages/airflow/example_dags/example_dataset_alias.py", line 53, in <module>
    def produce_dataset_events():
  File "/home/rafaelrb/anaconda3/lib/python3.9/site-packages/airflow/decorators/base.py", line 691, in decorator_factory
    return _TaskDecorator(
TypeError: _TaskDecorator() takes no arguments
[2025-02-23T03:25:13.680-0500] {processor.py:927} WARNING - No viable dags retrieved from /home/rafaelrb/anaconda3/lib/python3.9/site-packages/airflow/example_dags/example_dataset_alias.py
[2025-02-23T03:25:13.711-0500] {processor.py:208} INFO - Processing /home/rafaelrb/anaconda3/lib/python3.9/site-packages/airflow/example_dags/example_dataset_alias.py took 0.056 seconds
[2025-02-23T03:26:14.763-0500] {processor.py:186} INFO - Started process (PID=88139) to work on /home/rafaelrb/anaconda3/lib/python3.9/site-packages/airflow/example_dags/example_dataset_alias.py
[2025-02-23T03:26:14.771-0500] {processor.py:914} INFO - Processing file /home/rafaelrb/anaconda3/lib/python3.9/site-packages/airflow/example_dags/example_dataset_alias.py for tasks to queue
[2025-02-23T03:26:14.773-0500] {logging_mixin.py:190} INFO - [2025-02-23T03:26:14.773-0500] {dagbag.py:588} INFO - Filling up the DagBag from /home/rafaelrb/anaconda3/lib/python3.9/site-packages/airflow/example_dags/example_dataset_alias.py
[2025-02-23T03:26:14.794-0500] {logging_mixin.py:190} INFO - [2025-02-23T03:26:14.793-0500] {dagbag.py:387} ERROR - Failed to import: /home/rafaelrb/anaconda3/lib/python3.9/site-packages/airflow/example_dags/example_dataset_alias.py
Traceback (most recent call last):
  File "/home/rafaelrb/anaconda3/lib/python3.9/site-packages/airflow/models/dagbag.py", line 383, in parse
    loader.exec_module(new_module)
  File "<frozen importlib._bootstrap_external>", line 850, in exec_module
  File "<frozen importlib._bootstrap>", line 228, in _call_with_frames_removed
  File "/home/rafaelrb/anaconda3/lib/python3.9/site-packages/airflow/example_dags/example_dataset_alias.py", line 53, in <module>
    def produce_dataset_events():
  File "/home/rafaelrb/anaconda3/lib/python3.9/site-packages/airflow/decorators/base.py", line 691, in decorator_factory
    return _TaskDecorator(
TypeError: _TaskDecorator() takes no arguments
[2025-02-23T03:26:14.794-0500] {processor.py:927} WARNING - No viable dags retrieved from /home/rafaelrb/anaconda3/lib/python3.9/site-packages/airflow/example_dags/example_dataset_alias.py
[2025-02-23T03:26:14.825-0500] {processor.py:208} INFO - Processing /home/rafaelrb/anaconda3/lib/python3.9/site-packages/airflow/example_dags/example_dataset_alias.py took 0.070 seconds
